Workbook
Name _____I2: {"PVGraph2",#N/A,FALSE,"PV Data"}
Name _____I2: {"PVGraph2",#N/A,FALSE,"PV Data"}
Name _____I2: {"PVGraph2",#N/A,FALSE,"PV Data"}
Name _____I3: {"PVGraph2",#N/A,FALSE,"PV Data"}
Name _____I3: {"PVGraph2",#N/A,FALSE,"PV Data"}
Name _____I3: {"PVGraph2",#N/A,FALSE,"PV Data"}
Name _____w1: {"PVGraph2",#N/A,FALSE,"PV Data"}
Name _____w1: {"PVGraph2",#N/A,FALSE,"PV Data"}
Name _____w1: {"PVGraph2",#N/A,FALSE,"PV Data"}
Name _____w2: {"PVGraph2",#N/A,FALSE,"PV Data"}
Name _____w2: {"PVGraph2",#N/A,FALSE,"PV Data"}
Name _____w2: {"PVGraph2",#N/A,FALSE,"PV Data"}
Name _____w3: {"PVGraph2",#N/A,FALSE,"PV Data"}
Name _____w3: {"PVGraph2",#N/A,FALSE,"PV Data"}
Name _____w3: {"PVGraph2",#N/A,FALSE,"PV Data"}
Name _____y2: {"PVGraph2",#N/A,FALSE,"PV Data"}
Name _____y2: {"PVGraph2",#N/A,FALSE,"PV Data"}
Name _____y2: {"PVGraph2",#N/A,FALSE,"PV Data"}
Name ___I2: {"PVGraph2",#N/A,FALSE,"PV Data"}
Name ___I2: {"PVGraph2",#N/A,FALSE,"PV Data"}
Name ___I2: {"PVGraph2",#N/A,FALSE,"PV Data"}
Name ___I3: {"PVGraph2",#N/A,FALSE,"PV Data"}
Name ___I3: {"PVGraph2",#N/A,FALSE,"PV Data"}
Name ___I3: {"PVGraph2",#N/A,FALSE,"PV Data"}
Name ___s1: #REF!
Name ___s2: #REF!
Name ___s3: #REF!
Name ___s4: #REF!
Name ___s5: #REF!
Name ___s6: #REF!
Name ___w1: {"PVGraph2",#N/A,FALSE,"PV Data"}
Name ___w1: {"PVGraph2",#N/A,FALSE,"PV Data"}
Name ___w1: {"PVGraph2",#N/A,FALSE,"PV Data"}
Name ___w2: {"PVGraph2",#N/A,FALSE,"PV Data"}
Name ___w2: {"PVGraph2",#N/A,FALSE,"PV Data"}
Name ___w2: {"PVGraph2",#N/A,FALSE,"PV Data"}
Name ___w3: {"PVGraph2",#N/A,FALSE,"PV Data"}
Name ___w3: {"PVGraph2",#N/A,FALSE,"PV Data"}
Name ___w3: {"PVGraph2",#N/A,FALSE,"PV Data"}
Name ___y2: {"PVGraph2",#N/A,FALSE,"PV Data"}
Name ___y2: {"PVGraph2",#N/A,FALSE,"PV Data"}
Name ___y2: {"PVGraph2",#N/A,FALSE,"PV Data"}
Name __123Graph_A: #REF!
Name __123gRAPH_achart: #REF!
Name __123Graph_AChart1: #REF!
Name __123Graph_ACurrent: #REF!
Name __123Graph_AGRPH_EXPIRE: #REF!
Name __123Graph_AHMCISALES: #REF!
Name __123Graph_APRINCIPAL: #REF!
Name __123Graph_B: #REF!
Name __123Graph_BChart1: #REF!
Name __123Graph_BCurrent: #REF!
Name __123Graph_BFUEL: #REF!
Name __123Graph_BHMCISALES: #REF!
Name __123Graph_C: #REF!
Name __123Graph_CChart1: #REF!
Name __123Graph_CCurrent: #REF!
Name __123Graph_D: #REF!
Name __123Graph_DChart1: #REF!
Name __123Graph_DCurrent: #REF!

Sheet M&A Reporting Slide - Old
A1: Pro Forma Estimates | B1: Leads | C1: Events | D1: Total $ / Event | E1: Catering Attach. | F1: Beverage Attach. | G1: Non-Ancillary | H1: F&B | I1: Other Ancillary | J1: Total Revenue | K1: F&B | L1: Total COGS | M1: Staffing / Labor | N1: Other Opex | O1: EBITDA
A2: Firefly Lane | Q2: rev check | R2: EBITDA Check
A3: PF Y1 Estimate | B3: ='Adj. P&L'!$CD$11 -> 1506 | C3: ='Adj. P&L'!CD35+'Adj. P&L'!CD40 -> 190 | D3: =J3/C3 -> 10.333762 | E3: =('Revenue Analysis - Total'!G44+'Revenue Analysis - Total'!G30)/('Revenue Analysis - Total'!G43+'Revenue Analysis - Total'!G29) -> 0.3 | F3: =('Revenue Analysis - Total'!G31+'Revenue Analysis - Total'!G45)/('Revenue Analysis - Total'!G43+'Revenue Analysis - Total'!G29) -> 0 | G3: =SUM('Adj. P&L'!CD43:CD44,'Adj. P&L'!CD50:CD53) -> 1200.1098 | H3: ='Adj. P&L'!CD46+'Adj. P&L'!CD117 -> 241.85 | I3: =SUM('Adj. P&L'!CD47:CD49,'Adj. P&L'!CD118) -> 521.45487 | J3: =SUM(G3:I3) -> 1963.4147 | K3: =-('Adj. P&L'!CD58+'Adj. P&L'!CD60) -> 161.50825 | L3: =-('Adj. P&L'!CD65) -> 646.64875 | M3: =-'Adj. P&L'!CD80 -> 419.07763 | N3: =-'Adj. P&L'!CD99 -> 304.64108 | O3: =J3-SUM(L3:N3) -> 593.04724 | Q3: ='Adj. P&L'!CD55-J3 -> 0 | R3: ='Adj. P&L'!CD101-O3 -> 0
A4: PF Y2 Estimate | B4: ='Adj. P&L'!$CE$11 -> 1581 | C4: ='Adj. P&L'!CE35+'Adj. P&L'!CE40 -> 200 | D4: =J4/C4 -> 13.355365 | E4: =('Revenue Analysis - Total'!H44+'Revenue Analysis - Total'!H30)/('Revenue Analysis - Total'!H43+'Revenue Analysis - Total'!H29) -> 0.659375 | F4: =('Revenue Analysis - Total'!H31+'Revenue Analysis - Total'!H45)/('Revenue Analysis - Total'!H43+'Revenue Analysis - Total'!H29) -> 0.203125 | G4: =SUM('Adj. P&L'!CE43:CE44,'Adj. P&L'!CE50:CE53) -> 1335.1458 | H4: ='Adj. P&L'!CE46+'Adj. P&L'!CE117 -> 491.10833 | I4: =SUM('Adj. P&L'!CE47:CE49,'Adj. P&L'!CE118) -> 844.8189 | J4: =SUM(G4:I4) -> 2671.073 | K4: =-('Adj. P&L'!CE58+'Adj. P&L'!CE60) -> 389.58441 | L4: =-('Adj. P&L'!CE65) -> 1029.6084 | M4: =-'Adj. P&L'!CE80 -> 456.73697 | N4: =-'Adj. P&L'!CE99 -> 376.89088 | O4: =J4-SUM(L4:N4) -> 807.83677 | Q4: ='Adj. P&L'!CE55-J4 -> 0 | R4: ='Adj. P&L'!CE101-O4 -> 0
A5: PF Y3 Estimate | B5: ='Adj. P&L'!$CF$11 -> 1660 | C5: ='Adj. P&L'!CF35+'Adj. P&L'!CF40 -> 210 | D5: =J5/C5 -> 18.092088 | E5: =('Revenue Analysis - Total'!I44+'Revenue Analysis - Total'!I30)/('Revenue Analysis - Total'!I43+'Revenue Analysis - Total'!I29) -> 1 | F5: =('Revenue Analysis - Total'!I31+'Revenue Analysis - Total'!I45)/('Revenue Analysis - Total'!I43+'Revenue Analysis - Total'!I29) -> 1 | G5: =SUM('Adj. P&L'!CF43:CF44,'Adj. P&L'!CF50:CF53) -> 1399.0112 | H5: ='Adj. P&L'!CF46+'Adj. P&L'!CF117 -> 767.83333 | I5: =SUM('Adj. P&L'!CF47:CF49,'Adj. P&L'!CF118) -> 1632.4939 | J5: =SUM(G5:I5) -> 3799.3385 | K5: =-('Adj. P&L'!CF58+'Adj. P&L'!CF60) -> 667.3527 | L5: =-('Adj. P&L'!CF65) -> 1592.4943 | M5: =-'Adj. P&L'!CF80 -> 497.67151 | N5: =-'Adj. P&L'!CF99 -> 488.89979 | O5: =J5-SUM(L5:N5) -> 1220.2729 | Q5: ='Adj. P&L'!CF55-J5 -> 0 | R5: ='Adj. P&L'!CF101-O5 -> 0

Sheet M&A Reporting - New
D1: 46203 | E1: 46234 | F1: 46265 | G1: 46295 | H1: 46326 | I1: 46356 | J1: 46387 | K1: 46418 | L1: 46446 | M1: 46477 | N1: 46507 | O1: 46538 | Q1: Y1 | R1: Y2 | S1: Y3 | U1: 2026 | V1: 2027 | W1: 2028
C3: =Checks!$C$3 -> Firefly Lane
C4: PF P&L Analysis
D6: Year 1 Pro Forma | Q6: Annual | U6: Annual
D7: 46203 | E7: =EOMONTH(D7,1) -> 46234 | F7: =EOMONTH(E7,1) -> 46265 | G7: =EOMONTH(F7,1) -> 46295 | H7: =EOMONTH(G7,1) -> 46326 | I7: =EOMONTH(H7,1) -> 46356 | J7: =EOMONTH(I7,1) -> 46387 | K7: =EOMONTH(J7,1) -> 46418 | L7: =EOMONTH(K7,1) -> 46446 | ... O7: =EOMONTH(N7,1) -> 46538 | Q7: Y1 | R7: Y2 | S7: Y3 | U7: 2026 | V7: 2027 | W7: 2028
C9: Firefly Lane
A10: Contracts | C10: Contracts | D10: {=INDEX('Adj. P&L'!$D$11:$CX$119,MATCH($A10,'Adj. P&L'!$C$11:$C$119,0),MATCH(D$1,'Adj. P&L'!$D$9:$CX$9,0))} -> 15 | E10: {=INDEX('Adj. P&L'!$D$11:$CX$119,MATCH($A10,'Adj. P&L'!$C$11:$C$119,0),MATCH(E$1,'Adj. P&L'!$D$9:$CX$9,0))} -> 24 | F10: {=INDEX('Adj. P&L'!$D$11:$CX$119,MATCH($A10,'Adj. P&L'!$C$11:$C$119,0),MATCH(F$1,'Adj. P&L'!$D$9:$CX$9,0))} -> 21 | G10: {=INDEX('Adj. P&L'!$D$11:$CX$119,MATCH($A10,'Adj. P&L'!$C$11:$C$119,0),MATCH(G$1,'Adj. P&L'!$D$9:$CX$9,0))} -> 16 | H10: {=INDEX('Adj. P&L'!$D$11:$CX$119,MATCH($A10,'Adj. P&L'!$C$11:$C$119,0),MATCH(H$1,'Adj. P&L'!$D$9:$CX$9,0))} -> 12 | I10: {=INDEX('Adj. P&L'!$D$11:$CX$119,MATCH($A10,'Adj. P&L'!$C$11:$C$119,0),MATCH(I$1,'Adj. P&L'!$D$9:$CX$9,0))} -> 16 | J10: {=INDEX('Adj. P&L'!$D$11:$CX$119,MATCH($A10,'Adj. P&L'!$C$11:$C$119,0),MATCH(J$1,'Adj. P&L'!$D$9:$CX$9,0))} -> 11 | K10: {=INDEX('Adj. P&L'!$D$11:$CX$119,MATCH($A10,'Adj. P&L'!$C$11:$C$119,0),MATCH(K$1,'Adj. P&L'!$D$9:$CX$9,0))} -> 21 | ... O10: {=INDEX('Adj. P&L'!$D$11:$CX$119,MATCH($A10,'Adj. P&L'!$C$11:$C$119,0),MATCH(O$1,'Adj. P&L'!$D$9:$CX$9,0))} -> 13 | Q10: {=INDEX('Adj. P&L'!$D$11:$CX$119,MATCH($A10,'Adj. P&L'!$C$11:$C$119,0),MATCH(Q$1,'Adj. P&L'!$D$9:$CX$9,0))} -> 190 | R10: {=INDEX('Adj. P&L'!$D$11:$CX$119,MATCH($A10,'Adj. P&L'!$C$11:$C$119,0),MATCH(R$1,'Adj. P&L'!$D$9:$CX$9,0))} -> 200 | S10: {=INDEX('Adj. P&L'!$D$11:$CX$119,MATCH($A10,'Adj. P&L'!$C$11:$C$119,0),MATCH(S$1,'Adj. P&L'!$D$9:$CX$9,0))} -> 210 | U10: {=INDEX('Adj. P&L'!$D$11:$CX$119,MATCH($A10,'Adj. P&L'!$C$11:$C$119,0),MATCH(U$1,'Adj. P&L'!$D$9:$CX$9,0))} -> 163 | V10: {=INDEX('Adj. P&L'!$D$11:$CX$119,MATCH($A10,'Adj. P&L'!$C$11:$C$119,0),MATCH(V$1,'Adj. P&L'!$D$9:$CX$9,0))} -> 195 | W10: {=INDEX('Adj. P&L'!$D$11:$CX$119,MATCH($A10,'Adj. P&L'!$C$11:$C$119,0),MATCH(W$1,'Adj. P&L'!$D$9:$CX$9,0))} -> 206
A11: Events - B&C | C11: Events - B&C | D11: {=INDEX('Adj. P&L'!$D$11:$CX$119,MATCH($A11,'Adj. P&L'!$C$11:$C$119,0),MATCH(D$1,'Adj. P&L'!$D$9:$CX$9,0))} -> 12 | E11: {=INDEX('Adj. P&L'!$D$11:$CX$119,MATCH($A11,'Adj. P&L'!$C$11:$C$119,0),MATCH(E$1,'Adj. P&L'!$D$9:$CX$9,0))} -> 10 | F11: {=INDEX('Adj. P&L'!$D$11:$CX$119,MATCH($A11,'Adj. P&L'!$C$11:$C$119,0),MATCH(F$1,'Adj. P&L'!$D$9:$CX$9,0))} -> 15 | G11: {=INDEX('Adj. P&L'!$D$11:$CX$119,MATCH($A11,'Adj. P&L'!$C$11:$C$119,0),MATCH(G$1,'Adj. P&L'!$D$9:$CX$9,0))} -> 19 | H11: {=INDEX('Adj. P&L'!$D$11:$CX$119,MATCH($A11,'Adj. P&L'!$C$11:$C$119,0),MATCH(H$1,'Adj. P&L'!$D$9:$CX$9,0))} -> 24 | I11: {=INDEX('Adj. P&L'!$D$11:$CX$119,MATCH($A11,'Adj. P&L'!$C$11:$C$119,0),MATCH(I$1,'Adj. P&L'!$D$9:$CX$9,0))} -> 12 | J11: {=INDEX('Adj. P&L'!$D$11:$CX$119,MATCH($A11,'Adj. P&L'!$C$11:$C$119,0),MATCH(J$1,'Adj. P&L'!$D$9:$CX$9,0))} -> 5 | K11: {=INDEX('Adj. P&L'!$D$11:$CX$119,MATCH($A11,'Adj. P&L'!$C$11:$C$119,0),MATCH(K$1,'Adj. P&L'!$D$9:$CX$9,0))} -> 0 | ... O11: {=INDEX('Adj. P&L'!$D$11:$CX$119,MATCH($A11,'Adj. P&L'!$C$11:$C$119,0),MATCH(O$1,'Adj. P&L'!$D$9:$CX$9,0))} -> 27 | Q11: {=INDEX('Adj. P&L'!$D$11:$CX$119,MATCH($A11,'Adj. P&L'!$C$11:$C$119,0),MATCH(Q$1,'Adj. P&L'!$D$9:$CX$9,0))} -> 150 | R11: {=INDEX('Adj. P&L'!$D$11:$CX$119,MATCH($A11,'Adj. P&L'!$C$11:$C$119,0),MATCH(R$1,'Adj. P&L'!$D$9:$CX$9,0))} -> 160 | S11: {=INDEX('Adj. P&L'!$D$11:$CX$119,MATCH($A11,'Adj. P&L'!$C$11:$C$119,0),MATCH(S$1,'Adj. P&L'!$D$9:$CX$9,0))} -> 170 | U11: {=INDEX('Adj. P&L'!$D$11:$CX$119,MATCH($A11,'Adj. P&L'!$C$11:$C$119,0),MATCH(U$1,'Adj. P&L'!$D$9:$CX$9,0))} -> 140 | V11: {=INDEX('Adj. P&L'!$D$11:$CX$119,MATCH($A11,'Adj. P&L'!$C$11:$C$119,0),MATCH(V$1,'Adj. P&L'!$D$9:$CX$9,0))} -> 162 | W11: {=INDEX('Adj. P&L'!$D$11:$CX$119,MATCH($A11,'Adj. P&L'!$C$11:$C$119,0),MATCH(W$1,'Adj. P&L'!$D$9:$CX$9,0))} -> 166
A12: Elopements | C12: Elopements | D12: {=INDEX('Adj. P&L'!$D$11:$CX$119,MATCH($A12,'Adj. P&L'!$C$11:$C$119,0),MATCH(D$1,'Adj. P&L'!$D$9:$CX$9,0))} -> 4 | E12: {=INDEX('Adj. P&L'!$D$11:$CX$119,MATCH($A12,'Adj. P&L'!$C$11:$C$119,0),MATCH(E$1,'Adj. P&L'!$D$9:$CX$9,0))} -> 0 | F12: {=INDEX('Adj. P&L'!$D$11:$CX$119,MATCH($A12,'Adj. P&L'!$C$11:$C$119,0),MATCH(F$1,'Adj. P&L'!$D$9:$CX$9,0))} -> 2 | G12: {=INDEX('Adj. P&L'!$D$11:$CX$119,MATCH($A12,'Adj. P&L'!$C$11:$C$119,0),MATCH(G$1,'Adj. P&L'!$D$9:$CX$9,0))} -> 5 | H12: {=INDEX('Adj. P&L'!$D$11:$CX$119,MATCH($A12,'Adj. P&L'!$C$11:$C$119,0),MATCH(H$1,'Adj. P&L'!$D$9:$CX$9,0))} -> 6 | I12: {=INDEX('Adj. P&L'!$D$11:$CX$119,MATCH($A12,'Adj. P&L'!$C$11:$C$119,0),MATCH(I$1,'Adj. P&L'!$D$9:$CX$9,0))} -> 1 | J12: {=INDEX('Adj. P&L'!$D$11:$CX$119,MATCH($A12,'Adj. P&L'!$C$11:$C$119,0),MATCH(J$1,'Adj. P&L'!$D$9:$CX$9,0))} -> 0 | K12: {=INDEX('Adj. P&L'!$D$11:$CX$119,MATCH($A12,'Adj. P&L'!$C$11:$C$119,0),MATCH(K$1,'Adj. P&L'!$D$9:$CX$9,0))} -> 0 | ... O12: {=INDEX('Adj. P&L'!$D$11:$CX$119,MATCH($A12,'Adj. P&L'!$C$11:$C$119,0),MATCH(O$1,'Adj. P&L'!$D$9:$CX$9,0))} -> 12 | Q12: {=INDEX('Adj. P&L'!$D$11:$CX$119,MATCH($A12,'Adj. P&L'!$C$11:$C$119,0),MATCH(Q$1,'Adj. P&L'!$D$9:$CX$9,0))} -> 40 | R12: {=INDEX('Adj. P&L'!$D$11:$CX$119,MATCH($A12,'Adj. P&L'!$C$11:$C$119,0),MATCH(R$1,'Adj. P&L'!$D$9:$CX$9,0))} -> 40 | S12: {=INDEX('Adj. P&L'!$D$11:$CX$119,MATCH($A12,'Adj. P&L'!$C$11:$C$119,0),MATCH(S$1,'Adj. P&L'!$D$9:$CX$9,0))} -> 40 | U12: {=INDEX('Adj. P&L'!$D$11:$CX$119,MATCH($A12,'Adj. P&L'!$C$11:$C$119,0),MATCH(U$1,'Adj. P&L'!$D$9:$CX$9,0))} -> 27 | V12: {=INDEX('Adj. P&L'!$D$11:$CX$119,MATCH($A12,'Adj. P&L'!$C$11:$C$119,0),MATCH(V$1,'Adj. P&L'!$D$9:$CX$9,0))} -> 48 | W12: {=INDEX('Adj. P&L'!$D$11:$CX$119,MATCH($A12,'Adj. P&L'!$C$11:$C$119,0),MATCH(W$1,'Adj. P&L'!$D$9:$CX$9,0))} -> 40
C13: Events | D13: =SUM(D11:D12) -> 16 | E13: =SUM(E11:E12) -> 10 | F13: =SUM(F11:F12) -> 17 | G13: =SUM(G11:G12) -> 24 | H13: =SUM(H11:H12) -> 30 | I13: =SUM(I11:I12) -> 13 | J13: =SUM(J11:J12) -> 5 | K13: =SUM(K11:K12) -> 0 | ... O13: =SUM(O11:O12) -> 39 | Q13: =SUM(Q11:Q12) -> 190 | R13: =SUM(R11:R12) -> 200 | S13: =SUM(S11:S12) -> 210 | U13: =SUM(U11:U12) -> 167 | V13: =SUM(V11:V12) -> 210 | W13: =SUM(W11:W12) -> 206
A14: Total Revenue | C14: Revenue | D14: {=INDEX('Adj. P&L'!$D$11:$CX$119,MATCH($A14,'Adj. P&L'!$C$11:$C$119,0),MATCH(D$1,'Adj. P&L'!$D$9:$CX$9,0))} -> 170.66258 | E14: {=INDEX('Adj. P&L'!$D$11:$CX$119,MATCH($A14,'Adj. P&L'!$C$11:$C$119,0),MATCH(E$1,'Adj. P&L'!$D$9:$CX$9,0))} -> 115.06465 | F14: {=INDEX('Adj. P&L'!$D$11:$CX$119,MATCH($A14,'Adj. P&L'!$C$11:$C$119,0),MATCH(F$1,'Adj. P&L'!$D$9:$CX$9,0))} -> 238.78947 | G14: {=INDEX('Adj. P&L'!$D$11:$CX$119,MATCH($A14,'Adj. P&L'!$C$11:$C$119,0),MATCH(G$1,'Adj. P&L'!$D$9:$CX$9,0))} -> 256.80033 | H14: {=INDEX('Adj. P&L'!$D$11:$CX$119,MATCH($A14,'Adj. P&L'!$C$11:$C$119,0),MATCH(H$1,'Adj. P&L'!$D$9:$CX$9,0))} -> 298.71015 | I14: {=INDEX('Adj. P&L'!$D$11:$CX$119,MATCH($A14,'Adj. P&L'!$C$11:$C$119,0),MATCH(I$1,'Adj. P&L'!$D$9:$CX$9,0))} -> 154.89258 | J14: {=INDEX('Adj. P&L'!$D$11:$CX$119,MATCH($A14,'Adj. P&L'!$C$11:$C$119,0),MATCH(J$1,'Adj. P&L'!$D$9:$CX$9,0))} -> 54.519823 | K14: {=INDEX('Adj. P&L'!$D$11:$CX$119,MATCH($A14,'Adj. P&L'!$C$11:$C$119,0),MATCH(K$1,'Adj. P&L'!$D$9:$CX$9,0))} -> 0 | ... O14: {=INDEX('Adj. P&L'!$D$11:$CX$119,MATCH($A14,'Adj. P&L'!$C$11:$C$119,0),MATCH(O$1,'Adj. P&L'!$D$9:$CX$9,0))} -> 376.71205 | Q14: {=INDEX('Adj. P&L'!$D$11:$CX$119,MATCH($A14,'Adj. P&L'!$C$11:$C$119,0),MATCH(Q$1,'Adj. P&L'!$D$9:$CX$9,0))} -> 1963.4147 | R14: {=INDEX('Adj. P&L'!$D$11:$CX$119,MATCH($A14,'Adj. P&L'!$C$11:$C$119,0),MATCH(R$1,'Adj. P&L'!$D$9:$CX$9,0))} -> 2671.073 | S14: {=INDEX('Adj. P&L'!$D$11:$CX$119,MATCH($A14,'Adj. P&L'!$C$11:$C$119,0),MATCH(S$1,'Adj. P&L'!$D$9:$CX$9,0))} -> 3799.3385 | U14: {=INDEX('Adj. P&L'!$D$11:$CX$119,MATCH($A14,'Adj. P&L'!$C$11:$C$119,0),MATCH(U$1,'Adj. P&L'!$D$9:$CX$9,0))} -> 1689.6162 | V14: {=INDEX('Adj. P&L'!$D$11:$CX$119,MATCH($A14,'Adj. P&L'!$C$11:$C$119,0),MATCH(V$1,'Adj. P&L'!$D$9:$CX$9,0))} -> 2447.7819 | W14: {=INDEX('Adj. P&L'!$D$11:$CX$119,MATCH($A14,'Adj. P&L'!$C$11:$C$119,0),MATCH(W$1,'Adj. P&L'!$D$9:$CX$9,0))} -> 3467.3041
A15: Adjusted EBITDAR | C15: EBITDAR | D15: {=INDEX('Adj. P&L'!$D$11:$CX$119,MATCH($A15,'Adj. P&L'!$C$11:$C$119,0),MATCH(D$1,'Adj. P&L'!$D$9:$CX$9,0))} -> 48.268789 | E15: {=INDEX('Adj. P&L'!$D$11:$CX$119,MATCH($A15,'Adj. P&L'!$C$11:$C$119,0),MATCH(E$1,'Adj. P&L'!$D$9:$CX$9,0))} -> 23.790508 | F15: {=INDEX('Adj. P&L'!$D$11:$CX$119,MATCH($A15,'Adj. P&L'!$C$11:$C$119,0),MATCH(F$1,'Adj. P&L'!$D$9:$CX$9,0))} -> 71.364649 | G15: {=INDEX('Adj. P&L'!$D$11:$CX$119,MATCH($A15,'Adj. P&L'!$C$11:$C$119,0),MATCH(G$1,'Adj. P&L'!$D$9:$CX$9,0))} -> 100.16013 | H15: {=INDEX('Adj. P&L'!$D$11:$CX$119,MATCH($A15,'Adj. P&L'!$C$11:$C$119,0),MATCH(H$1,'Adj. P&L'!$D$9:$CX$9,0))} -> 132.74032 | I15: {=INDEX('Adj. P&L'!$D$11:$CX$119,MATCH($A15,'Adj. P&L'!$C$11:$C$119,0),MATCH(I$1,'Adj. P&L'!$D$9:$CX$9,0))} -> 42.60307 | J15: {=INDEX('Adj. P&L'!$D$11:$CX$119,MATCH($A15,'Adj. P&L'!$C$11:$C$119,0),MATCH(J$1,'Adj. P&L'!$D$9:$CX$9,0))} -> -10.321925 | K15: {=INDEX('Adj. P&L'!$D$11:$CX$119,MATCH($A15,'Adj. P&L'!$C$11:$C$119,0),MATCH(K$1,'Adj. P&L'!$D$9:$CX$9,0))} -> -44.904764 | ... O15: {=INDEX('Adj. P&L'!$D$11:$CX$119,MATCH($A15,'Adj. P&L'!$C$11:$C$119,0),MATCH(O$1,'Adj. P&L'!$D$9:$CX$9,0))} -> 170.72079 | Q15: {=INDEX('Adj. P&L'!$D$11:$CX$119,MATCH($A15,'Adj. P&L'!$C$11:$C$119,0),MATCH(Q$1,'Adj. P&L'!$D$9:$CX$9,0))} -> 593.04724 | R15: {=INDEX('Adj. P&L'!$D$11:$CX$119,MATCH($A15,'Adj. P&L'!$C$11:$C$119,0),MATCH(R$1,'Adj. P&L'!$D$9:$CX$9,0))} -> 807.83677 | S15: {=INDEX('Adj. P&L'!$D$11:$CX$119,MATCH($A15,'Adj. P&L'!$C$11:$C$119,0),MATCH(S$1,'Adj. P&L'!$D$9:$CX$9,0))} -> 1220.2729 | U15: {=INDEX('Adj. P&L'!$D$11:$CX$119,MATCH($A15,'Adj. P&L'!$C$11:$C$119,0),MATCH(U$1,'Adj. P&L'!$D$9:$CX$9,0))} -> 579.92769 | V15: {=INDEX('Adj. P&L'!$D$11:$CX$119,MATCH($A15,'Adj. P&L'!$C$11:$C$119,0),MATCH(V$1,'Adj. P&L'!$D$9:$CX$9,0))} -> 739.2378 | W15: {=INDEX('Adj. P&L'!$D$11:$CX$119,MATCH($A15,'Adj. P&L'!$C$11:$C$119,0),MATCH(W$1,'Adj. P&L'!$D$9:$CX$9,0))} -> 1150.5784

Sheet Valuation
C3: Firefly Lane
C4: Valuation
C6: Inputs
C7: Cap Rate | D7: 0.072
C8: LTM EBITDAR | D8: ='Adj. P&L'!CC111 -> 559.60715
C9: Y1 EBITDAR | D9: ='Adj. P&L'!CD111 -> 593.04724
C10: PF Year 2 EBITDAR | D10: ='Adj. P&L'!CE111 -> 807.83677
C12: $ in thousands | D12: WH Offer
D13: WholeCo | E13: OpCo w/ SLB
C15: Deal Value
C17: Implied Total Value (RE + Business) | D17: =D20 -> 3600 | E17: =E20-E19 -> 3600
C19: (-) Implied Real Estate Value (EPRT) | D19: =D43 -> 0 | E19: -2000
C20: Walters Purchase Price | D20: 3600 | E20: 1600
C22: (-) Seller Financing | D22: =D46 -> 0 | E22: =E46 -> 0
C23: Walters Purchase Price | D23: =D20+D22 -> 3600 | E23: =E20+E22 -> 1600
C25: Transaction Expenses
C26: Broker Fee
C27: Other Transaction Expenses
C28: Deposits not Received
C29: Transaction Value | D29: =D26+D28 -> 0 | E29: =E26+E28 -> 0
C31: Deal Value
C33: LTM EBITDAR | D33: =$D$8 -> 559.60715 | E33: =$D$8 -> 559.60715
C34: Y1 EBITDAR | D34: =$D$9 -> 593.04724 | E34: =$D$9 -> 593.04724
C35: Y2 EBITDAR | D35: =$D$10 -> 807.83677 | E35: =$D$10 -> 807.83677
C37: LTM EBITDA | D37: =D33-D$42 -> 559.60715 | E37: =E33-E$42 -> 415.60715
C38: Y1 EBITDA | D38: =D34-D$42 -> 593.04724 | E38: =E34-E$42 -> 449.04724
C39: Y2 EBITDA | D39: =D35-D$42 -> 807.83677 | E39: =E35-E$42 -> 663.83677
C41: Memo: Real Estate Value
C42: Rent | D42: 0 | E42: =E43*$D$7 -> 144
C43: ="Implied SLB Value ("&TEXT(D7,"0.0%")&" Cap Rate)" -> Implied SLB Value (7.2% Cap Rate) | D43: =D42/$D$7 -> 0 | E43: =-E19 -> 2000
C44: Rent Coverage - Closing EBITDAR | D44: =IFERROR(D33/D42,0) -> 0 | E44: =IFERROR(E33/E42,0) -> 3.8861607
C45: Rent Coverage - PF EBITDAR | D45: =IFERROR(D35/D42,0) -> 0 | E45: =IFERROR(E35/E42,0) -> 5.6099775
C47: Multiples
C49: LTM
C51: Lender Multiple (Upfront / EBITDA) | D51: =D$23/D37 -> 6.4330844 | E51: =E$23/E37 -> 3.8497894
C52: Purchase Multiple (Deal Value / EBITDAR) | D52: =D$17/D33 -> 6.4330844 | E52: =E$17/E33 -> 6.4330844
C54: PF Year 1
C56: Lender Multiple (Upfront / EBITDA) | D56: =D$23/D38 -> 6.0703427 | E56: =E$23/E38 -> 3.5630995
C57: Purchase Multiple (Deal Value / EBITDAR) | D57: =D$17/D34 -> 6.0703427 | E57: =E$17/E34 -> 6.0703427
C59: PF Year 2
...

Sheet Sales & Marketing Summary
D3: =Checks!$C$3 -> Firefly Lane
D4: Sales / Marketing Summary
D6: Note: Contracts includes elopement contracts
D7: Month | E7: # Leads | F7: Tours | G7: Contracts | H7: L->T | I7: T->C | J7: L->C
D9: Monthly Average
D10: 1 | E10: =AVERAGEIFS(E$19:E$61,$B$19:$B$61,$D10) -> 125.5 | F10: =AVERAGEIFS(F$19:F$61,$B$19:$B$61,$D10) -> 35.416667 | G10: =AVERAGEIFS(G$19:G$61,$B$19:$B$61,$D10) -> 15.833333 | H10: =F10/E10 -> 0.28220452 | I10: =G10/F10 -> 0.44705882 | J10: =G10/E10 -> 0.12616202
D11: 2 | E11: =AVERAGEIFS(E$19:E$61,$B$19:$B$61,$D11) -> 131.75 | F11: =AVERAGEIFS(F$19:F$61,$B$19:$B$61,$D11) -> 39.583333 | G11: =AVERAGEIFS(G$19:G$61,$B$19:$B$61,$D11) -> 16.666667 | H11: =F11/E11 -> 0.30044276 | I11: =G11/F11 -> 0.42105263 | J11: =G11/E11 -> 0.12650221
D12: 3 | E12: =AVERAGEIFS(E$19:E$61,$B$19:$B$61,$D12) -> 138.33333 | F12: =AVERAGEIFS(F$19:F$61,$B$19:$B$61,$D12) -> 43.75 | G12: =AVERAGEIFS(G$19:G$61,$B$19:$B$61,$D12) -> 17.5 | H12: =F12/E12 -> 0.31626506 | I12: =G12/F12 -> 0.4 | J12: =G12/E12 -> 0.12650602
A14: =YEAR(D14) -> 2026 | D14: 46053
A15: =YEAR(D15) -> 2026 | D15: =EOMONTH(D14,1) -> 46081
A16: =YEAR(D16) -> 2026 | D16: =EOMONTH(D15,1) -> 46112
A17: =YEAR(D17) -> 2026 | D17: =EOMONTH(D16,1) -> 46142
A18: =YEAR(D18) -> 2026 | D18: =EOMONTH(D17,1) -> 46173
A19: =YEAR(D19) -> 2026 | B19: 1 | D19: =EOMONTH(D18,1) -> 46203 | E19: =SUMIFS('Adj. P&L'!$11:$11,'Adj. P&L'!$9:$9,$D19) -> 118.89474 | F19: =SUMIFS('Adj. P&L'!$15:$15,'Adj. P&L'!$9:$9,$D19) -> 33.552632 | G19: =SUMIFS('Adj. P&L'!$22:$22,'Adj. P&L'!$9:$9,$D19) -> 15 | H19: =F19/E19 -> 0.28220452 | I19: =G19/F19 -> 0.44705882 | J19: =G19/E19 -> 0.12616202
A20: =YEAR(D20) -> 2026 | B20: =B19 -> 1 | D20: =EOMONTH(D19,1) -> 46234 | E20: =SUMIFS('Adj. P&L'!$11:$11,'Adj. P&L'!$9:$9,$D20) -> 190.23158 | F20: =SUMIFS('Adj. P&L'!$15:$15,'Adj. P&L'!$9:$9,$D20) -> 53.684211 | G20: =SUMIFS('Adj. P&L'!$22:$22,'Adj. P&L'!$9:$9,$D20) -> 24 | H20: =F20/E20 -> 0.28220452 | I20: =G20/F20 -> 0.44705882 | J20: =G20/E20 -> 0.12616202
A21: =YEAR(D21) -> 2026 | B21: =B20 -> 1 | D21: =EOMONTH(D20,1) -> 46265 | E21: =SUMIFS('Adj. P&L'!$11:$11,'Adj. P&L'!$9:$9,$D21) -> 166.45263 | F21: =SUMIFS('Adj. P&L'!$15:$15,'Adj. P&L'!$9:$9,$D21) -> 46.973684 | G21: =SUMIFS('Adj. P&L'!$22:$22,'Adj. P&L'!$9:$9,$D21) -> 21 | H21: =F21/E21 -> 0.28220452 | I21: =G21/F21 -> 0.44705882 | J21: =G21/E21 -> 0.12616202
A22: =YEAR(D22) -> 2026 | B22: =B21 -> 1 | D22: =EOMONTH(D21,1) -> 46295 | E22: =SUMIFS('Adj. P&L'!$11:$11,'Adj. P&L'!$9:$9,$D22) -> 126.82105 | F22: =SUMIFS('Adj. P&L'!$15:$15,'Adj. P&L'!$9:$9,$D22) -> 35.789474 | G22: =SUMIFS('Adj. P&L'!$22:$22,'Adj. P&L'!$9:$9,$D22) -> 16 | H22: =F22/E22 -> 0.28220452 | I22: =G22/F22 -> 0.44705882 | J22: =G22/E22 -> 0.12616202
A23: =YEAR(D23) -> 2026 | B23: =B22 -> 1 | D23: =EOMONTH(D22,1) -> 46326 | E23: =SUMIFS('Adj. P&L'!$11:$11,'Adj. P&L'!$9:$9,$D23) -> 95.115789 | F23: =SUMIFS('Adj. P&L'!$15:$15,'Adj. P&L'!$9:$9,$D23) -> 26.842105 | G23: =SUMIFS('Adj. P&L'!$22:$22,'Adj. P&L'!$9:$9,$D23) -> 12 | H23: =F23/E23 -> 0.28220452 | I23: =G23/F23 -> 0.44705882 | J23: =G23/E23 -> 0.12616202
A24: =YEAR(D24) -> 2026 | B24: =B23 -> 1 | D24: =EOMONTH(D23,1) -> 46356 | E24: =SUMIFS('Adj. P&L'!$11:$11,'Adj. P&L'!$9:$9,$D24) -> 126.82105 | F24: =SUMIFS('Adj. P&L'!$15:$15,'Adj. P&L'!$9:$9,$D24) -> 35.789474 | G24: =SUMIFS('Adj. P&L'!$22:$22,'Adj. P&L'!$9:$9,$D24) -> 16 | H24: =F24/E24 -> 0.28220452 | I24: =G24/F24 -> 0.44705882 | J24: =G24/E24 -> 0.12616202
A25: =YEAR(D25) -> 2026 | B25: =B24 -> 1 | D25: =EOMONTH(D24,1) -> 46387 | E25: =SUMIFS('Adj. P&L'!$11:$11,'Adj. P&L'!$9:$9,$D25) -> 87.189474 | F25: =SUMIFS('Adj. P&L'!$15:$15,'Adj. P&L'!$9:$9,$D25) -> 24.605263 | G25: =SUMIFS('Adj. P&L'!$22:$22,'Adj. P&L'!$9:$9,$D25) -> 11 | H25: =F25/E25 -> 0.28220452 | I25: =G25/F25 -> 0.44705882 | J25: =G25/E25 -> 0.12616202
A26: =YEAR(D26) -> 2027 | B26: =B25 -> 1 | D26: =EOMONTH(D25,1) -> 46418 | E26: =SUMIFS('Adj. P&L'!$11:$11,'Adj. P&L'!$9:$9,$D26) -> 166.45263 | F26: =SUMIFS('Adj. P&L'!$15:$15,'Adj. P&L'!$9:$9,$D26) -> 46.973684 | G26: =SUMIFS('Adj. P&L'!$22:$22,'Adj. P&L'!$9:$9,$D26) -> 21 | H26: =F26/E26 -> 0.28220452 | I26: =G26/F26 -> 0.44705882 | J26: =G26/E26 -> 0.12616202
A27: =YEAR(D27) -> 2027 | B27: =B26 -> 1 | D27: =EOMONTH(D26,1) -> 46446 | E27: =SUMIFS('Adj. P&L'!$11:$11,'Adj. P&L'!$9:$9,$D27) -> 87.189474 | F27: =SUMIFS('Adj. P&L'!$15:$15,'Adj. P&L'!$9:$9,$D27) -> 24.605263 | G27: =SUMIFS('Adj. P&L'!$22:$22,'Adj. P&L'!$9:$9,$D27) -> 11 | H27: =F27/E27 -> 0.28220452 | I27: =G27/F27 -> 0.44705882 | J27: =G27/E27 -> 0.12616202
A28: =YEAR(D28) -> 2027 | B28: =B27 -> 1 | D28: =EOMONTH(D27,1) -> 46477 | E28: =SUMIFS('Adj. P&L'!$11:$11,'Adj. P&L'!$9:$9,$D28) -> 134.74737 | F28: =SUMIFS('Adj. P&L'!$15:$15,'Adj. P&L'!$9:$9,$D28) -> 38.026316 | G28: =SUMIFS('Adj. P&L'!$22:$22,'Adj. P&L'!$9:$9,$D28) -> 17 | H28: =F28/E28 -> 0.28220452 | I28: =G28/F28 -> 0.44705882 | J28: =G28/E28 -> 0.12616202
A29: =YEAR(D29) -> 2027 | B29: =B28 -> 1 | D29: =EOMONTH(D28,1) -> 46507 | E29: =SUMIFS('Adj. P&L'!$11:$11,'Adj. P&L'!$9:$9,$D29) -> 103.04211 | F29: =SUMIFS('Adj. P&L'!$15:$15,'Adj. P&L'!$9:$9,$D29) -> 29.078947 | G29: =SUMIFS('Adj. P&L'!$22:$22,'Adj. P&L'!$9:$9,$D29) -> 13 | H29: =F29/E29 -> 0.28220452 | I29: =G29/F29 -> 0.44705882 | J29: =G29/E29 -> 0.12616202
A30: =YEAR(D30) -> 2027 | B30: =B29 -> 1 | D30: =EOMONTH(D29,1) -> 46538 | E30: =SUMIFS('Adj. P&L'!$11:$11,'Adj. P&L'!$9:$9,$D30) -> 103.04211 | F30: =SUMIFS('Adj. P&L'!$15:$15,'Adj. P&L'!$9:$9,$D30) -> 29.078947 | G30: =SUMIFS('Adj. P&L'!$22:$22,'Adj. P&L'!$9:$9,$D30) -> 13 | H30: =F30/E30 -> 0.28220452 | I30: =G30/F30 -> 0.44705882 | J30: =G30/E30 -> 0.12616202
A31: =YEAR(D31) -> 2027 | B31: =B19+1 -> 2 | D31: =EOMONTH(D30,1) -> 46568 | E31: =SUMIFS('Adj. P&L'!$11:$11,'Adj. P&L'!$9:$9,$D31) -> 158.1 | F31: =SUMIFS('Adj. P&L'!$15:$15,'Adj. P&L'!$9:$9,$D31) -> 47.5 | G31: =SUMIFS('Adj. P&L'!$22:$22,'Adj. P&L'!$9:$9,$D31) -> 20 | H31: =F31/E31 -> 0.30044276 | I31: =G31/F31 -> 0.42105263 | J31: =G31/E31 -> 0.12650221
A32: =YEAR(D32) -> 2027 | B32: =B20+1 -> 2 | D32: =EOMONTH(D31,1) -> 46599 | E32: =SUMIFS('Adj. P&L'!$11:$11,'Adj. P&L'!$9:$9,$D32) -> 221.34 | F32: =SUMIFS('Adj. P&L'!$15:$15,'Adj. P&L'!$9:$9,$D32) -> 66.5 | G32: =SUMIFS('Adj. P&L'!$22:$22,'Adj. P&L'!$9:$9,$D32) -> 28 | H32: =F32/E32 -> 0.30044276 | I32: =G32/F32 -> 0.42105263 | J32: =G32/E32 -> 0.12650221
A33: =YEAR(D33) -> 2027 | B33: =B21+1 -> 2 | D33: =EOMONTH(D32,1) -> 46630 | E33: =SUMIFS('Adj. P&L'!$11:$11,'Adj. P&L'!$9:$9,$D33) -> 189.72 | F33: =SUMIFS('Adj. P&L'!$15:$15,'Adj. P&L'!$9:$9,$D33) -> 57 | G33: =SUMIFS('Adj. P&L'!$22:$22,'Adj. P&L'!$9:$9,$D33) -> 24 | H33: =F33/E33 -> 0.30044276 | I33: =G33/F33 -> 0.42105263 | J33: =G33/E33 -> 0.12650221
A34: =YEAR(D34) -> 2027 | B34: =B22+1 -> 2 | D34: =EOMONTH(D33,1) -> 46660 | E34: =SUMIFS('Adj. P&L'!$11:$11,'Adj. P&L'!$9:$9,$D34) -> 126.48 | F34: =SUMIFS('Adj. P&L'!$15:$15,'Adj. P&L'!$9:$9,$D34) -> 38 | G34: =SUMIFS('Adj. P&L'!$22:$22,'Adj. P&L'!$9:$9,$D34) -> 16 | H34: =F34/E34 -> 0.30044276 | I34: =G34/F34 -> 0.42105263 | J34: =G34/E34 -> 0.12650221
A35: =YEAR(D35) -> 2027 | B35: =B23+1 -> 2 | D35: =EOMONTH(D34,1) -> 46691 | E35: =SUMIFS('Adj. P&L'!$11:$11,'Adj. P&L'!$9:$9,$D35) -> 94.86 | F35: =SUMIFS('Adj. P&L'!$15:$15,'Adj. P&L'!$9:$9,$D35) -> 28.5 | G35: =SUMIFS('Adj. P&L'!$22:$22,'Adj. P&L'!$9:$9,$D35) -> 12 | H35: =F35/E35 -> 0.30044276 | I35: =G35/F35 -> 0.42105263 | J35: =G35/E35 -> 0.12650221
A36: =YEAR(D36) -> 2027 | B36: =B24+1 -> 2 | D36: =EOMONTH(D35,1) -> 46721 | E36: =SUMIFS('Adj. P&L'!$11:$11,'Adj. P&L'!$9:$9,$D36) -> 110.67 | F36: =SUMIFS('Adj. P&L'!$15:$15,'Adj. P&L'!$9:$9,$D36) -> 33.25 | G36: =SUMIFS('Adj. P&L'!$22:$22,'Adj. P&L'!$9:$9,$D36) -> 14 | H36: =F36/E36 -> 0.30044276 | I36: =G36/F36 -> 0.42105263 | J36: =G36/E36 -> 0.12650221
A37: =YEAR(D37) -> 2027 | B37: =B25+1 -> 2 | D37: =EOMONTH(D36,1) -> 46752 | E37: =SUMIFS('Adj. P&L'!$11:$11,'Adj. P&L'!$9:$9,$D37) -> 47.43 | F37: =SUMIFS('Adj. P&L'!$15:$15,'Adj. P&L'!$9:$9,$D37) -> 14.25 | G37: =SUMIFS('Adj. P&L'!$22:$22,'Adj. P&L'!$9:$9,$D37) -> 6 | H37: =F37/E37 -> 0.30044276 | I37: =G37/F37 -> 0.42105263 | J37: =G37/E37 -> 0.12650221
A38: =YEAR(D38) -> 2028 | B38: =B26+1 -> 2 | D38: =EOMONTH(D37,1) -> 46783 | E38: =SUMIFS('Adj. P&L'!$11:$11,'Adj. P&L'!$9:$9,$D38) -> 173.91 | F38: =SUMIFS('Adj. P&L'!$15:$15,'Adj. P&L'!$9:$9,$D38) -> 52.25 | G38: =SUMIFS('Adj. P&L'!$22:$22,'Adj. P&L'!$9:$9,$D38) -> 22 | H38: =F38/E38 -> 0.30044276 | I38: =G38/F38 -> 0.42105263 | J38: =G38/E38 -> 0.12650221
A39: =YEAR(D39) -> 2028 | B39: =B27+1 -> 2 | D39: =EOMONTH(D38,1) -> 46812 | E39: =SUMIFS('Adj. P&L'!$11:$11,'Adj. P&L'!$9:$9,$D39) -> 94.86 | F39: =SUMIFS('Adj. P&L'!$15:$15,'Adj. P&L'!$9:$9,$D39) -> 28.5 | G39: =SUMIFS('Adj. P&L'!$22:$22,'Adj. P&L'!$9:$9,$D39) -> 12 | H39: =F39/E39 -> 0.30044276 | I39: =G39/F39 -> 0.42105263 | J39: =G39/E39 -> 0.12650221
A40: =YEAR(D40) -> 2028 | B40: =B28+1 -> 2 | D40: =EOMONTH(D39,1) -> 46843 | E40: =SUMIFS('Adj. P&L'!$11:$11,'Adj. P&L'!$9:$9,$D40) -> 142.29 | F40: =SUMIFS('Adj. P&L'!$15:$15,'Adj. P&L'!$9:$9,$D40) -> 42.75 | G40: =SUMIFS('Adj. P&L'!$22:$22,'Adj. P&L'!$9:$9,$D40) -> 18 | H40: =F40/E40 -> 0.30044276 | I40: =G40/F40 -> 0.42105263 | J40: =G40/E40 -> 0.12650221
A41: =YEAR(D41) -> 2028 | B41: =B29+1 -> 2 | D41: =EOMONTH(D40,1) -> 46873 | E41: =SUMIFS('Adj. P&L'!$11:$11,'Adj. P&L'!$9:$9,$D41) -> 110.67 | F41: =SUMIFS('Adj. P&L'!$15:$15,'Adj. P&L'!$9:$9,$D41) -> 33.25 | G41: =SUMIFS('Adj. P&L'!$22:$22,'Adj. P&L'!$9:$9,$D41) -> 14 | H41: =F41/E41 -> 0.30044276 | I41: =G41/F41 -> 0.42105263 | J41: =G41/E41 -> 0.12650221
A42: =YEAR(D42) -> 2028 | B42: =B30+1 -> 2 | D42: =EOMONTH(D41,1) -> 46904 | E42: =SUMIFS('Adj. P&L'!$11:$11,'Adj. P&L'!$9:$9,$D42) -> 110.67 | F42: =SUMIFS('Adj. P&L'!$15:$15,'Adj. P&L'!$9:$9,$D42) -> 33.25 | G42: =SUMIFS('Adj. P&L'!$22:$22,'Adj. P&L'!$9:$9,$D42) -> 14 | H42: =F42/E42 -> 0.30044276 | I42: =G42/F42 -> 0.42105263 | J42: =G42/E42 -> 0.12650221
... A61: =YEAR(D61) -> 2029 | B61: =B49+1 -> 4 | D61: =EOMONTH(D60,1) -> 47483 | E61: =SUMIFS('Adj. P&L'!$11:$11,'Adj. P&L'!$9:$9,$D61) -> 47.428571 | F61: =SUMIFS('Adj. P&L'!$15:$15,'Adj. P&L'!$9:$9,$D61) -> 15 | G61: =SUMIFS('Adj. P&L'!$22:$22,'Adj. P&L'!$9:$9,$D61) -> 6 | H61: =F61/E61 -> 0.31626506 | I61: =G61/F61 -> 0.4 | J61: =G61/E61 -> 0.12650602

Sheet Adj. P&L
D1: =YEAR(D9) -> 2024 | E1: =YEAR(E9) -> 2024 | F1: =YEAR(F9) -> 2024 | G1: =YEAR(G9) -> 2024 | H1: =YEAR(H9) -> 2024 | I1: =YEAR(I9) -> 2024 | J1: =YEAR(J9) -> 2024 | K1: =YEAR(K9) -> 2024 | ... AF1: =YEAR(AF9) -> 2026 | AH1: =YEAR(AH9) -> 2026 | AI1: =YEAR(AI9) -> 2026 | AJ1: =YEAR(AJ9) -> 2026 | AK1: =YEAR(AK9) -> 2026 | AL1: =YEAR(AL9) -> 2026 | AM1: =YEAR(AM9) -> 2026 | AN1: =YEAR(AN9) -> 2026 | AO1: =YEAR(AO9) -> 2027 | ... BQ1: =YEAR(BQ9) -> 2029 | BS1: =YEAR(BS9) -> 2029 | BT1: =YEAR(BT9) -> 2029 | BU1: =YEAR(BU9) -> 2029 | BV1: =YEAR(BV9) -> 2029 | BW1: =YEAR(BW9) -> 2029 | BX1: =YEAR(BX9) -> 2029 | BY1: =YEAR(BY9) -> 2029 | CH1: 1 | CI1: 2 | CJ1: 3 | CN1: DFW
D2: =MONTH(D9) -> 1 | E2: =MONTH(E9) -> 2 | F2: =MONTH(F9) -> 3 | G2: =MONTH(G9) -> 4 | H2: =MONTH(H9) -> 5 | I2: =MONTH(I9) -> 6 | J2: =MONTH(J9) -> 7 | K2: =MONTH(K9) -> 8 | ... AF2: =MONTH(AF9) -> 5 | AH2: =MONTH(AH9) -> 6 | AI2: =MONTH(AI9) -> 7 | AJ2: =MONTH(AJ9) -> 8 | AK2: =MONTH(AK9) -> 9 | AL2: =MONTH(AL9) -> 10 | AM2: =MONTH(AM9) -> 11 | AN2: =MONTH(AN9) -> 12 | AO2: =MONTH(AO9) -> 1 | ... BQ2: =MONTH(BQ9) -> 5 | BS2: =MONTH(BS9) -> 6 | BT2: =MONTH(BT9) -> 7 | BU2: =MONTH(BU9) -> 8 | BV2: =MONTH(BV9) -> 9 | BW2: =MONTH(BW9) -> 10 | BX2: =MONTH(BX9) -> 11 | BY2: =MONTH(BY9) -> 12 | CA2: 2024 | CB2: 2025 | CC2: LTM | CD2: 1 | CE2: 2 | CF2: 3 | CU2: 1 | CV2: 2 | CW2: 3 | CX2: 3
T3: LTM | U3: LTM | V3: LTM | W3: LTM | X3: LTM | Y3: LTM | Z3: LTM | AA3: LTM | AB3: LTM | AC3: LTM | AD3: LTM | AE3: LTM | AH3: 1 | AI3: =AH3 -> 1 | AJ3: =AI3 -> 1 | AK3: =AJ3 -> 1 | AL3: =AK3 -> 1 | AM3: =AL3 -> 1 | AN3: =AM3 -> 1 | AO3: =AN3 -> 1 | AP3: =AO3 -> 1 | ... AS3: =AR3 -> 1 | AT3: =AH3+1 -> 2 | AU3: =AI3+1 -> 2 | AV3: =AJ3+1 -> 2 | AW3: =AK3+1 -> 2 | AX3: =AL3+1 -> 2 | AY3: =AM3+1 -> 2 | AZ3: =AN3+1 -> 2 | BA3: =AO3+1 -> 2 | ... BQ3: =BE3+1 -> 3 | BS3: =BF3+1 -> 4 | BT3: =BG3+1 -> 4 | BU3: =BH3+1 -> 4 | BV3: =BI3+1 -> 4 | BW3: =BJ3+1 -> 4 | BX3: =BK3+1 -> 4 | BY3: =BL3+1 -> 4
C5: =Checks!$C$3 -> Firefly Lane | CN5: {=INDEX('FY25 By Venue Financials'!$1:$1,MATCH(CN1,'FY25 By Venue Financials'!$4:$4,0))} -> J
C6: PF P&L Analysis
D8: Historicals | P8: Historicals | AH8: Forecast | CA8: Historicals | CD8: PF | CH8: PF Drivers | CL8: Current | CN8: WH Comparable Venue | CU8: Annual
D9: 45322 | E9: =EOMONTH(D9,1) -> 45351 | F9: =EOMONTH(E9,1) -> 45382 | G9: =EOMONTH(F9,1) -> 45412 | H9: =EOMONTH(G9,1) -> 45443 | I9: =EOMONTH(H9,1) -> 45473 | J9: =EOMONTH(I9,1) -> 45504 | K9: =EOMONTH(J9,1) -> 45535 | L9: =EOMONTH(K9,1) -> 45565 | ... AF9: =EOMONTH(AE9,1) -> 46173 | AH9: =EOMONTH(AF9,1) -> 46203 | AI9: =EOMONTH(AH9,1) -> 46234 | AJ9: =EOMONTH(AI9,1) -> 46265 | AK9: =EOMONTH(AJ9,1) -> 46295 | AL9: =EOMONTH(AK9,1) -> 46326 | AM9: =EOMONTH(AL9,1) -> 46356 | AN9: =EOMONTH(AM9,1) -> 46387 | AO9: =EOMONTH(AN9,1) -> 46418 | AP9: =EOMONTH(AO9,1) -> 46446 | ... BQ9: =EOMONTH(BP9,1) -> 47269 | BS9: =EOMONTH(BQ9,1) -> 47299 | BT9: =EOMONTH(BS9,1) -> 47330 | BU9: =EOMONTH(BT9,1) -> 47361 | BV9: =EOMONTH(BU9,1) -> 47391 | BW9: =EOMONTH(BV9,1) -> 47422 | BX9: =EOMONTH(BW9,1) -> 47452 | BY9: =EOMONTH(BX9,1) -> 47483 | CA9: 2024 | CB9: 2025 | CC9: ='Events Summary'!$C$12 -> LTM Apr-26 | CD9: Y1 | CE9: Y2 | CF9: Y3 | CH9: Y1 | CI9: Y2 | CJ9: Y3 | CL9: % | CN9: $ | CO9: % | CQ9: % Type | CR9: Historical / PF Comments | CU9: 2026 | CV9: =CU9+1 -> 2027 | CW9: =CV9+1 -> 2028 | CX9: =CW9+1 -> 2029
C11: Leads | AH11: =AH15/AH13 -> 118.89474 | AI11: =AI15/AI13 -> 190.23158 | AJ11: =AJ15/AJ13 -> 166.45263 | AK11: =AK15/AK13 -> 126.82105 | AL11: =AL15/AL13 -> 95.115789 | AM11: =AM15/AM13 -> 126.82105 | AN11: =AN15/AN13 -> 87.189474 | AO11: =AO15/AO13 -> 166.45263 | ... BQ11: =BQ15/BQ13 -> 118.57143 | BS11: =BF11 -> 166 | BT11: =BG11 -> 237.14286 | BU11: =BH11 -> 197.61905 | BV11: =BI11 -> 134.38095 | BW11: =BJ11 -> 94.857143 | BX11: =BK11 -> 118.57143 | BY11: =BL11 -> 47.428571 | CA11: 0 | CB11: 0 | CC11: 0 | CD11: 1506 | CE11: =ROUND(CD11*1.05,0) -> 1581 | CF11: =ROUND(CE11*1.05,0) -> 1660 | CR11: Per Marketing | CU11: =SUMIFS($D11:$BZ11,$D$1:$BZ$1,CU$9) -> 911.52632 | CV11: =SUMIFS($D11:$BZ11,$D$1:$BZ$1,CV$9) -> 1543.0737 | CW11: =SUMIFS($D11:$BZ11,$D$1:$BZ$1,CW$9) -> 1628.4 | CX11: =SUMIFS($D11:$BZ11,$D$1:$BZ$1,CX$9) -> 1660
C13: L->T Conversion | AH13: =SUMIFS($CD13:$CF13,$CD$2:$CF$2,AH$3) -> 0.28220452 | AI13: =SUMIFS($CD13:$CF13,$CD$2:$CF$2,AI$3) -> 0.28220452 | AJ13: =SUMIFS($CD13:$CF13,$CD$2:$CF$2,AJ$3) -> 0.28220452 | AK13: =SUMIFS($CD13:$CF13,$CD$2:$CF$2,AK$3) -> 0.28220452 | AL13: =SUMIFS($CD13:$CF13,$CD$2:$CF$2,AL$3) -> 0.28220452 | AM13: =SUMIFS($CD13:$CF13,$CD$2:$CF$2,AM$3) -> 0.28220452 | AN13: =SUMIFS($CD13:$CF13,$CD$2:$CF$2,AN$3) -> 0.28220452 | AO13: =SUMIFS($CD13:$CF13,$CD$2:$CF$2,AO$3) -> 0.28220452 | ... BQ13: =SUMIFS($CD13:$CF13,$CD$2:$CF$2,BQ$3) -> 0.31626506 | CA13: 0 | CB13: 0 | CC13: 0 | CD13: =CD15/CD11 -> 0.28220452 | CE13: =CE15/CE11 -> 0.30044276 | CF13: =CF15/CF11 -> 0.31626506 | CU13: 0.12 | CV13: 0.12 | CW13: 0.12 | CX13: 0.12
C15: Tours | P15: =SUMIFS('Leads & Tours'!$D:$D,'Leads & Tours'!$A:$A,P$9) -> 29 | Q15: =SUMIFS('Leads & Tours'!$D:$D,'Leads & Tours'!$A:$A,Q$9) -> 16 | R15: =SUMIFS('Leads & Tours'!$D:$D,'Leads & Tours'!$A:$A,R$9) -> 17 | S15: =SUMIFS('Leads & Tours'!$D:$D,'Leads & Tours'!$A:$A,S$9) -> 13 | T15: =SUMIFS('Leads & Tours'!$D:$D,'Leads & Tours'!$A:$A,T$9) -> 19 | U15: =SUMIFS('Leads & Tours'!$D:$D,'Leads & Tours'!$A:$A,U$9) -> 24 | V15: =SUMIFS('Leads & Tours'!$D:$D,'Leads & Tours'!$A:$A,V$9) -> 34 | W15: =SUMIFS('Leads & Tours'!$D:$D,'Leads & Tours'!$A:$A,W$9) -> 30 | ... AF15: =SUMIFS('Leads & Tours'!$D:$D,'Leads & Tours'!$A:$A,AF$9) -> 16 | AH15: =AH22/AH17 -> 33.552632 | AI15: =AI22/AI17 -> 53.684211 | AJ15: =AJ22/AJ17 -> 46.973684 | AK15: =AK22/AK17 -> 35.789474 | AL15: =AL22/AL17 -> 26.842105 | AM15: =AM22/AM17 -> 35.789474 | AN15: =AN22/AN17 -> 24.605263 | AO15: =AO22/AO17 -> 46.973684 | ... BQ15: =BQ22/BQ17 -> 37.5 | BS15: =BF15 -> 52.5 | BT15: =BG15 -> 75 | BU15: =BH15 -> 62.5 | BV15: =BI15 -> 42.5 | BW15: =BJ15 -> 30 | BX15: =BK15 -> 37.5 | BY15: =BL15 -> 15 | CA15: =SUMIFS($D15:$BZ15,$D$1:$BZ$1,CA$2) -> 0 | CB15: =SUMIFS($D15:$BZ15,$D$1:$BZ$1,CB$2) -> 281 | CC15: =SUMIFS($P15:$AF15,$P$3:$AF$3,$CC$2) -> 312 | CD15: 425 | CE15: 475 | CF15: 525 | CU15: =SUMIFS($D15:$BZ15,$D$1:$BZ$1,CU$9) -> 379.23684 | CV15: =SUMIFS($D15:$BZ15,$D$1:$BZ$1,CV$9) -> 452.76316 | CW15: =SUMIFS($D15:$BZ15,$D$1:$BZ$1,CW$9) -> 505 | CX15: =SUMIFS($D15:$BZ15,$D$1:$BZ$1,CX$9) -> 525
C17: T->C Conversion | AH17: =SUMIFS($CD17:$CF17,$CD$2:$CF$2,AH$3) -> 0.44705882 | AI17: =SUMIFS($CD17:$CF17,$CD$2:$CF$2,AI$3) -> 0.44705882 | AJ17: =SUMIFS($CD17:$CF17,$CD$2:$CF$2,AJ$3) -> 0.44705882 | AK17: =SUMIFS($CD17:$CF17,$CD$2:$CF$2,AK$3) -> 0.44705882 | AL17: =SUMIFS($CD17:$CF17,$CD$2:$CF$2,AL$3) -> 0.44705882 | AM17: =SUMIFS($CD17:$CF17,$CD$2:$CF$2,AM$3) -> 0.44705882 | AN17: =SUMIFS($CD17:$CF17,$CD$2:$CF$2,AN$3) -> 0.44705882 | AO17: =SUMIFS($CD17:$CF17,$CD$2:$CF$2,AO$3) -> 0.44705882 | ... BQ17: =SUMIFS($CD17:$CF17,$CD$2:$CF$2,BQ$3) -> 0.4 | CA17: 0 | CB17: =CB22/CB15 -> 0.54092527 | CC17: =CC22/CC15 -> 0.4775641 | CD17: =CD22/CD15 -> 0.44705882 | CE17: =CE22/CE15 -> 0.42105263 | CF17: =CF22/CF15 -> 0.4 | CU17: =AVERAGE(0.39,0.4) -> 0.395 | CV17: =AVERAGE(0.39,0.4) -> 0.395 | CW17: =AVERAGE(0.39,0.4) -> 0.395 | CX17: =AVERAGE(0.39,0.4) -> 0.395
C19: Barn Contracts | D19: =SUMIFS('Events Summary'!$L:$L,'Events Summary'!$C:$C,D$9) -> 0 | E19: =SUMIFS('Events Summary'!$L:$L,'Events Summary'!$C:$C,E$9) -> 0 | F19: =SUMIFS('Events Summary'!$L:$L,'Events Summary'!$C:$C,F$9) -> 5 | G19: =SUMIFS('Events Summary'!$L:$L,'Events Summary'!$C:$C,G$9) -> 20 | H19: =SUMIFS('Events Summary'!$L:$L,'Events Summary'!$C:$C,H$9) -> 17 | I19: =SUMIFS('Events Summary'!$L:$L,'Events Summary'!$C:$C,I$9) -> 16 | J19: =SUMIFS('Events Summary'!$L:$L,'Events Summary'!$C:$C,J$9) -> 7 | K19: =SUMIFS('Events Summary'!$L:$L,'Events Summary'!$C:$C,K$9) -> 16 | ... O19: =SUMIFS('Events Summary'!$L:$L,'Events Summary'!$C:$C,O$9) -> 9 | P19: =SUMIFS('Date Booked Summary'!$D:$D,'Date Booked Summary'!$C:$C,P$9) -> 4 | Q19: =SUMIFS('Date Booked Summary'!$D:$D,'Date Booked Summary'!$C:$C,Q$9) -> 1 | R19: =SUMIFS('Date Booked Summary'!$D:$D,'Date Booked Summary'!$C:$C,R$9) -> 4 | S19: =SUMIFS('Date Booked Summary'!$D:$D,'Date Booked Summary'!$C:$C,S$9) -> 5 | T19: =SUMIFS('Date Booked Summary'!$D:$D,'Date Booked Summary'!$C:$C,T$9) -> 1 | U19: =SUMIFS('Date Booked Summary'!$D:$D,'Date Booked Summary'!$C:$C,U$9) -> 1 | V19: =SUMIFS('Date Booked Summary'!$D:$D,'Date Booked Summary'!$C:$C,V$9) -> 7 | W19: =SUMIFS('Date Booked Summary'!$D:$D,'Date Booked Summary'!$C:$C,W$9) -> 4 | ... AF19: =SUMIFS('Date Booked Summary'!$D:$D,'Date Booked Summary'!$C:$C,AF$9) -> 0 | AH19: 4 | AI19: 6 | AJ19: 5 | AK19: 5 | AL19: 3 | AM19: 4 | AN19: 2 | AO19: 6 | AP19: 3 | AQ19: 5 | AR19: 3 | AS19: 4 | AT19: =ROUND(SUMIFS($CD19:$CF19,$CD$2:$CF$2,AT$3)*AT$23,0) -> 6 | AU19: =ROUND(SUMIFS($CD19:$CF19,$CD$2:$CF$2,AU$3)*AU$23,0) -> 8 | AV19: =ROUND(SUMIFS($CD19:$CF19,$CD$2:$CF$2,AV$3)*AV$23,0) -> 7 | AW19: =ROUND(SUMIFS($CD19:$CF19,$CD$2:$CF$2,AW$3)*AW$23,0) -> 5 | AX19: =ROUND(SUMIFS($CD19:$CF19,$CD$2:$CF$2,AX$3)*AX$23,0) -> 4 | AY19: =ROUND(SUMIFS($CD19:$CF19,$CD$2:$CF$2,AY$3)*AY$23,0) -> 4 | AZ19: =ROUND(SUMIFS($CD19:$CF19,$CD$2:$CF$2,AZ$3)*AZ$23,0) -> 2 | BA19: =ROUND(SUMIFS($CD19:$CF19,$CD$2:$CF$2,BA$3)*BA$23,0) -> 7 | ... BK19: =ROUND(SUMIFS($CD19:$CF19,$CD$2:$CF$2,BK$3)*BK$23,0) -> 5 | BL19: 2 | BM19: =ROUND(SUMIFS($CD19:$CF19,$CD$2:$CF$2,BM$3)*BM$23,0) -> 8 | BN19: =ROUND(SUMIFS($CD19:$CF19,$CD$2:$CF$2,BN$3)*BN$23,0) -> 4 | BO19: =ROUND(SUMIFS($CD19:$CF19,$CD$2:$CF$2,BO$3)*BO$23,0) -> 6 | BP19: =ROUND(SUMIFS($CD19:$CF19,$CD$2:$CF$2,BP$3)*BP$23,0) -> 5 | BQ19: =ROUND(SUMIFS($CD19:$CF19,$CD$2:$CF$2,BQ$3)*BQ$23,0) -> 5 | BS19: =BF19 -> 7 | BT19: =BG19 -> 10 | BU19: =BH19 -> 8 | BV19: =BI19 -> 6 | BW19: =BJ19 -> 4 | BX19: =BK19 -> 5 | BY19: =BL19 -> 2 | CA19: 0 | CB19: =SUMIFS($D19:$BZ19,$D$1:$BZ$1,CB$2) -> 40 | CC19: =SUMIFS($P19:$AF19,$P$3:$AF$3,$CC$2) -> 40 | CD19: =SUMIFS($D19:$BZ19,$D$3:$BZ$3,CD$2) -> 50 | CE19: 60 | CF19: 70 | CU19: =SUMIFS($D19:$BZ19,$D$1:$BZ$1,CU$9) -> 43 | CV19: =SUMIFS($D19:$BZ19,$D$1:$BZ$1,CV$9) -> 57 | CW19: =SUMIFS($D19:$BZ19,$D$1:$BZ$1,CW$9) -> 66 | CX19: =SUMIFS($D19:$BZ19,$D$1:$BZ$1,CX$9) -> 70
C20: Chapel Contracts | P20: =SUMIFS('Date Booked Summary'!$E:$E,'Date Booked Summary'!$C:$C,P$9) -> 6 | Q20: =SUMIFS('Date Booked Summary'!$E:$E,'Date Booked Summary'!$C:$C,Q$9) -> 6 | R20: =SUMIFS('Date Booked Summary'!$E:$E,'Date Booked Summary'!$C:$C,R$9) -> 4 | S20: =SUMIFS('Date Booked Summary'!$E:$E,'Date Booked Summary'!$C:$C,S$9) -> 3 | T20: =SUMIFS('Date Booked Summary'!$E:$E,'Date Booked Summary'!$C:$C,T$9) -> 3 | U20: =SUMIFS('Date Booked Summary'!$E:$E,'Date Booked Summary'!$C:$C,U$9) -> 8 | V20: =SUMIFS('Date Booked Summary'!$E:$E,'Date Booked Summary'!$C:$C,V$9) -> 11 | W20: =SUMIFS('Date Booked Summary'!$E:$E,'Date Booked Summary'!$C:$C,W$9) -> 13 | ... AF20: =SUMIFS('Date Booked Summary'!$E:$E,'Date Booked Summary'!$C:$C,AF$9) -> 0 | AH20: 8 | AI20: 13 | AJ20: 11 | AK20: 8 | AL20: 6 | AM20: 9 | AN20: 6 | AO20: 11 | AP20: 6 | AQ20: 9 | AR20: 7 | AS20: 6 | AT20: =ROUND(SUMIFS($CD20:$CF20,$CD$2:$CF$2,AT$3)*AT$23,0) -> 10 | AU20: =ROUND(SUMIFS($CD20:$CF20,$CD$2:$CF$2,AU$3)*AU$23,0) -> 14 | AV20: =ROUND(SUMIFS($CD20:$CF20,$CD$2:$CF$2,AV$3)*AV$23,0) -> 12 | AW20: =ROUND(SUMIFS($CD20:$CF20,$CD$2:$CF$2,AW$3)*AW$23,0) -> 8 | AX20: =ROUND(SUMIFS($CD20:$CF20,$CD$2:$CF$2,AX$3)*AX$23,0) -> 6 | AY20: =ROUND(SUMIFS($CD20:$CF20,$CD$2:$CF$2,AY$3)*AY$23,0) -> 7 | AZ20: 3 | BA20: =ROUND(SUMIFS($CD20:$CF20,$CD$2:$CF$2,BA$3)*BA$23,0) -> 11 | BB20: =ROUND(SUMIFS($CD20:$CF20,$CD$2:$CF$2,BB$3)*BB$23,0) -> 6 | BC20: =ROUND(SUMIFS($CD20:$CF20,$CD$2:$CF$2,BC$3)*BC$23,0) -> 9 | BD20: =ROUND(SUMIFS($CD20:$CF20,$CD$2:$CF$2,BD$3)*BD$23,0) -> 7 | BE20: =ROUND(SUMIFS($CD20:$CF20,$CD$2:$CF$2,BE$3)*BE$23,0) -> 7 | BF20: =ROUND(SUMIFS($CD20:$CF20,$CD$2:$CF$2,BF$3)*BF$23,0) -> 10 | BG20: =ROUND(SUMIFS($CD20:$CF20,$CD$2:$CF$2,BG$3)*BG$23,0) -> 14 | BH20: =ROUND(SUMIFS($CD20:$CF20,$CD$2:$CF$2,BH$3)*BH$23,0) -> 12 | ... BK20: =ROUND(SUMIFS($CD20:$CF20,$CD$2:$CF$2,BK$3)*BK$23,0) -> 7 | BL20: 3 | BM20: =ROUND(SUMIFS($CD20:$CF20,$CD$2:$CF$2,BM$3)*BM$23,0) -> 11 | BN20: =ROUND(SUMIFS($CD20:$CF20,$CD$2:$CF$2,BN$3)*BN$23,0) -> 6 | BO20: =ROUND(SUMIFS($CD20:$CF20,$CD$2:$CF$2,BO$3)*BO$23,0) -> 9 | BP20: =ROUND(SUMIFS($CD20:$CF20,$CD$2:$CF$2,BP$3)*BP$23,0) -> 7 | BQ20: =ROUND(SUMIFS($CD20:$CF20,$CD$2:$CF$2,BQ$3)*BQ$23,0) -> 7 | BS20: =BF20 -> 10 | BT20: =BG20 -> 14 | BU20: =BH20 -> 12 | BV20: =BI20 -> 8 | BW20: =BJ20 -> 6 | BX20: =BK20 -> 7 | BY20: =BL20 -> 3 | CA20: =SUMIFS($D20:$BZ20,$D$1:$BZ$1,CA$2) -> 0 | CB20: =SUMIFS($D20:$BZ20,$D$1:$BZ$1,CB$2) -> 75 | CC20: =SUMIFS($P20:$AF20,$P$3:$AF$3,$CC$2) -> 81 | CD20: =SUMIFS($D20:$BZ20,$D$3:$BZ$3,CD$2) -> 100 | CE20: 100 | CF20: 100 | CU20: =SUMIFS($D20:$BZ20,$D$1:$BZ$1,CU$9) -> 86 | CV20: =SUMIFS($D20:$BZ20,$D$1:$BZ$1,CV$9) -> 99 | CW20: =SUMIFS($D20:$BZ20,$D$1:$BZ$1,CW$9) -> 100 | CX20: =SUMIFS($D20:$BZ20,$D$1:$BZ$1,CX$9) -> 100
C21: Elopement Contracts | P21: =SUMIFS('Date Booked Summary'!$H:$H,'Date Booked Summary'!$C:$C,P$9) -> 9 | Q21: =SUMIFS('Date Booked Summary'!$H:$H,'Date Booked Summary'!$C:$C,Q$9) -> 5 | R21: =SUMIFS('Date Booked Summary'!$H:$H,'Date Booked Summary'!$C:$C,R$9) -> 2 | S21: =SUMIFS('Date Booked Summary'!$H:$H,'Date Booked Summary'!$C:$C,S$9) -> 2 | T21: =SUMIFS('Date Booked Summary'!$H:$H,'Date Booked Summary'!$C:$C,T$9) -> 0 | U21: =SUMIFS('Date Booked Summary'!$H:$H,'Date Booked Summary'!$C:$C,U$9) -> 4 | V21: =SUMIFS('Date Booked Summary'!$H:$H,'Date Booked Summary'!$C:$C,V$9) -> 4 | W21: =SUMIFS('Date Booked Summary'!$H:$H,'Date Booked Summary'!$C:$C,W$9) -> 1 | ... AF21: =SUMIFS('Date Booked Summary'!$H:$H,'Date Booked Summary'!$C:$C,AF$9) -> 0 | AH21: 3 | AI21: 5 | AJ21: 5 | AK21: 3 | AL21: 3 | AM21: 3 | AN21: 3 | AO21: 4 | AP21: 2 | AQ21: 3 | AR21: 3 | AS21: 3 | AT21: =ROUND(SUMIFS($CD21:$CF21,$CD$2:$CF$2,AT$3)*AT$23,0) -> 4 | AU21: =ROUND(SUMIFS($CD21:$CF21,$CD$2:$CF$2,AU$3)*AU$23,0) -> 6 | AV21: =ROUND(SUMIFS($CD21:$CF21,$CD$2:$CF$2,AV$3)*AV$23,0) -> 5 | AW21: =ROUND(SUMIFS($CD21:$CF21,$CD$2:$CF$2,AW$3)*AW$23,0) -> 3 | AX21: =ROUND(SUMIFS($CD21:$CF21,$CD$2:$CF$2,AX$3)*AX$23,0) -> 2 | AY21: =ROUND(SUMIFS($CD21:$CF21,$CD$2:$CF$2,AY$3)*AY$23,0) -> 3 | AZ21: 1 | BA21: =ROUND(SUMIFS($CD21:$CF21,$CD$2:$CF$2,BA$3)*BA$23,0) -> 4 | BB21: =ROUND(SUMIFS($CD21:$CF21,$CD$2:$CF$2,BB$3)*BB$23,0) -> 2 | BC21: =ROUND(SUMIFS($CD21:$CF21,$CD$2:$CF$2,BC$3)*BC$23,0) -> 4 | BD21: =ROUND(SUMIFS($CD21:$CF21,$CD$2:$CF$2,BD$3)*BD$23,0) -> 3 | BE21: =ROUND(SUMIFS($CD21:$CF21,$CD$2:$CF$2,BE$3)*BE$23,0) -> 3 | BF21: =ROUND(SUMIFS($CD21:$CF21,$CD$2:$CF$2,BF$3)*BF$23,0) -> 4 | BG21: =ROUND(SUMIFS($CD21:$CF21,$CD$2:$CF$2,BG$3)*BG$23,0) -> 6 | BH21: =ROUND(SUMIFS($CD21:$CF21,$CD$2:$CF$2,BH$3)*BH$23,0) -> 5 | ... BK21: =ROUND(SUMIFS($CD21:$CF21,$CD$2:$CF$2,BK$3)*BK$23,0) -> 3 | BL21: 1 | BM21: =ROUND(SUMIFS($CD21:$CF21,$CD$2:$CF$2,BM$3)*BM$23,0) -> 4 | BN21: =ROUND(SUMIFS($CD21:$CF21,$CD$2:$CF$2,BN$3)*BN$23,0) -> 2 | BO21: =ROUND(SUMIFS($CD21:$CF21,$CD$2:$CF$2,BO$3)*BO$23,0) -> 4 | BP21: =ROUND(SUMIFS($CD21:$CF21,$CD$2:$CF$2,BP$3)*BP$23,0) -> 3 | BQ21: =ROUND(SUMIFS($CD21:$CF21,$CD$2:$CF$2,BQ$3)*BQ$23,0) -> 3 | BS21: =BF21 -> 4 | BT21: =BG21 -> 6 | BU21: =BH21 -> 5 | BV21: =BI21 -> 3 | BW21: =BJ21 -> 2 | BX21: =BK21 -> 3 | BY21: =BL21 -> 1 | CA21: =SUMIFS($D21:$BZ21,$D$1:$BZ$1,CA$2) -> 0 | CB21: =SUMIFS($D21:$BZ21,$D$1:$BZ$1,CB$2) -> 37 | CC21: =SUMIFS($P21:$AF21,$P$3:$AF$3,$CC$2) -> 28 | CD21: =SUMIFS($D21:$BZ21,$D$3:$BZ$3,CD$2) -> 40 | CE21: 40 | CF21: 40 | CU21: =SUMIFS($D21:$BZ21,$D$1:$BZ$1,CU$9) -> 34 | CV21: =SUMIFS($D21:$BZ21,$D$1:$BZ$1,CV$9) -> 39 | CW21: =SUMIFS($D21:$BZ21,$D$1:$BZ$1,CW$9) -> 40 | CX21: =SUMIFS($D21:$BZ21,$D$1:$BZ$1,CX$9) -> 40
C22: Contracts | D22: 0 | E22: 0 | F22: 0 | G22: 0 | H22: 0 | I22: 0 | J22: 0 | K22: 0 | L22: 0 | M22: 0 | N22: 0 | O22: 0 | P22: =SUM(P19:P21) -> 19 | Q22: =SUM(Q19:Q21) -> 12 | R22: =SUM(R19:R21) -> 10 | S22: =SUM(S19:S21) -> 10 | T22: =SUM(T19:T21) -> 4 | U22: =SUM(U19:U21) -> 13 | V22: =SUM(V19:V21) -> 22 | W22: =SUM(W19:W21) -> 18 | ... AF22: =SUM(AF19:AF21) -> 0 | AH22: =SUM(AH19:AH21) -> 15 | AI22: =SUM(AI19:AI21) -> 24 | AJ22: =SUM(AJ19:AJ21) -> 21 | AK22: =SUM(AK19:AK21) -> 16 | AL22: =SUM(AL19:AL21) -> 12 | AM22: =SUM(AM19:AM21) -> 16 | AN22: =SUM(AN19:AN21) -> 11 | AO22: =SUM(AO19:AO21) -> 21 | ... BQ22: =SUM(BQ19:BQ21) -> 15 | BS22: =SUM(BS19:BS21) -> 21 | BT22: =SUM(BT19:BT21) -> 30 | BU22: =SUM(BU19:BU21) -> 25 | BV22: =SUM(BV19:BV21) -> 17 | BW22: =SUM(BW19:BW21) -> 12 | BX22: =SUM(BX19:BX21) -> 15 | BY22: =SUM(BY19:BY21) -> 6 | CA22: =SUMIFS($D22:$BZ22,$D$1:$BZ$1,CA$2) -> 0 | CB22: =SUMIFS($D22:$BZ22,$D$1:$BZ$1,CB$2) -> 152 | CC22: =SUMIFS($P22:$AF22,$P$3:$AF$3,$CC$2) -> 149 | CD22: =SUM(CD19:CD21) -> 190 | CE22: =SUM(CE19:CE21) -> 200 | CF22: =SUM(CF19:CF21) -> 210 | CR22: Est.Y3 events are stabilized, so that many contracts each year | CU22: =SUMIFS($D22:$BZ22,$D$1:$BZ$1,CU$9) -> 163 | CV22: =SUMIFS($D22:$BZ22,$D$1:$BZ$1,CV$9) -> 195 | CW22: =SUMIFS($D22:$BZ22,$D$1:$BZ$1,CW$9) -> 206 | CX22: =SUMIFS($D22:$BZ22,$D$1:$BZ$1,CX$9) -> 210
C23: % of Annual Contracts | AH23: {=INDEX('Date Booked Summary'!$T$19:$T$30,MATCH(AH2,'Date Booked Summary'!$S$19:$S$30,0))} -> 0.1 | AI23: {=INDEX('Date Booked Summary'!$T$19:$T$30,MATCH(AI2,'Date Booked Summary'!$S$19:$S$30,0))} -> 0.14 | AJ23: {=INDEX('Date Booked Summary'!$T$19:$T$30,MATCH(AJ2,'Date Booked Summary'!$S$19:$S$30,0))} -> 0.12 | AK23: {=INDEX('Date Booked Summary'!$T$19:$T$30,MATCH(AK2,'Date Booked Summary'!$S$19:$S$30,0))} -> 0.08 | AL23: {=INDEX('Date Booked Summary'!$T$19:$T$30,MATCH(AL2,'Date Booked Summary'!$S$19:$S$30,0))} -> 0.06 | AM23: {=INDEX('Date Booked Summary'!$T$19:$T$30,MATCH(AM2,'Date Booked Summary'!$S$19:$S$30,0))} -> 0.07 | AN23: {=INDEX('Date Booked Summary'!$T$19:$T$30,MATCH(AN2,'Date Booked Summary'!$S$19:$S$30,0))} -> 0.04 | AO23: {=INDEX('Date Booked Summary'!$T$19:$T$30,MATCH(AO2,'Date Booked Summary'!$S$19:$S$30,0))} -> 0.11 | ... BQ23: {=INDEX('Date Booked Summary'!$T$19:$T$30,MATCH(BQ2,'Date Booked Summary'!$S$19:$S$30,0))} -> 0.07 | BS23: {=INDEX('Date Booked Summary'!$T$19:$T$30,MATCH(BS2,'Date Booked Summary'!$S$19:$S$30,0))} -> 0.1 | BT23: {=INDEX('Date Booked Summary'!$T$19:$T$30,MATCH(BT2,'Date Booked Summary'!$S$19:$S$30,0))} -> 0.14 | BU23: {=INDEX('Date Booked Summary'!$T$19:$T$30,MATCH(BU2,'Date Booked Summary'!$S$19:$S$30,0))} -> 0.12 | BV23: {=INDEX('Date Booked Summary'!$T$19:$T$30,MATCH(BV2,'Date Booked Summary'!$S$19:$S$30,0))} -> 0.08 | BW23: {=INDEX('Date Booked Summary'!$T$19:$T$30,MATCH(BW2,'Date Booked Summary'!$S$19:$S$30,0))} -> 0.06 | BX23: {=INDEX('Date Booked Summary'!$T$19:$T$30,MATCH(BX2,'Date Booked Summary'!$S$19:$S$30,0))} -> 0.07 | BY23: {=INDEX('Date Booked Summary'!$T$19:$T$30,MATCH(BY2,'Date Booked Summary'!$S$19:$S$30,0))} -> 0.04 | CD23: =CD22/CD11 -> 0.12616202 | CE23: =CE22/CE11 -> 0.12650221 | CF23: =CF22/CF11 -> 0.12650602
C25: Original - Barn | D25: {=IFERROR(INDEX('Events Summary'!$D:$D,MATCH(D$9,'Events Summary'!$C:$C,0)),0)} -> 0 | E25: {=IFERROR(INDEX('Events Summary'!$D:$D,MATCH(E$9,'Events Summary'!$C:$C,0)),0)} -> 0 | F25: {=IFERROR(INDEX('Events Summary'!$D:$D,MATCH(F$9,'Events Summary'!$C:$C,0)),0)} -> 5 | G25: {=IFERROR(INDEX('Events Summary'!$D:$D,MATCH(G$9,'Events Summary'!$C:$C,0)),0)} -> 8 | H25: {=IFERROR(INDEX('Events Summary'!$D:$D,MATCH(H$9,'Events Summary'!$C:$C,0)),0)} -> 5 | I25: {=IFERROR(INDEX('Events Summary'!$D:$D,MATCH(I$9,'Events Summary'!$C:$C,0)),0)} -> 3 | J25: {=IFERROR(INDEX('Events Summary'!$D:$D,MATCH(J$9,'Events Summary'!$C:$C,0)),0)} -> 0 | K25: {=IFERROR(INDEX('Events Summary'!$D:$D,MATCH(K$9,'Events Summary'!$C:$C,0)),0)} -> 3 | ... AF25: {=IFERROR(INDEX('Events Summary'!$D:$D,MATCH(AF$9,'Events Summary'!$C:$C,0)),0)} -> 7 | AH25: {=IFERROR(INDEX('Events Summary'!$D:$D,MATCH(AH$9,'Events Summary'!$C:$C,0)),0)} -> 2 | AI25: {=IFERROR(INDEX('Events Summary'!$D:$D,MATCH(AI$9,'Events Summary'!$C:$C,0)),0)} -> 1 | AJ25: {=IFERROR(INDEX('Events Summary'!$D:$D,MATCH(AJ$9,'Events Summary'!$C:$C,0)),0)} -> 3 | AK25: {=IFERROR(INDEX('Events Summary'!$D:$D,MATCH(AK$9,'Events Summary'!$C:$C,0)),0)} -> 8 | AL25: {=IFERROR(INDEX('Events Summary'!$D:$D,MATCH(AL$9,'Events Summary'!$C:$C,0)),0)} -> 11 | AM25: {=IFERROR(INDEX('Events Summary'!$D:$D,MATCH(AM$9,'Events Summary'!$C:$C,0)),0)} -> 2 | AN25: {=IFERROR(INDEX('Events Summary'!$D:$D,MATCH(AN$9,'Events Summary'!$C:$C,0)),0)} -> 0 | AO25: {=IFERROR(INDEX('Events Summary'!$D:$D,MATCH(AO$9,'Events Summary'!$C:$C,0)),0)} -> 0 | ... BQ25: {=IFERROR(INDEX('Events Summary'!$D:$D,MATCH(BQ$9,'Events Summary'!$C:$C,0)),0)} -> 0 | BS25: {=IFERROR(INDEX('Events Summary'!$D:$D,MATCH(BS$9,'Events Summary'!$C:$C,0)),0)} -> 0 | BT25: {=IFERROR(INDEX('Events Summary'!$D:$D,MATCH(BT$9,'Events Summary'!$C:$C,0)),0)} -> 0 | BU25: {=IFERROR(INDEX('Events Summary'!$D:$D,MATCH(BU$9,'Events Summary'!$C:$C,0)),0)} -> 0 | BV25: {=IFERROR(INDEX('Events Summary'!$D:$D,MATCH(BV$9,'Events Summary'!$C:$C,0)),0)} -> 0 | BW25: {=IFERROR(INDEX('Events Summary'!$D:$D,MATCH(BW$9,'Events Summary'!$C:$C,0)),0)} -> 0 | BX25: {=IFERROR(INDEX('Events Summary'!$D:$D,MATCH(BX$9,'Events Summary'!$C:$C,0)),0)} -> 0 | BY25: {=IFERROR(INDEX('Events Summary'!$D:$D,MATCH(BY$9,'Events Summary'!$C:$C,0)),0)} -> 0 | CA25: ='Revenue Analysis - Barn'!D11 -> 54 | CB25: ='Revenue Analysis - Barn'!E11 -> 47 | CC25: ='Revenue Analysis - Barn'!F11 -> 40 | CD25: ='Revenue Analysis - Barn'!G11 -> 35 | CE25: ='Revenue Analysis - Barn'!H11 -> 7 | CF25: ='Revenue Analysis - Barn'!I11 -> 0 | CU25: =SUMIFS($D25:$BZ25,$D$1:$BZ$1,CU$9) -> 39 | CV25: =SUMIFS($D25:$BZ25,$D$1:$BZ$1,CV$9) -> 15 | CW25: =SUMIFS($D25:$BZ25,$D$1:$BZ$1,CW$9) -> 0 | CX25: =SUMIFS($D25:$BZ25,$D$1:$BZ$1,CX$9) -> 0
C26: New - Barn | AN26: =AN27-AN25 -> 2 | AO26: =AO27-AO25 -> 0 | AP26: =AP27-AP25 -> 0 | AQ26: =AQ27-AQ25 -> 1 | AR26: =AR27-AR25 -> 6 | AS26: =AS27-AS25 -> 6 | AT26: =AT27-AT25 -> 6 | AU26: =AU27-AU25 -> 4 | ... BQ26: =BQ27-BQ25 -> 11 | BS26: =BS27-BS25 -> 8 | BT26: =BT27-BT25 -> 4 | BU26: =BU27-BU25 -> 7 | BV26: =BV27-BV25 -> 9 | BW26: =BW27-BW25 -> 11 | BX26: =BX27-BX25 -> 6 | BY26: =BY27-BY25 -> 2 | CD26: ='Revenue Analysis - Barn'!G12 -> 15 | CE26: ='Revenue Analysis - Barn'!H12 -> 53 | CF26: ='Revenue Analysis - Barn'!I12 -> 70 | CU26: =SUMIFS($D26:$BZ26,$D$1:$BZ$1,CU$9) -> 2 | CV26: =SUMIFS($D26:$BZ26,$D$1:$BZ$1,CV$9) -> 47 | CW26: =SUMIFS($D26:$BZ26,$D$1:$BZ$1,CW$9) -> 66 | CX26: =SUMIFS($D26:$BZ26,$D$1:$BZ$1,CX$9) -> 70
C27: Events - Barn | D27: =SUM(D25:D26) -> 0 | E27: =SUM(E25:E26) -> 0 | F27: =SUM(F25:F26) -> 5 | G27: =SUM(G25:G26) -> 8 | H27: =SUM(H25:H26) -> 5 | I27: =SUM(I25:I26) -> 3 | J27: =SUM(J25:J26) -> 0 | K27: =SUM(K25:K26) -> 3 | ... AF27: =SUM(AF25:AF26) -> 7 | AH27: =AH25 -> 2 | AI27: =AI25 -> 1 | AJ27: =AJ25 -> 3 | AK27: =AK25 -> 8 | AL27: =AL25 -> 11 | AM27: =AM25 -> 2 | AN27: 2 | AO27: =ROUND(($CD$27-SUM($AH$27:$AM$27))*(AB33/SUM($AA$33:$AF$33)),0) -> 0 | AP27: =ROUND(($CD$27-SUM($AH$27:$AM$27))*(AC33/SUM($AA$33:$AF$33)),0) -> 0 | AQ27: =ROUND(($CD$27-SUM($AH$27:$AM$27))*(AD33/SUM($AA$33:$AF$33)),0) -> 2 | AR27: =ROUND(($CD$27-SUM($AH$27:$AM$27))*(AE33/SUM($AA$33:$AF$33)),0) -> 8 | AS27: =ROUND(($CD$27-SUM($AH$27:$AM$27))*(AF33/SUM($AA$33:$AF$33)),0) -> 11 | AT27: {=ROUND(INDEX('Events Summary'!$AF:$AF,MATCH(AT$2,'Events Summary'!$AE:$AE,0))*SUMIFS($CD27:$CF27,$CD$2:$CF$2,AT$3),0)} -> 7 | AU27: {=ROUND(INDEX('Events Summary'!$AF:$AF,MATCH(AU$2,'Events Summary'!$AE:$AE,0))*SUMIFS($CD27:$CF27,$CD$2:$CF$2,AU$3),0)} -> 4 | AV27: {=ROUND(INDEX('Events Summary'!$AF:$AF,MATCH(AV$2,'Events Summary'!$AE:$AE,0))*SUMIFS($CD27:$CF27,$CD$2:$CF$2,AV$3),0)} -> 6 | AW27: {=ROUND(INDEX('Events Summary'!$AF:$AF,MATCH(AW$2,'Events Summary'!$AE:$AE,0))*SUMIFS($CD27:$CF27,$CD$2:$CF$2,AW$3),0)} -> 8 | AX27: {=ROUND(INDEX('Events Summary'!$AF:$AF,MATCH(AX$2,'Events Summary'!$AE:$AE,0))*SUMIFS($CD27:$CF27,$CD$2:$CF$2,AX$3),0)} -> 9 | AY27: {=ROUND(INDEX('Events Summary'!$AF:$AF,MATCH(AY$2,'Events Summary'!$AE:$AE,0))*SUMIFS($CD27:$CF27,$CD$2:$CF$2,AY$3),0)} -> 5 | AZ27: {=ROUND(INDEX('Events Summary'!$AF:$AF,MATCH(AZ$2,'Events Summary'!$AE:$AE,0))*SUMIFS($CD27:$CF27,$CD$2:$CF$2,AZ$3),0)} -> 2 | BA27: {=ROUND(INDEX('Events Summary'!$AF:$AF,MATCH(BA$2,'Events Summary'!$AE:$AE,0))*SUMIFS($CD27:$CF27,$CD$2:$CF$2,BA$3),0)} -> 0 | ... BK27: {=ROUND(INDEX('Events Summary'!$AF:$AF,MATCH(BK$2,'Events Summary'!$AE:$AE,0))*SUMIFS($CD27:$CF27,$CD$2:$CF$2,BK$3),0)} -> 6 | BL27: 2 | BM27: {=ROUND(INDEX('Events Summary'!$AF:$AF,MATCH(BM$2,'Events Summary'!$AE:$AE,0))*SUMIFS($CD27:$CF27,$CD$2:$CF$2,BM$3),0)} -> 0 | BN27: {=ROUND(INDEX('Events Summary'!$AF:$AF,MATCH(BN$2,'Events Summary'!$AE:$AE,0))*SUMIFS($CD27:$CF27,$CD$2:$CF$2,BN$3),0)} -> 0 | BO27: {=ROUND(INDEX('Events Summary'!$AF:$AF,MATCH(BO$2,'Events Summary'!$AE:$AE,0))*SUMIFS($CD27:$CF27,$CD$2:$CF$2,BO$3),0)} -> 4 | BP27: {=ROUND(INDEX('Events Summary'!$AF:$AF,MATCH(BP$2,'Events Summary'!$AE:$AE,0))*SUMIFS($CD27:$CF27,$CD$2:$CF$2,BP$3),0)} -> 8 | BQ27: {=ROUND(INDEX('Events Summary'!$AF:$AF,MATCH(BQ$2,'Events Summary'!$AE:$AE,0))*SUMIFS($CD27:$CF27,$CD$2:$CF$2,BQ$3),0)} -> 11 | BS27: =BF27 -> 8 | BT27: =BG27 -> 4 | BU27: =BH27 -> 7 | BV27: =BI27 -> 9 | BW27: =BJ27 -> 11 | BX27: =BK27 -> 6 | BY27: =BL27 -> 2 | CA27: =SUM(CA25:CA26) -> 54 | CB27: =SUM(CB25:CB26) -> 47 | CC27: =SUM(CC25:CC26) -> 40 | CD27: =SUM(CD25:CD26) -> 50 | CE27: =SUM(CE25:CE26) -> 60 | CF27: =SUM(CF25:CF26) -> 70 | CR27: See Revenue Analysis - Barn | CU27: =SUM(CU25:CU26) -> 41 | CV27: =SUM(CV25:CV26) -> 62 | CW27: =SUM(CW25:CW26) -> 66 | CX27: =SUM(CX25:CX26) -> 70
C29: Original - Chapel | D29: {=IFERROR(INDEX('Events Summary'!$H:$H,MATCH(D$9,'Events Summary'!$C:$C,0)),0)} -> 0 | E29: {=IFERROR(INDEX('Events Summary'!$H:$H,MATCH(E$9,'Events Summary'!$C:$C,0)),0)} -> 0 | F29: {=IFERROR(INDEX('Events Summary'!$H:$H,MATCH(F$9,'Events Summary'!$C:$C,0)),0)} -> 0 | G29: {=IFERROR(INDEX('Events Summary'!$H:$H,MATCH(G$9,'Events Summary'!$C:$C,0)),0)} -> 12 | H29: {=IFERROR(INDEX('Events Summary'!$H:$H,MATCH(H$9,'Events Summary'!$C:$C,0)),0)} -> 12 | I29: {=IFERROR(INDEX('Events Summary'!$H:$H,MATCH(I$9,'Events Summary'!$C:$C,0)),0)} -> 13 | J29: {=IFERROR(INDEX('Events Summary'!$H:$H,MATCH(J$9,'Events Summary'!$C:$C,0)),0)} -> 7 | K29: {=IFERROR(INDEX('Events Summary'!$H:$H,MATCH(K$9,'Events Summary'!$C:$C,0)),0)} -> 13 | ... AF29: {=IFERROR(INDEX('Events Summary'!$H:$H,MATCH(AF$9,'Events Summary'!$C:$C,0)),0)} -> 15 | AH29: {=IFERROR(INDEX('Events Summary'!$H:$H,MATCH(AH$9,'Events Summary'!$C:$C,0)),0)} -> 10 | AI29: {=IFERROR(INDEX('Events Summary'!$H:$H,MATCH(AI$9,'Events Summary'!$C:$C,0)),0)} -> 9 | AJ29: {=IFERROR(INDEX('Events Summary'!$H:$H,MATCH(AJ$9,'Events Summary'!$C:$C,0)),0)} -> 12 | AK29: {=IFERROR(INDEX('Events Summary'!$H:$H,MATCH(AK$9,'Events Summary'!$C:$C,0)),0)} -> 11 | AL29: {=IFERROR(INDEX('Events Summary'!$H:$H,MATCH(AL$9,'Events Summary'!$C:$C,0)),0)} -> 13 | AM29: {=IFERROR(INDEX('Events Summary'!$H:$H,MATCH(AM$9,'Events Summary'!$C:$C,0)),0)} -> 10 | AN29: {=IFERROR(INDEX('Events Summary'!$H:$H,MATCH(AN$9,'Events Summary'!$C:$C,0)),0)} -> 2 | AO29: {=IFERROR(INDEX('Events Summary'!$H:$H,MATCH(AO$9,'Events Summary'!$C:$C,0)),0)} -> 0 | ... BQ29: {=IFERROR(INDEX('Events Summary'!$H:$H,MATCH(BQ$9,'Events Summary'!$C:$C,0)),0)} -> 0 | BS29: {=IFERROR(INDEX('Events Summary'!$H:$H,MATCH(BS$9,'Events Summary'!$C:$C,0)),0)} -> 0 | BT29: {=IFERROR(INDEX('Events Summary'!$H:$H,MATCH(BT$9,'Events Summary'!$C:$C,0)),0)} -> 0 | BU29: {=IFERROR(INDEX('Events Summary'!$H:$H,MATCH(BU$9,'Events Summary'!$C:$C,0)),0)} -> 0 | BV29: {=IFERROR(INDEX('Events Summary'!$H:$H,MATCH(BV$9,'Events Summary'!$C:$C,0)),0)} -> 0 | BW29: {=IFERROR(INDEX('Events Summary'!$H:$H,MATCH(BW$9,'Events Summary'!$C:$C,0)),0)} -> 0 | BX29: {=IFERROR(INDEX('Events Summary'!$H:$H,MATCH(BX$9,'Events Summary'!$C:$C,0)),0)} -> 0 | BY29: {=IFERROR(INDEX('Events Summary'!$H:$H,MATCH(BY$9,'Events Summary'!$C:$C,0)),0)} -> 0 | CA29: ='Revenue Analysis - Chapel'!D11 -> 99 | CB29: ='Revenue Analysis - Chapel'!E11 -> 86 | CC29: ='Revenue Analysis - Chapel'!F11 -> 91 | CD29: ='Revenue Analysis - Chapel'!G11 -> 87 | CE29: ='Revenue Analysis - Chapel'!H11 -> 23 | CF29: ='Revenue Analysis - Chapel'!I11 -> 0 | CU29: =SUMIFS($D29:$BZ29,$D$1:$BZ$1,CU$9) -> 98 | CV29: =SUMIFS($D29:$BZ29,$D$1:$BZ$1,CV$9) -> 43 | CW29: =SUMIFS($D29:$BZ29,$D$1:$BZ$1,CW$9) -> 0 | CX29: =SUMIFS($D29:$BZ29,$D$1:$BZ$1,CX$9) -> 0
C30: New - Chapel | AN30: =AN31-AN29 -> 1 | AO30: =AO31-AO29 -> 0 | AP30: =AP31-AP29 -> 0 | AQ30: =AQ31-AQ29 -> 4 | AR30: =AR31-AR29 -> 5 | AS30: =AS31-AS29 -> 3 | AT30: =AT31-AT29 -> 1 | AU30: =AU31-AU29 -> 4 | ... BQ30: =BQ31-BQ29 -> 15 | BS30: =BS31-BS29 -> 11 | BT30: =BT31-BT29 -> 6 | BU30: =BU31-BU29 -> 10 | BV30: =BV31-BV29 -> 13 | BW30: =BW31-BW29 -> 15 | BX30: =BX31-BX29 -> 9 | BY30: =BY31-BY29 -> 4 | CD30: ='Revenue Analysis - Chapel'!G12 -> 13 | CE30: ='Revenue Analysis - Chapel'!H12 -> 77 | CF30: ='Revenue Analysis - Chapel'!I12 -> 100 | CU30: =SUMIFS($D30:$BZ30,$D$1:$BZ$1,CU$9) -> 1 | CV30: =SUMIFS($D30:$BZ30,$D$1:$BZ$1,CV$9) -> 57 | CW30: =SUMIFS($D30:$BZ30,$D$1:$BZ$1,CW$9) -> 100 | CX30: =SUMIFS($D30:$BZ30,$D$1:$BZ$1,CX$9) -> 100
