Workbook
Name _____I2: {"PVGraph2",#N/A,FALSE,"PV Data"}
Name _____I3: {"PVGraph2",#N/A,FALSE,"PV Data"}
Name _____w1: {"PVGraph2",#N/A,FALSE,"PV Data"}
Name _____w2: {"PVGraph2",#N/A,FALSE,"PV Data"}
Name _____w3: {"PVGraph2",#N/A,FALSE,"PV Data"}
Name _____y2: {"PVGraph2",#N/A,FALSE,"PV Data"}
Name ___I2: {"PVGraph2",#N/A,FALSE,"PV Data"}
Name ___I3: {"PVGraph2",#N/A,FALSE,"PV Data"}
Name ___w1: {"PVGraph2",#N/A,FALSE,"PV Data"}
Name ___w2: {"PVGraph2",#N/A,FALSE,"PV Data"}
Name ___w3: {"PVGraph2",#N/A,FALSE,"PV Data"}
Name ___y2: {"PVGraph2",#N/A,FALSE,"PV Data"}
Name __PL4: {#N/A,#N/A,FALSE,"Report Data";#N/A,#N/A,FALSE,"COMP POOL";#N/A,#N/A,FALSE,"COMP POOL NB95";#N/A,#N/A,FALSE,"COMP POOL NB94"}
Name _A11: {#N/A,#N/A,FALSE,"Umsatz 99";#N/A,#N/A,FALSE,"ER 99 "}
Name _c: {"Fiesta Facer Page",#N/A,FALSE,"Q_C_S";"Fiesta Main Page",#N/A,FALSE,"V_L";"Fiesta 95BP Struct",#N/A,FALSE,"StructBP";"Fiesta Post 95BP Struct",#N/A,FALSE,"AdjStructBP"}
Name _c83: {0,0,0,0;0,0,0,0;0,0,0,0}
Name _cd1: {#N/A,#N/A,FALSE,"Job Sched"}
Name _cd2: {#N/A,#N/A,FALSE,"Job Sched"}
Name _CD3: {#N/A,#N/A,FALSE,"Job Sched"}
Name _cd4: {#N/A,#N/A,FALSE,"Job Sched"}
Name _Cd5: {#N/A,#N/A,FALSE,"A"}
Name _cd8: {#N/A,#N/A,FALSE,"Job Sched"}
Name _fdf1: {"incomemth",#N/A,TRUE,"forecast00";"incomepercentmth",#N/A,TRUE,"forecast00";"balancemth",#N/A,TRUE,"forecast00";"cashmth",#N/A,TRUE,"forecast00";"covenantmth",#N/A,TRUE,"forecast00"}
Name _fdg1: {"incomemth",#N/A,TRUE,"forecast00";"incomepercentmth",#N/A,TRUE,"forecast00";"balancemth",#N/A,TRUE,"forecast00";"cashmth",#N/A,TRUE,"forecast00";"covenantmth",#N/A,TRUE,"forecast00"}
Name _gf1: {"incomemth",#N/A,TRUE,"forecast00";"incomepercentmth",#N/A,TRUE,"forecast00";"balancemth",#N/A,TRUE,"forecast00";"cashmth",#N/A,TRUE,"forecast00";"covenantmth",#N/A,TRUE,"forecast00"}
Name _I2: {"PVGraph2",#N/A,FALSE,"PV Data"}
Name _I3: {"PVGraph2",#N/A,FALSE,"PV Data"}
Name _mfg2: {"PAGE 1",#N/A,FALSE,"WEST_OT"}
Name _mfg3: {"PAGE 1",#N/A,FALSE,"WEST_OT"}
Name _mfg4: {"PAGE 1",#N/A,FALSE,"WEST_OT"}
Name _mfg5: {"PAGE 1",#N/A,FALSE,"WEST_OT"}
Name _nm12: {#N/A,#N/A,FALSE,"Land";#N/A,#N/A,FALSE,"Cost Analysis";"Summary",#N/A,FALSE,"Equipment"}
Name _rod1: {#N/A,#N/A,FALSE,"Projections";#N/A,#N/A,FALSE,"Multiples Valuation";#N/A,#N/A,FALSE,"LBO";#N/A,#N/A,FALSE,"Multiples_Sensitivity";#N/A,#N/A,FALSE,"Summary"}
Name _t1: {"bs",#N/A,FALSE,"SCF"}
Name _w1: {"PVGraph2",#N/A,FALSE,"PV Data"}
Name _w2: {"PVGraph2",#N/A,FALSE,"PV Data"}
Name _w3: {"PVGraph2",#N/A,FALSE,"PV Data"}
Name _wrn2: {#N/A,#N/A,FALSE,"ASSUMPTIONS";#N/A,#N/A,FALSE,"Valuation Summary";"page1",#N/A,FALSE,"PRESENTATION";"page2",#N/A,FALSE,"PRESENTATION";#N/A,#N/A,FALSE,"ORIGINAL_ROLLBACK"}
Name _wrn3: {#N/A,#N/A,FALSE,"ASSUMPTIONS";#N/A,#N/A,FALSE,"Valuation Summary";"page1",#N/A,FALSE,"PRESENTATION";"page2",#N/A,FALSE,"PRESENTATION";#N/A,#N/A,FALSE,"ORIGINAL_ROLLBACK"}
Name _wrn4: {"general",#N/A,FALSE,"Assumptions"}
Name _x1: {#N/A,#N/A,FALSE,"FY97";#N/A,#N/A,FALSE,"FY98";#N/A,#N/A,FALSE,"FY99";#N/A,#N/A,FALSE,"FY00";#N/A,#N/A,FALSE,"FY01"}
Name _y2: {"PVGraph2",#N/A,FALSE,"PV Data"}
Name a: {"histincome",#N/A,FALSE,"hyfins";"closing balance",#N/A,FALSE,"hyfins"}
Name a.: {#N/A,#N/A,TRUE,"KEY DATA";#N/A,#N/A,TRUE,"KEY DATA Base Case";#N/A,#N/A,TRUE,"JULY";#N/A,#N/A,TRUE,"AUG";#N/A,#N/A,TRUE,"SEPT";#N/A,#N/A,TRUE,"3Q"}
Name A..: {#N/A,#N/A,TRUE,"KEY DATA";#N/A,#N/A,TRUE,"KEY DATA Base Case";#N/A,#N/A,TRUE,"JULY";#N/A,#N/A,TRUE,"AUG";#N/A,#N/A,TRUE,"SEPT";#N/A,#N/A,TRUE,"3Q"}
Name aa: {#N/A,#N/A,TRUE,"KEY DATA";#N/A,#N/A,TRUE,"KEY DATA Base Case";#N/A,#N/A,TRUE,"JULY";#N/A,#N/A,TRUE,"AUG";#N/A,#N/A,TRUE,"SEPT";#N/A,#N/A,TRUE,"3Q"}
Name aaa: {#N/A,#N/A,TRUE,"Falcons_Standalone";#N/A,#N/A,TRUE,"Target_Input";#N/A,#N/A,TRUE,"Target_Calendarized"}
Name aaa.: {#N/A,#N/A,TRUE,"KEY DATA";#N/A,#N/A,TRUE,"KEY DATA Base Case";#N/A,#N/A,TRUE,"JULY";#N/A,#N/A,TRUE,"AUG";#N/A,#N/A,TRUE,"SEPT";#N/A,#N/A,TRUE,"3Q"}
Name aaaaaaa: {"Outflow 1",#N/A,FALSE,"Outflows-Inflows";"Outflow 2",#N/A,FALSE,"Outflows-Inflows";"Inflow 1",#N/A,FALSE,"Outflows-Inflows";"Inflow 2",#N/A,FALSE,"Outflows-Inflows"}
Name aaaasdf: {#N/A,#N/A,TRUE,"GEM Total";#N/A,#N/A,TRUE,"Final Assembly";#N/A,#N/A,TRUE,"Cleaning";#N/A,#N/A,TRUE,"Schooping,Clearing";#N/A,#N/A,TRUE,"Winding"}
Name aabb: {#N/A,#N/A,FALSE,"Projections";#N/A,#N/A,FALSE,"Multiples Valuation";#N/A,#N/A,FALSE,"LBO";#N/A,#N/A,FALSE,"Multiples_Sensitivity";#N/A,#N/A,FALSE,"Summary"}
Name aasda: {"PrintView",#N/A,FALSE,"Cash & Equiv";"PrintView",#N/A,FALSE,"Investments";"Other Assets Print View",#N/A,FALSE,"Other Assets"}
Name aasdfa: {"rtn",#N/A,FALSE,"RTN";"tables",#N/A,FALSE,"RTN";"cf",#N/A,FALSE,"CF";"stats",#N/A,FALSE,"Stats";"prop",#N/A,FALSE,"Prop"}
Name abcd: {"histincome",#N/A,FALSE,"hyfins";"closing balance",#N/A,FALSE,"hyfins"}
Name adfadf: {"histincome",#N/A,FALSE,"hyfins";"closing balance",#N/A,FALSE,"hyfins"}
Name adfda: {"histincome",#N/A,FALSE,"hyfins";"closing balance",#N/A,FALSE,"hyfins"}
Name adfdasfasd: {"histincome",#N/A,FALSE,"hyfins";"closing balance",#N/A,FALSE,"hyfins"}
Name adfj: {"bs",#N/A,FALSE,"SCF"}
Name adg: {"'Sheet1'!$A$1:$O$40"}
Name ads: {#N/A,#N/A,FALSE,"AD_Purch";#N/A,#N/A,FALSE,"Projections";#N/A,#N/A,FALSE,"DCF";#N/A,#N/A,FALSE,"Mkt Val"}

Sheet Detailed P&L
D1: =YEAR(D9) -> 2024 | E1: =YEAR(E9) -> 2024 | F1: =YEAR(F9) -> 2024 | G1: =YEAR(G9) -> 2024 | H1: =YEAR(H9) -> 2024 | I1: =YEAR(I9) -> 2024 | J1: =YEAR(J9) -> 2024 | K1: =YEAR(K9) -> 2024 | ... AI1: =YEAR(AI9) -> 2026 | AK1: =YEAR(AK9) -> 2026 | AL1: =YEAR(AL9) -> 2026 | AM1: =YEAR(AM9) -> 2026 | AN1: =YEAR(AN9) -> 2026 | AO1: =YEAR(AO9) -> 2027 | AP1: =YEAR(AP9) -> 2027 | AQ1: =YEAR(AQ9) -> 2027 | AR1: =YEAR(AR9) -> 2027 | ... BX1: =YEAR(BX9) -> 2029 | CC1: 1 | CD1: 2 | CE1: 3 | CM1: ATL
D2: =MONTH(D9) -> 1 | E2: =MONTH(E9) -> 2 | F2: =MONTH(F9) -> 3 | G2: =MONTH(G9) -> 4 | H2: =MONTH(H9) -> 5 | I2: =MONTH(I9) -> 6 | J2: =MONTH(J9) -> 7 | K2: =MONTH(K9) -> 8 | ... AI2: =MONTH(AI9) -> 8 | AK2: =MONTH(AK9) -> 9 | AL2: =MONTH(AL9) -> 10 | AM2: =MONTH(AM9) -> 11 | AN2: =MONTH(AN9) -> 12 | AO2: =MONTH(AO9) -> 1 | AP2: =MONTH(AP9) -> 2 | AQ2: =MONTH(AQ9) -> 3 | AR2: =MONTH(AR9) -> 4 | ... BX2: =MONTH(BX9) -> 12
W3: LTM | X3: LTM | Y3: LTM | Z3: LTM | AA3: LTM | AB3: LTM | AC3: LTM | AD3: LTM | AE3: LTM | AF3: LTM | AG3: LTM | AH3: LTM | AK3: 1 | AL3: =AK3 -> 1 | AM3: =AL3 -> 1 | AN3: =AM3 -> 1 | AO3: =AN3 -> 1 | AP3: =AO3 -> 1 | AQ3: =AP3 -> 1 | AR3: =AQ3 -> 1 | AS3: =AR3 -> 1 | ... AV3: =AU3 -> 1 | AW3: =AK3+1 -> 2 | AX3: =AL3+1 -> 2 | AY3: =AM3+1 -> 2 | AZ3: =AN3+1 -> 2 | BA3: =AO3+1 -> 2 | BB3: =AP3+1 -> 2 | BC3: =AQ3+1 -> 2 | BD3: =AR3+1 -> 2 | ... BX3: =BL3+1 -> 4
C5: =Summary!$C$3 -> Hadden Estate | CM5: =INDEX('FY25 By Venue Financials'!$1:$1,MATCH(CM1,'FY25 By Venue Financials'!$4:$4,0)) -> N
C6: PF P&L Analysis
D8: Historicals | P8: Historicals | AK8: Forecast | BZ8: Historicals | CC8: PF | CG8: PF Drivers | CK8: Current | CM8: WH Comparable Venue
D9: 45322 | E9: =EOMONTH(D9,1) -> 45351 | F9: =EOMONTH(E9,1) -> 45382 | G9: =EOMONTH(F9,1) -> 45412 | H9: =EOMONTH(G9,1) -> 45443 | I9: =EOMONTH(H9,1) -> 45473 | J9: =EOMONTH(I9,1) -> 45504 | K9: =EOMONTH(J9,1) -> 45535 | L9: =EOMONTH(K9,1) -> 45565 | ... AI9: =EOMONTH(AH9,1) -> 46265 | AK9: =EOMONTH(AI9,1) -> 46295 | AL9: =EOMONTH(AK9,1) -> 46326 | AM9: =EOMONTH(AL9,1) -> 46356 | AN9: =EOMONTH(AM9,1) -> 46387 | AO9: =EOMONTH(AN9,1) -> 46418 | AP9: =EOMONTH(AO9,1) -> 46446 | AQ9: =EOMONTH(AP9,1) -> 46477 | AR9: =EOMONTH(AQ9,1) -> 46507 | AS9: =EOMONTH(AR9,1) -> 46538 | ... BX9: =EOMONTH(BW9,1) -> 47483 | BZ9: 2024 | CA9: 2025 | CB9: ='Events Summary'!$C$12 -> LTM Jul-26 | CC9: Y1 | CD9: Y2 | CE9: Y3 | CG9: Y1 | CH9: Y2 | CI9: Y3 | CK9: % | CM9: $ | CN9: % | CP9: % Type | CQ9: Monthly Split | CR9: Historical / PF Comments
C11: Leads | AB11: =SUMIFS(Leads!$I$4:$I$10,Leads!$H$4:$H$10,AB$9) -> 67 | AC11: =SUMIFS(Leads!$I$4:$I$10,Leads!$H$4:$H$10,AC$9) -> 30 | AD11: =SUMIFS(Leads!$I$4:$I$10,Leads!$H$4:$H$10,AD$9) -> 29 | AE11: =SUMIFS(Leads!$I$4:$I$10,Leads!$H$4:$H$10,AE$9) -> 53 | AF11: =SUMIFS(Leads!$I$4:$I$10,Leads!$H$4:$H$10,AF$9) -> 45 | AG11: =SUMIFS(Leads!$I$4:$I$10,Leads!$H$4:$H$10,AG$9) -> 43 | AH11: =SUMIFS(Leads!$I$4:$I$10,Leads!$H$4:$H$10,AH$9) -> 38 | AI11: 85 | AK11: 90 | AL11: 115 | AM11: 110 | AN11: 110 | AO11: 175 | AP11: =($CC$11-SUM($AK$11:$AO$11))*(AP91/SUM($AP$91:$AV$91)) -> 142.10526 | AQ11: =($CC$11-SUM($AK$11:$AO$11))*(AQ91/SUM($AP$91:$AV$91)) -> 126.31579 | AR11: =($CC$11-SUM($AK$11:$AO$11))*(AR91/SUM($AP$91:$AV$91)) -> 126.31579 | AS11: =($CC$11-SUM($AK$11:$AO$11))*(AS91/SUM($AP$91:$AV$91)) -> 126.31579 | AT11: =($CC$11-SUM($AK$11:$AO$11))*(AT91/SUM($AP$91:$AV$91)) -> 126.31579 | AU11: =($CC$11-SUM($AK$11:$AO$11))*(AU91/SUM($AP$91:$AV$91)) -> 126.31579 | AV11: =($CC$11-SUM($AK$11:$AO$11))*(AV91/SUM($AP$91:$AV$91)) -> 126.31579 | AW11: =ROUND(SUMIFS($CC11:$CE11,$CC$1:$CE$1,AW$3)*AW$91,0) -> 140 | AX11: =ROUND(SUMIFS($CC11:$CE11,$CC$1:$CE$1,AX$3)*AX$91,0) -> 140 | AY11: =ROUND(SUMIFS($CC11:$CE11,$CC$1:$CE$1,AY$3)*AY$91,0) -> 123 | AZ11: =ROUND(SUMIFS($CC11:$CE11,$CC$1:$CE$1,AZ$3)*AZ$91,0) -> 123 | BA11: 226 | BB11: =ROUND(SUMIFS($CC11:$CE11,$CC$1:$CE$1,BB$3)*BB$91,0) -> 158 | BC11: =ROUND(SUMIFS($CC11:$CE11,$CC$1:$CE$1,BC$3)*BC$91,0) -> 140 | BD11: =ROUND(SUMIFS($CC11:$CE11,$CC$1:$CE$1,BD$3)*BD$91,0) -> 140 | BE11: =ROUND(SUMIFS($CC11:$CE11,$CC$1:$CE$1,BE$3)*BE$91,0) -> 140 | BF11: =ROUND(SUMIFS($CC11:$CE11,$CC$1:$CE$1,BF$3)*BF$91,0) -> 140 | BG11: =ROUND(SUMIFS($CC11:$CE11,$CC$1:$CE$1,BG$3)*BG$91,0) -> 140 | BH11: =ROUND(SUMIFS($CC11:$CE11,$CC$1:$CE$1,BH$3)*BH$91,0) -> 140 | BI11: =ROUND(SUMIFS($CC11:$CE11,$CC$1:$CE$1,BI$3)*BI$91,0) -> 160 | ... BT11: =ROUND(SUMIFS($CC11:$CE11,$CC$1:$CE$1,BT$3)*BT$91,0) -> 160 | BU11: =BI11 -> 160 | BV11: =BJ11 -> 160 | BW11: =BK11 -> 140 | BX11: =BL11 -> 140 | CC11: 1500 | CD11: 1750 | CE11: 2000
C13: L->T Conversion | AB13: =AB15/AB11 -> 0.029850746 | AC13: =AC15/AC11 -> 0.1 | AD13: =AD15/AD11 -> 0.20689655 | AE13: =AE15/AE11 -> 0.056603774 | AF13: =AF15/AF11 -> 0.22222222 | AG13: =AG15/AG11 -> 0.11627907 | AH13: =AH15/AH11 -> 0.31578947 | AK13: =AK15/AK11 -> 0.16666667 | AL13: =AL15/AL11 -> 0.13043478 | AM13: =AM15/AM11 -> 0.17272727 | AN13: =AN15/AN11 -> 0.24545455 | AO13: =AO15/AO11 -> 0.31428571 | AP13: =AP15/AP11 -> 0.21814815 | AQ13: =AQ15/AQ11 -> 0.21375 | AR13: =AR15/AR11 -> 0.18208333 | ... BX13: =BX15/BX11 -> 0.28571429 | CC13: =CC15/CC11 -> 0.2 | CD13: =CD15/CD11 -> 0.2 | CE13: =CE15/CE11 -> 0.2
C15: Tours | AB15: =SUMIFS(Tours!$G$3:$G$9,Tours!$F$3:$F$9,AB$9) -> 2 | AC15: =SUMIFS(Tours!$G$3:$G$9,Tours!$F$3:$F$9,AC$9) -> 3 | AD15: =SUMIFS(Tours!$G$3:$G$9,Tours!$F$3:$F$9,AD$9) -> 6 | AE15: =SUMIFS(Tours!$G$3:$G$9,Tours!$F$3:$F$9,AE$9) -> 3 | AF15: =SUMIFS(Tours!$G$3:$G$9,Tours!$F$3:$F$9,AF$9) -> 10 | AG15: =SUMIFS(Tours!$G$3:$G$9,Tours!$F$3:$F$9,AG$9) -> 5 | AH15: =SUMIFS(Tours!$G$3:$G$9,Tours!$F$3:$F$9,AH$9) -> 12 | AI15: 9 | AK15: 15 | AL15: 15 | AM15: 19 | AN15: 27 | AO15: 55 | AP15: 31 | AQ15: 27 | AR15: 23 | AS15: 19 | AT15: 23 | AU15: 23 | AV15: 23 | AW15: =ROUND(SUMIFS($CC15:$CE15,$CC$1:$CE$1,AW$3)*AW$92,0) -> 30 | AX15: =ROUND(SUMIFS($CC15:$CE15,$CC$1:$CE$1,AX$3)*AX$92,0) -> 30 | AY15: =ROUND(SUMIFS($CC15:$CE15,$CC$1:$CE$1,AY$3)*AY$92,0) -> 33 | AZ15: =ROUND(SUMIFS($CC15:$CE15,$CC$1:$CE$1,AZ$3)*AZ$92,0) -> 35 | BA15: =ROUND(SUMIFS($CC15:$CE15,$CC$1:$CE$1,BA$3)*BA$92,0) -> 41 | BB15: =ROUND(SUMIFS($CC15:$CE15,$CC$1:$CE$1,BB$3)*BB$92,0) -> 29 | BC15: =ROUND(SUMIFS($CC15:$CE15,$CC$1:$CE$1,BC$3)*BC$92,0) -> 27 | BD15: 23 | BE15: 21 | BF15: =ROUND(SUMIFS($CC15:$CE15,$CC$1:$CE$1,BF$3)*BF$92,0) -> 25 | BG15: =ROUND(SUMIFS($CC15:$CE15,$CC$1:$CE$1,BG$3)*BG$92,0) -> 30 | BH15: =ROUND(SUMIFS($CC15:$CE15,$CC$1:$CE$1,BH$3)*BH$92,0) -> 26 | BI15: =ROUND(SUMIFS($CC15:$CE15,$CC$1:$CE$1,BI$3)*BI$92,0) -> 34 | BJ15: =ROUND(SUMIFS($CC15:$CE15,$CC$1:$CE$1,BJ$3)*BJ$92,0) -> 34 | BK15: =ROUND(SUMIFS($CC15:$CE15,$CC$1:$CE$1,BK$3)*BK$92,0) -> 38 | BL15: =ROUND(SUMIFS($CC15:$CE15,$CC$1:$CE$1,BL$3)*BL$92,0) -> 40 | BM15: =ROUND(SUMIFS($CC15:$CE15,$CC$1:$CE$1,BM$3)*BM$92,0) -> 47 | ... BP15: =ROUND(SUMIFS($CC15:$CE15,$CC$1:$CE$1,BP$3)*BP$92,0) -> 27 | BQ15: 24 | BR15: =ROUND(SUMIFS($CC15:$CE15,$CC$1:$CE$1,BR$3)*BR$92,0) -> 28 | BS15: =ROUND(SUMIFS($CC15:$CE15,$CC$1:$CE$1,BS$3)*BS$92,0) -> 34 | BT15: =ROUND(SUMIFS($CC15:$CE15,$CC$1:$CE$1,BT$3)*BT$92,0) -> 30 | BU15: =BI15 -> 34 | BV15: =BJ15 -> 34 | BW15: =BK15 -> 38 | BX15: =BL15 -> 40 | CC15: 300 | CD15: 350 | CE15: 400
C17: T->C Conversion | AK17: =AK19/AK15 -> 0.33333333 | AL17: =AL19/AL15 -> 0.33333333 | AM17: =AM19/AM15 -> 0.26315789 | AN17: =AN19/AN15 -> 0.25925926 | AO17: =AO19/AO15 -> 0.25454545 | AP17: =AP19/AP15 -> 0.25806452 | AQ17: =AQ19/AQ15 -> 0.25925926 | AR17: =AR19/AR15 -> 0.26086957 | ... BX17: =BX19/BX15 -> 0.25 | CC17: =CC19/CC15 -> 0.26666667 | CD17: =CD19/CD15 -> 0.25714286 | CE17: =CE19/CE15 -> 0.25
C19: Contracts | D19: 0 | E19: 0 | F19: 0 | G19: 0 | H19: 0 | I19: 0 | J19: 0 | K19: 0 | L19: 0 | M19: 0 | N19: 0 | O19: 0 | P19: 0 | Q19: 0 | R19: 0 | S19: 0 | T19: 0 | U19: 0 | V19: 0 | W19: 0 | X19: 0 | Y19: 0 | Z19: 0 | AA19: 0 | AB19: 0 | AC19: 0 | AD19: 0 | AE19: 0 | AF19: 0 | AG19: 0 | AH19: 0 | AI19: 5 | AK19: 5 | AL19: 5 | AM19: 5 | AN19: 7 | AO19: 14 | AP19: 8 | AQ19: 7 | AR19: 6 | AS19: 5 | AT19: 6 | AU19: 6 | AV19: 6 | AW19: 5 | AX19: =ROUND(SUMIFS($CC19:$CE19,$CC$1:$CE$1,AX$3)*AX$93,0) -> 8 | AY19: =ROUND(SUMIFS($CC19:$CE19,$CC$1:$CE$1,AY$3)*AY$93,0) -> 6 | AZ19: =ROUND(SUMIFS($CC19:$CE19,$CC$1:$CE$1,AZ$3)*AZ$93,0) -> 9 | BA19: =ROUND(SUMIFS($CC19:$CE19,$CC$1:$CE$1,BA$3)*BA$93,0) -> 11 | BB19: =ROUND(SUMIFS($CC19:$CE19,$CC$1:$CE$1,BB$3)*BB$93,0) -> 9 | BC19: =ROUND(SUMIFS($CC19:$CE19,$CC$1:$CE$1,BC$3)*BC$93,0) -> 8 | BD19: =ROUND(SUMIFS($CC19:$CE19,$CC$1:$CE$1,BD$3)*BD$93,0) -> 7 | BE19: =ROUND(SUMIFS($CC19:$CE19,$CC$1:$CE$1,BE$3)*BE$93,0) -> 6 | ... BP19: =ROUND(SUMIFS($CC19:$CE19,$CC$1:$CE$1,BP$3)*BP$93,0) -> 8 | BQ19: 7 | BR19: =ROUND(SUMIFS($CC19:$CE19,$CC$1:$CE$1,BR$3)*BR$93,0) -> 7 | BS19: =ROUND(SUMIFS($CC19:$CE19,$CC$1:$CE$1,BS$3)*BS$93,0) -> 7 | BT19: =ROUND(SUMIFS($CC19:$CE19,$CC$1:$CE$1,BT$3)*BT$93,0) -> 8 | BU19: =BI19 -> 7 | BV19: =BJ19 -> 9 | BW19: =BK19 -> 7 | BX19: =BL19 -> 10 | CC19: 80 | CD19: 90 | CE19: 100
C21: Original | D21: =SUMIFS('Events Summary'!$P:$P,'Events Summary'!$C:$C,D$9) -> 0 | E21: =SUMIFS('Events Summary'!$P:$P,'Events Summary'!$C:$C,E$9) -> 3 | F21: =SUMIFS('Events Summary'!$P:$P,'Events Summary'!$C:$C,F$9) -> 5 | G21: =SUMIFS('Events Summary'!$P:$P,'Events Summary'!$C:$C,G$9) -> 4 | H21: =SUMIFS('Events Summary'!$P:$P,'Events Summary'!$C:$C,H$9) -> 8 | I21: =SUMIFS('Events Summary'!$P:$P,'Events Summary'!$C:$C,I$9) -> 6 | J21: =SUMIFS('Events Summary'!$P:$P,'Events Summary'!$C:$C,J$9) -> 1 | K21: =SUMIFS('Events Summary'!$P:$P,'Events Summary'!$C:$C,K$9) -> 0 | ... AI21: =SUMIFS('Events Summary'!$P:$P,'Events Summary'!$C:$C,AI$9) -> 7 | AK21: =SUMIFS('Events Summary'!$P:$P,'Events Summary'!$C:$C,AK$9) -> 6 | AL21: =SUMIFS('Events Summary'!$P:$P,'Events Summary'!$C:$C,AL$9) -> 6 | AM21: =SUMIFS('Events Summary'!$P:$P,'Events Summary'!$C:$C,AM$9) -> 2 | AN21: =SUMIFS('Events Summary'!$P:$P,'Events Summary'!$C:$C,AN$9) -> 0 | AO21: =SUMIFS('Events Summary'!$P:$P,'Events Summary'!$C:$C,AO$9) -> 0 | AP21: =SUMIFS('Events Summary'!$P:$P,'Events Summary'!$C:$C,AP$9) -> 0 | AQ21: =SUMIFS('Events Summary'!$P:$P,'Events Summary'!$C:$C,AQ$9) -> 1 | AR21: =SUMIFS('Events Summary'!$P:$P,'Events Summary'!$C:$C,AR$9) -> 2 | ... BX21: =SUMIFS('Events Summary'!$P:$P,'Events Summary'!$C:$C,BX$9) -> 0 | BZ21: ='Revenue Analysis'!D11 -> 42 | CA21: ='Revenue Analysis'!E11 -> 43 | CB21: ='Revenue Analysis'!F11 -> 39 | CC21: ='Revenue Analysis'!G11 -> 24 | CD21: ='Revenue Analysis'!H11 -> 1 | CE21: ='Revenue Analysis'!I11 -> 0
C22: New | AK22: 0 | AL22: 0 | AM22: 0 | AN22: 2 | AO22: 0 | AP22: 0 | AQ22: 0 | AR22: 2 | AS22: 4 | AT22: 2 | AU22: 2 | AV22: 4 | AW22: =AW23-AW21 -> 6 | AX22: =AX23-AX21 -> 6 | AY22: =AY23-AY21 -> 6 | AZ22: =AZ23-AZ21 -> 5 | BA22: =BA23-BA21 -> 3 | BB22: =BB23-BB21 -> 4 | BC22: =BC23-BC21 -> 5 | BD22: =BD23-BD21 -> 5 | ... BX22: =BX23-BX21 -> 6 | BZ22: ='Revenue Analysis'!D12 -> 0 | CA22: ='Revenue Analysis'!E12 -> 0 | CB22: ='Revenue Analysis'!F12 -> 0 | CC22: ='Revenue Analysis'!G12 -> 16 | CD22: ='Revenue Analysis'!H12 -> 64 | CE22: ='Revenue Analysis'!I12 -> 80
C23: Events | D23: =SUM(D21:D22) -> 0 | E23: =SUM(E21:E22) -> 3 | F23: =SUM(F21:F22) -> 5 | G23: =SUM(G21:G22) -> 4 | H23: =SUM(H21:H22) -> 8 | I23: =SUM(I21:I22) -> 6 | J23: =SUM(J21:J22) -> 1 | K23: =SUM(K21:K22) -> 0 | ... AI23: =SUM(AI21:AI22) -> 7 | AK23: =AK21+AK22 -> 6 | AL23: =AL21+AL22 -> 6 | AM23: =AM21+AM22 -> 2 | AN23: =AN21+AN22 -> 2 | AO23: =AO21+AO22 -> 0 | AP23: =AP21+AP22 -> 0 | AQ23: =SUM(AQ21:AQ22) -> 1 | AR23: =SUM(AR21:AR22) -> 4 | AS23: =SUM(AS21:AS22) -> 8 | AT23: =SUM(AT21:AT22) -> 5 | AU23: =SUM(AU21:AU22) -> 2 | AV23: =SUM(AV21:AV22) -> 4 | AW23: =ROUND(AW$94*SUMIFS($CC23:$CE23,$CC$1:$CE$1,AW$3),0) -> 6 | AX23: =ROUND(AX$94*SUMIFS($CC23:$CE23,$CC$1:$CE$1,AX$3),0) -> 7 | AY23: =ROUND(AY$94*SUMIFS($CC23:$CE23,$CC$1:$CE$1,AY$3),0) -> 6 | AZ23: =ROUND(AZ$94*SUMIFS($CC23:$CE23,$CC$1:$CE$1,AZ$3),0) -> 5 | BA23: =ROUND(BA$94*SUMIFS($CC23:$CE23,$CC$1:$CE$1,BA$3),0) -> 3 | BB23: =ROUND(BB$94*SUMIFS($CC23:$CE23,$CC$1:$CE$1,BB$3),0) -> 4 | BC23: =ROUND(BC$94*SUMIFS($CC23:$CE23,$CC$1:$CE$1,BC$3),0) -> 5 | BD23: =ROUND(BD$94*SUMIFS($CC23:$CE23,$CC$1:$CE$1,BD$3),0) -> 5 | BE23: 8 | BF23: =ROUND(BF$94*SUMIFS($CC23:$CE23,$CC$1:$CE$1,BF$3),0) -> 6 | BG23: =ROUND(BG$94*SUMIFS($CC23:$CE23,$CC$1:$CE$1,BG$3),0) -> 5 | BH23: =ROUND(BH$94*SUMIFS($CC23:$CE23,$CC$1:$CE$1,BH$3),0) -> 5 | BI23: =ROUND(BI$94*SUMIFS($CC23:$CE23,$CC$1:$CE$1,BI$3),0) -> 8 | BJ23: =ROUND(BJ$94*SUMIFS($CC23:$CE23,$CC$1:$CE$1,BJ$3),0) -> 9 | BK23: =ROUND(BK$94*SUMIFS($CC23:$CE23,$CC$1:$CE$1,BK$3),0) -> 8 | BL23: =ROUND(BL$94*SUMIFS($CC23:$CE23,$CC$1:$CE$1,BL$3),0) -> 6 | BM23: =ROUND(BM$94*SUMIFS($CC23:$CE23,$CC$1:$CE$1,BM$3),0) -> 4 | ... BP23: =ROUND(BP$94*SUMIFS($CC23:$CE23,$CC$1:$CE$1,BP$3),0) -> 6 | BQ23: 8 | BR23: =ROUND(BR$94*SUMIFS($CC23:$CE23,$CC$1:$CE$1,BR$3),0) -> 8 | BS23: =ROUND(BS$94*SUMIFS($CC23:$CE23,$CC$1:$CE$1,BS$3),0) -> 6 | BT23: =ROUND(BT$94*SUMIFS($CC23:$CE23,$CC$1:$CE$1,BT$3),0) -> 6 | BU23: =BI23 -> 8 | BV23: =BJ23 -> 9 | BW23: =BK23 -> 8 | BX23: =BL23 -> 6 | BZ23: =SUM(BZ21:BZ22) -> 42 | CA23: =SUM(CA21:CA22) -> 43 | CB23: =SUM(CB21:CB22) -> 39 | CC23: =SUM(CC21:CC22) -> 40 | CD23: =SUM(CD21:CD22) -> 65 | CE23: =SUM(CE21:CE22) -> 80 | CK23: =CB23 -> 39 | CM23: ='Revenue Analysis'!$Q$13 -> 245
C24: % of Annual Events | AK24: =AK23/SUMIFS($CC$23:$CE$23,$CC$1:$CE$1,AK$3) -> 0.15 | AL24: =AL23/SUMIFS($CC$23:$CE$23,$CC$1:$CE$1,AL$3) -> 0.15 | AM24: =AM23/SUMIFS($CC$23:$CE$23,$CC$1:$CE$1,AM$3) -> 0.05 | AN24: =AN23/SUMIFS($CC$23:$CE$23,$CC$1:$CE$1,AN$3) -> 0.05 | AO24: =AO23/SUMIFS($CC$23:$CE$23,$CC$1:$CE$1,AO$3) -> 0 | AP24: =AP23/SUMIFS($CC$23:$CE$23,$CC$1:$CE$1,AP$3) -> 0 | AQ24: =AQ23/SUMIFS($CC$23:$CE$23,$CC$1:$CE$1,AQ$3) -> 0.025 | AR24: =AR23/SUMIFS($CC$23:$CE$23,$CC$1:$CE$1,AR$3) -> 0.1 | ... BT24: =BT23/SUMIFS($CC$23:$CE$23,$CC$1:$CE$1,BT$3) -> 0.075 | CC24: =SUM(AK23:AV23)-CC23 -> 0
AK25: =AK94 -> 0.097389487 | AL25: =AL94 -> 0.11295986 | AM25: =AM94 -> 0.099464075 | AN25: =AN94 -> 0.079707106 | AO25: =AO94 -> 0.044982847 | AP25: =AP94 -> 0.058016636 | AQ25: =AQ94 -> 0.078703584 | AR25: =AR94 -> 0.078777127 | ... BX25: =BX94 -> 0.079707106
C26: Revenue
C27: Room Rental Revenue | D27: =INDEX('Events Summary'!$E:$E,MATCH(D$9,'Events Summary'!$C:$C,0))/1000 -> 0 | E27: =INDEX('Events Summary'!$E:$E,MATCH(E$9,'Events Summary'!$C:$C,0))/1000 -> 12.12665 | F27: =INDEX('Events Summary'!$E:$E,MATCH(F$9,'Events Summary'!$C:$C,0))/1000 -> 50.2 | G27: =INDEX('Events Summary'!$E:$E,MATCH(G$9,'Events Summary'!$C:$C,0))/1000 -> 58.6 | H27: =INDEX('Events Summary'!$E:$E,MATCH(H$9,'Events Summary'!$C:$C,0))/1000 -> 52.982 | I27: =INDEX('Events Summary'!$E:$E,MATCH(I$9,'Events Summary'!$C:$C,0))/1000 -> 82 | J27: =INDEX('Events Summary'!$E:$E,MATCH(J$9,'Events Summary'!$C:$C,0))/1000 -> 14 | K27: =INDEX('Events Summary'!$E:$E,MATCH(K$9,'Events Summary'!$C:$C,0))/1000 -> 0 | ... AH27: =INDEX('Events Summary'!$E:$E,MATCH(AH$9,'Events Summary'!$C:$C,0))/1000 -> 18 | AK27: =SUMIFS($CC27:$CE27,$CC$1:$CE$1,AK$3)*AK$24 -> 109.19594 | AL27: =SUMIFS($CC27:$CE27,$CC$1:$CE$1,AL$3)*AL$24 -> 109.19594 | AM27: =SUMIFS($CC27:$CE27,$CC$1:$CE$1,AM$3)*AM$24 -> 36.398648 | AN27: =SUMIFS($CC27:$CE27,$CC$1:$CE$1,AN$3)*AN$24 -> 36.398648 | AO27: =SUMIFS($CC27:$CE27,$CC$1:$CE$1,AO$3)*AO$24 -> 0 | AP27: =SUMIFS($CC27:$CE27,$CC$1:$CE$1,AP$3)*AP$24 -> 0 | AQ27: =SUMIFS($CC27:$CE27,$CC$1:$CE$1,AQ$3)*AQ$24 -> 18.199324 | AR27: =SUMIFS($CC27:$CE27,$CC$1:$CE$1,AR$3)*AR$24 -> 72.797295 | ... BT27: =SUMIFS($CC27:$CE27,$CC$1:$CE$1,BT$3)*BT$24 -> 90.983607 | BU27: =BI27 -> 121.31148 | BV27: =BJ27 -> 136.47541 | BW27: =BK27 -> 121.31148 | BX27: =BL27 -> 90.983607 | BZ27: =SUMIFS($D27:$AJ27,$D$1:$AJ$1,BZ$9) -> 352.75965 | CA27: =SUMIFS($D27:$AJ27,$D$1:$AJ$1,CA$9) -> 319.97463 | CB27: =SUMIFS($D27:$AJ27,$D$3:$AJ$3,"LTM") -> 452.64363 | CC27: ='Revenue Analysis'!G60+'Revenue Analysis'!G75 -> 727.97295 | CD27: ='Revenue Analysis'!H60+'Revenue Analysis'!H75 -> 989.9918 | CE27: ='Revenue Analysis'!I60+'Revenue Analysis'!I75 -> 1213.1148 | CM27: =SUMIFS('FY25 By Venue Financials'!$N:$N,'FY25 By Venue Financials'!$A:$A,$C27) -> 1646.586
C28: Food Revenue | D28: 0 | E28: 0 | F28: 0 | G28: 0 | H28: 0 | I28: 0 | J28: 0 | K28: 0 | L28: 0 | M28: 0 | N28: 0 | O28: 0 | P28: 0 | Q28: 0 | R28: 0 | S28: 0 | T28: 0 | U28: 0 | V28: 0 | W28: 0 | X28: 0 | Y28: 0 | Z28: 0 | AA28: 0 | AB28: 0 | AC28: 0 | AD28: 0 | AE28: 0 | AF28: 0 | AG28: 0 | AH28: 0 | AK28: =SUMIFS($CC28:$CE28,$CC$1:$CE$1,AK$3)*AK$24 -> 0 | AL28: =SUMIFS($CC28:$CE28,$CC$1:$CE$1,AL$3)*AL$24 -> 0 | AM28: =SUMIFS($CC28:$CE28,$CC$1:$CE$1,AM$3)*AM$24 -> 0 | AN28: =SUMIFS($CC28:$CE28,$CC$1:$CE$1,AN$3)*AN$24 -> 0 | AO28: =SUMIFS($CC28:$CE28,$CC$1:$CE$1,AO$3)*AO$24 -> 0 | AP28: =SUMIFS($CC28:$CE28,$CC$1:$CE$1,AP$3)*AP$24 -> 0 | AQ28: =SUMIFS($CC28:$CE28,$CC$1:$CE$1,AQ$3)*AQ$24 -> 0 | AR28: =SUMIFS($CC28:$CE28,$CC$1:$CE$1,AR$3)*AR$24 -> 0 | ... BT28: =SUMIFS($CC28:$CE28,$CC$1:$CE$1,BT$3)*BT$24 -> 30.313996 | BU28: =BI28 -> 40.418662 | BV28: =BJ28 -> 45.470995 | BW28: =BK28 -> 40.418662 | BX28: =BL28 -> 30.313996 | BZ28: =SUMIFS($D28:$AJ28,$D$1:$AJ$1,BZ$9) -> 0 | CA28: =SUMIFS($D28:$AJ28,$D$1:$AJ$1,CA$9) -> 0 | CB28: =SUMIFS($D28:$AJ28,$D$3:$AJ$3,"LTM") -> 0 | CC28: ='Revenue Analysis'!G61+'Revenue Analysis'!G76 -> 0 | CD28: ='Revenue Analysis'!H61+'Revenue Analysis'!H76 -> 161.67465 | CE28: ='Revenue Analysis'!I61+'Revenue Analysis'!I76 -> 404.18662 | CM28: =SUMIFS('FY25 By Venue Financials'!$N:$N,'FY25 By Venue Financials'!$A:$A,$C28) -> 1731.7743
C29: Beverage Revenue | D29: 0 | E29: 0 | F29: 0 | G29: 0 | H29: 0 | I29: 0 | J29: 0 | K29: 0 | L29: 0 | M29: 0 | N29: 0 | O29: 0 | P29: 0 | Q29: 0 | R29: 0 | S29: 0 | T29: 0 | U29: 0 | V29: 0 | W29: 0 | X29: 0 | Y29: 0 | Z29: 0 | AA29: 0 | AB29: 0 | AC29: 0 | AD29: 0 | AE29: 0 | AF29: 0 | AG29: 0 | AH29: 0 | AK29: =SUMIFS($CC29:$CE29,$CC$1:$CE$1,AK$3)*AK$24 -> 0.9 | AL29: =SUMIFS($CC29:$CE29,$CC$1:$CE$1,AL$3)*AL$24 -> 0.9 | AM29: =SUMIFS($CC29:$CE29,$CC$1:$CE$1,AM$3)*AM$24 -> 0.3 | AN29: =SUMIFS($CC29:$CE29,$CC$1:$CE$1,AN$3)*AN$24 -> 0.3 | AO29: =SUMIFS($CC29:$CE29,$CC$1:$CE$1,AO$3)*AO$24 -> 0 | AP29: =SUMIFS($CC29:$CE29,$CC$1:$CE$1,AP$3)*AP$24 -> 0 | AQ29: =SUMIFS($CC29:$CE29,$CC$1:$CE$1,AQ$3)*AQ$24 -> 0.15 | AR29: =SUMIFS($CC29:$CE29,$CC$1:$CE$1,AR$3)*AR$24 -> 0.6 | ... BT29: =SUMIFS($CC29:$CE29,$CC$1:$CE$1,BT$3)*BT$24 -> 4.5 | BU29: =BI29 -> 6 | BV29: =BJ29 -> 6.75 | BW29: =BK29 -> 6 | BX29: =BL29 -> 4.5 | BZ29: =SUMIFS($D29:$AJ29,$D$1:$AJ$1,BZ$9) -> 0 | CA29: =SUMIFS($D29:$AJ29,$D$1:$AJ$1,CA$9) -> 0 | CB29: =SUMIFS($D29:$AJ29,$D$3:$AJ$3,"LTM") -> 0 | CC29: ='Revenue Analysis'!G62+'Revenue Analysis'!G77 -> 6 | CD29: ='Revenue Analysis'!H62+'Revenue Analysis'!H77 -> 36 | CE29: ='Revenue Analysis'!I62+'Revenue Analysis'!I77 -> 60 | CM29: =SUMIFS('FY25 By Venue Financials'!$N:$N,'FY25 By Venue Financials'!$A:$A,$C29) -> 980.4895
C30: Lodging Revenues | D30: =INDEX('Events Summary'!$I:$I,MATCH(D$9,'Events Summary'!$C:$C,0))/1000 -> 0 | E30: =INDEX('Events Summary'!$I:$I,MATCH(E$9,'Events Summary'!$C:$C,0))/1000 -> 4.8 | F30: =INDEX('Events Summary'!$I:$I,MATCH(F$9,'Events Summary'!$C:$C,0))/1000 -> 0 | G30: =INDEX('Events Summary'!$I:$I,MATCH(G$9,'Events Summary'!$C:$C,0))/1000 -> 10.3 | H30: =INDEX('Events Summary'!$I:$I,MATCH(H$9,'Events Summary'!$C:$C,0))/1000 -> 4.7 | I30: =INDEX('Events Summary'!$I:$I,MATCH(I$9,'Events Summary'!$C:$C,0))/1000 -> 3.8 | J30: =INDEX('Events Summary'!$I:$I,MATCH(J$9,'Events Summary'!$C:$C,0))/1000 -> 5.1 | K30: =INDEX('Events Summary'!$I:$I,MATCH(K$9,'Events Summary'!$C:$C,0))/1000 -> 0 | ... AH30: =INDEX('Events Summary'!$I:$I,MATCH(AH$9,'Events Summary'!$C:$C,0))/1000 -> 5.2 | AK30: =SUMIFS($CC30:$CE30,$CC$1:$CE$1,AK$3)*AK$24 -> 11.835 | AL30: =SUMIFS($CC30:$CE30,$CC$1:$CE$1,AL$3)*AL$24 -> 11.835 | AM30: =SUMIFS($CC30:$CE30,$CC$1:$CE$1,AM$3)*AM$24 -> 3.945 | AN30: =SUMIFS($CC30:$CE30,$CC$1:$CE$1,AN$3)*AN$24 -> 3.945 | AO30: =SUMIFS($CC30:$CE30,$CC$1:$CE$1,AO$3)*AO$24 -> 0 | AP30: =SUMIFS($CC30:$CE30,$CC$1:$CE$1,AP$3)*AP$24 -> 0 | AQ30: =SUMIFS($CC30:$CE30,$CC$1:$CE$1,AQ$3)*AQ$24 -> 1.9725 | AR30: =SUMIFS($CC30:$CE30,$CC$1:$CE$1,AR$3)*AR$24 -> 7.89 | ... BT30: =SUMIFS($CC30:$CE30,$CC$1:$CE$1,BT$3)*BT$24 -> 9 | BU30: =BI30 -> 12 | BV30: =BJ30 -> 13.5 | BW30: =BK30 -> 12 | BX30: =BL30 -> 9 | BZ30: =SUMIFS($D30:$AJ30,$D$1:$AJ$1,BZ$9) -> 41.26 | CA30: =SUMIFS($D30:$AJ30,$D$1:$AJ$1,CA$9) -> 67.8 | CB30: =SUMIFS($D30:$AJ30,$D$3:$AJ$3,"LTM") -> 69.8 | CC30: ='Revenue Analysis'!G63+'Revenue Analysis'!G78 -> 78.9 | CD30: ='Revenue Analysis'!H63+'Revenue Analysis'!H78 -> 96 | CE30: ='Revenue Analysis'!I63+'Revenue Analysis'!I78 -> 120 | CM30: =SUMIFS('FY25 By Venue Financials'!$N:$N,'FY25 By Venue Financials'!$A:$A,$C30) -> 0
C31: Ancillary Revenue | D31: =INDEX('Events Summary'!$M:$M,MATCH(D$9,'Events Summary'!$C:$C,0))/1000 -> 0 | E31: =INDEX('Events Summary'!$M:$M,MATCH(E$9,'Events Summary'!$C:$C,0))/1000 -> 1 | F31: =INDEX('Events Summary'!$M:$M,MATCH(F$9,'Events Summary'!$C:$C,0))/1000 -> 0 | G31: =INDEX('Events Summary'!$M:$M,MATCH(G$9,'Events Summary'!$C:$C,0))/1000 -> 3.929 | H31: =INDEX('Events Summary'!$M:$M,MATCH(H$9,'Events Summary'!$C:$C,0))/1000 -> 0.52 | I31: =INDEX('Events Summary'!$M:$M,MATCH(I$9,'Events Summary'!$C:$C,0))/1000 -> 1.248 | J31: =INDEX('Events Summary'!$M:$M,MATCH(J$9,'Events Summary'!$C:$C,0))/1000 -> 1.07967 | K31: =INDEX('Events Summary'!$M:$M,MATCH(K$9,'Events Summary'!$C:$C,0))/1000 -> 0 | ... AH31: =INDEX('Events Summary'!$M:$M,MATCH(AH$9,'Events Summary'!$C:$C,0))/1000 -> 0 | AK31: =SUMIFS($CC31:$CE31,$CC$1:$CE$1,AK$3)*AK$24 -> 2.9424495 | AL31: =SUMIFS($CC31:$CE31,$CC$1:$CE$1,AL$3)*AL$24 -> 2.9424495 | AM31: =SUMIFS($CC31:$CE31,$CC$1:$CE$1,AM$3)*AM$24 -> 0.98081651 | AN31: =SUMIFS($CC31:$CE31,$CC$1:$CE$1,AN$3)*AN$24 -> 0.98081651 | AO31: =SUMIFS($CC31:$CE31,$CC$1:$CE$1,AO$3)*AO$24 -> 0 | AP31: =SUMIFS($CC31:$CE31,$CC$1:$CE$1,AP$3)*AP$24 -> 0 | AQ31: =SUMIFS($CC31:$CE31,$CC$1:$CE$1,AQ$3)*AQ$24 -> 0.49040826 | AR31: =SUMIFS($CC31:$CE31,$CC$1:$CE$1,AR$3)*AR$24 -> 1.961633 | ... BT31: =SUMIFS($CC31:$CE31,$CC$1:$CE$1,BT$3)*BT$24 -> 24.971406 | BU31: =BI31 -> 33.295208 | BV31: =BJ31 -> 37.457109 | BW31: =BK31 -> 33.295208 | BX31: =BL31 -> 24.971406 | BZ31: =SUMIFS($D31:$AJ31,$D$1:$AJ$1,BZ$9) -> 11.25867 | CA31: =SUMIFS($D31:$AJ31,$D$1:$AJ$1,CA$9) -> 15.29051 | CB31: =SUMIFS($D31:$AJ31,$D$3:$AJ$3,"LTM") -> 23.3665 | CC31: =SUM('Revenue Analysis'!G64:G69)+SUM('Revenue Analysis'!G79:G84) -> 19.61633 | CD31: =SUM('Revenue Analysis'!H64:H69)+SUM('Revenue Analysis'!H79:H84) -> 148.18495 | CE31: =SUM('Revenue Analysis'!I64:I69)+SUM('Revenue Analysis'!I79:I84) -> 332.95208 | CM31: =SUMIFS('FY25 By Venue Financials'!$N:$N,'FY25 By Venue Financials'!$A:$A,$C31) -> 1517.7478
C32: Service Charge | D32: 0 | E32: 0 | F32: 0 | G32: 0 | H32: 0 | I32: 0 | J32: 0 | K32: 0 | L32: 0 | M32: 0 | N32: 0 | O32: 0 | P32: 0 | Q32: 0 | R32: 0 | S32: 0 | T32: 0 | U32: 0 | V32: 0 | W32: 0 | X32: 0 | Y32: 0 | Z32: 0 | AA32: 0 | AB32: 0 | AC32: 0 | AD32: 0 | AE32: 0 | AF32: 0 | AG32: 0 | AH32: 0 | AK32: =SUMIFS($CC32:$CE32,$CC$1:$CE$1,AK$3)*AK$24 -> 9.4409463 | AL32: =SUMIFS($CC32:$CE32,$CC$1:$CE$1,AL$3)*AL$24 -> 9.4409463 | AM32: =SUMIFS($CC32:$CE32,$CC$1:$CE$1,AM$3)*AM$24 -> 3.1469821 | AN32: =SUMIFS($CC32:$CE32,$CC$1:$CE$1,AN$3)*AN$24 -> 3.1469821 | AO32: =SUMIFS($CC32:$CE32,$CC$1:$CE$1,AO$3)*AO$24 -> 0 | AP32: =SUMIFS($CC32:$CE32,$CC$1:$CE$1,AP$3)*AP$24 -> 0 | AQ32: =SUMIFS($CC32:$CE32,$CC$1:$CE$1,AQ$3)*AQ$24 -> 1.573491 | AR32: =SUMIFS($CC32:$CE32,$CC$1:$CE$1,AR$3)*AR$24 -> 6.2939642 | ... BT32: =SUMIFS($CC32:$CE32,$CC$1:$CE$1,BT$3)*BT$24 -> 35.149182 | BU32: =BI32 -> 46.865576 | BV32: =BJ32 -> 52.723773 | BW32: =BK32 -> 46.865576 | BX32: =BL32 -> 35.149182 | BZ32: =SUMIFS($D32:$AJ32,$D$1:$AJ$1,BZ$9) -> 0 | CA32: =SUMIFS($D32:$AJ32,$D$1:$AJ$1,CA$9) -> 0 | CB32: =SUMIFS($D32:$AJ32,$D$3:$AJ$3,"LTM") -> 0 | CC32: ='Revenue Analysis'!G85 -> 62.939642 | CD32: ='Revenue Analysis'!H85 -> 310.71731 | CE32: ='Revenue Analysis'!I85 -> 468.65576 | CM32: =SUMIFS('FY25 By Venue Financials'!$N:$N,'FY25 By Venue Financials'!$A:$A,$C32) -> 1209.2074
C33: Cancelled Events | D33: 0 | E33: 0 | F33: 0 | G33: 0 | H33: 0 | I33: 0 | J33: 0 | K33: 0 | L33: 0 | M33: 0 | N33: 0 | O33: 0 | P33: 0 | Q33: 0 | R33: 0 | S33: 0 | T33: 0 | U33: 0 | V33: 0 | W33: 0 | X33: 0 | Y33: 0 | Z33: 0 | AA33: 0 | AB33: 0 | AC33: 0 | AD33: 0 | AE33: 0 | AF33: 0 | AG33: 0 | AH33: 0 | AK33: =SUMIFS($CC33:$CE33,$CC$1:$CE$1,AK$3)*AK$24 -> 2.3152501 | AL33: =SUMIFS($CC33:$CE33,$CC$1:$CE$1,AL$3)*AL$24 -> 2.3152501 | AM33: =SUMIFS($CC33:$CE33,$CC$1:$CE$1,AM$3)*AM$24 -> 0.77175004 | AN33: =SUMIFS($CC33:$CE33,$CC$1:$CE$1,AN$3)*AN$24 -> 0.77175004 | AO33: =SUMIFS($CC33:$CE33,$CC$1:$CE$1,AO$3)*AO$24 -> 0 | AP33: =SUMIFS($CC33:$CE33,$CC$1:$CE$1,AP$3)*AP$24 -> 0 | AQ33: =SUMIFS($CC33:$CE33,$CC$1:$CE$1,AQ$3)*AQ$24 -> 0.38587502 | AR33: =SUMIFS($CC33:$CE33,$CC$1:$CE$1,AR$3)*AR$24 -> 1.5435001 | ... BT33: =SUMIFS($CC33:$CE33,$CC$1:$CE$1,BT$3)*BT$24 -> 3.3599121 | BU33: =BI33 -> 4.4798828 | BV33: =BJ33 -> 5.0398681 | BW33: =BK33 -> 4.4798828 | BX33: =BL33 -> 3.3599121 | BZ33: =SUMIFS($D33:$AJ33,$D$1:$AJ$1,BZ$9) -> 0 | CA33: =SUMIFS($D33:$AJ33,$D$1:$AJ$1,CA$9) -> 0 | CB33: =SUMIFS($D33:$AJ33,$D$3:$AJ$3,"LTM") -> 0 | CC33: =SUM(CC$27:CC$32)*CG33 -> 15.435001 | CD33: =SUM(CD$27:CD$32)*CH33 -> 30.037615 | CE33: =SUM(CE$27:CE$32)*CI33 -> 44.798828 | CG33: =$CN33 -> 0.01723755 | CH33: =$CN33 -> 0.01723755 | CI33: =$CN33 -> 0.01723755 | CK33: =IFERROR(CB33/CB4,0) -> 0 | CM33: =SUMIFS('FY25 By Venue Financials'!$N:$N,'FY25 By Venue Financials'!$A:$A,$C33) -> 122.14192 | CN33: =CM33/SUM($CM$27:$CM$32) -> 0.01723755 | CP33: % Total Rev | CQ33: % of Total Events | CR33: Avg ATL
C34: Outside Events | D34: 0 | E34: 0 | F34: 0 | G34: 0 | H34: 0 | I34: 0 | J34: 0 | K34: 0 | L34: 0 | M34: 0 | N34: 0 | O34: 0 | P34: 0 | Q34: 0 | R34: 0 | S34: 0 | T34: 0 | U34: 0 | V34: 0 | W34: 0 | X34: 0 | Y34: 0 | Z34: 0 | AA34: 0 | AB34: 0 | AC34: 0 | AD34: 0 | AE34: 0 | AF34: 0 | AG34: 0 | AH34: 0 | AK34: =SUMIFS($CC34:$CE34,$CC$1:$CE$1,AK$3)*AK$24 -> 0 | AL34: =SUMIFS($CC34:$CE34,$CC$1:$CE$1,AL$3)*AL$24 -> 0 | AM34: =SUMIFS($CC34:$CE34,$CC$1:$CE$1,AM$3)*AM$24 -> 0 | AN34: =SUMIFS($CC34:$CE34,$CC$1:$CE$1,AN$3)*AN$24 -> 0 | AO34: =SUMIFS($CC34:$CE34,$CC$1:$CE$1,AO$3)*AO$24 -> 0 | AP34: =SUMIFS($CC34:$CE34,$CC$1:$CE$1,AP$3)*AP$24 -> 0 | AQ34: =SUMIFS($CC34:$CE34,$CC$1:$CE$1,AQ$3)*AQ$24 -> 0 | AR34: =SUMIFS($CC34:$CE34,$CC$1:$CE$1,AR$3)*AR$24 -> 0 | ... BT34: =SUMIFS($CC34:$CE34,$CC$1:$CE$1,BT$3)*BT$24 -> 0 | BU34: =BI34 -> 0 | BV34: =BJ34 -> 0 | BW34: =BK34 -> 0 | BX34: =BL34 -> 0 | BZ34: =SUMIFS($D34:$AJ34,$D$1:$AJ$1,BZ$9) -> 0 | CA34: =SUMIFS($D34:$AJ34,$D$1:$AJ$1,CA$9) -> 0 | CB34: =SUMIFS($D34:$AJ34,$D$3:$AJ$3,"LTM") -> 0 | CC34: =SUM(CC$27:CC$32)*CG34 -> 0 | CD34: =SUM(CD$27:CD$32)*CH34 -> 0 | CE34: =SUM(CE$27:CE$32)*CI34 -> 0 | CG34: =$CN34 -> 0 | CH34: =$CN34 -> 0 | CI34: =$CN34 -> 0 | CK34: =IFERROR(CB34/CB5,0) -> 0 | CM34: =SUMIFS('FY25 By Venue Financials'!$N:$N,'FY25 By Venue Financials'!$A:$A,$C34) -> 0 | CN34: =CM34/SUM($CM$27:$CM$32) -> 0 | CP34: % Total Rev | CQ34: % of Total Events
C35: Discounts | D35: 0 | E35: 0 | F35: 0 | G35: 0 | H35: 0 | I35: 0 | J35: 0 | K35: 0 | L35: 0 | M35: 0 | N35: 0 | O35: 0 | P35: 0 | Q35: 0 | R35: 0 | S35: 0 | T35: 0 | U35: 0 | V35: 0 | W35: 0 | X35: 0 | Y35: 0 | Z35: 0 | AA35: 0 | AB35: 0 | AC35: 0 | AD35: 0 | AE35: 0 | AF35: 0 | AG35: 0 | AH35: 0 | AK35: =SUMIFS($CC35:$CE35,$CC$1:$CE$1,AK$3)*AK$24 -> -2.9288386 | AL35: =SUMIFS($CC35:$CE35,$CC$1:$CE$1,AL$3)*AL$24 -> -2.9288386 | AM35: =SUMIFS($CC35:$CE35,$CC$1:$CE$1,AM$3)*AM$24 -> -0.97627955 | AN35: =SUMIFS($CC35:$CE35,$CC$1:$CE$1,AN$3)*AN$24 -> -0.97627955 | AO35: =SUMIFS($CC35:$CE35,$CC$1:$CE$1,AO$3)*AO$24 -> 0 | AP35: =SUMIFS($CC35:$CE35,$CC$1:$CE$1,AP$3)*AP$24 -> 0 | AQ35: =SUMIFS($CC35:$CE35,$CC$1:$CE$1,AQ$3)*AQ$24 -> -0.48813977 | AR35: =SUMIFS($CC35:$CE35,$CC$1:$CE$1,AR$3)*AR$24 -> -1.9525591 | ... BT35: =SUMIFS($CC35:$CE35,$CC$1:$CE$1,BT$3)*BT$24 -> -4.2503573 | BU35: =BI35 -> -5.6671431 | BV35: =BJ35 -> -6.375536 | BW35: =BK35 -> -5.6671431 | BX35: =BL35 -> -4.2503573 | BZ35: =SUMIFS($D35:$AJ35,$D$1:$AJ$1,BZ$9) -> 0 | CA35: =SUMIFS($D35:$AJ35,$D$1:$AJ$1,CA$9) -> 0 | CB35: =SUMIFS($D35:$AJ35,$D$3:$AJ$3,"LTM") -> 0 | CC35: =SUM(CC$27:CC$32)*CG35 -> -19.525591 | CD35: =SUM(CD$27:CD$32)*CH35 -> -37.998196 | CE35: =SUM(CE$27:CE$32)*CI35 -> -56.671431 | CG35: =$CN35 -> -0.021805852 | CH35: =$CN35 -> -0.021805852 | CI35: =$CN35 -> -0.021805852 | CK35: =IFERROR(CB35/CB6,0) -> 0 | CM35: =SUMIFS('FY25 By Venue Financials'!$N:$N,'FY25 By Venue Financials'!$A:$A,$C35) -> -154.51202 | CN35: =CM35/SUM($CM$27:$CM$32) -> -0.021805852 | CP35: % Total Rev | CQ35: % of Total Events | CR35: Avg ATL
C36: Other Revenue | D36: =SUMIFS('P&L'!C:C,'P&L'!$A:$A,$C36)/1000 -> 0.38245 | E36: =SUMIFS('P&L'!D:D,'P&L'!$A:$A,$C36)/1000 -> 0 | F36: =SUMIFS('P&L'!E:E,'P&L'!$A:$A,$C36)/1000 -> 0 | G36: =SUMIFS('P&L'!F:F,'P&L'!$A:$A,$C36)/1000 -> 3.7616 | H36: =SUMIFS('P&L'!G:G,'P&L'!$A:$A,$C36)/1000 -> 14.6798 | I36: =SUMIFS('P&L'!H:H,'P&L'!$A:$A,$C36)/1000 -> 23.39819 | J36: =SUMIFS('P&L'!I:I,'P&L'!$A:$A,$C36)/1000 -> 3.091 | K36: =SUMIFS('P&L'!J:J,'P&L'!$A:$A,$C36)/1000 -> 0.836 | L36: =SUMIFS('P&L'!K:K,'P&L'!$A:$A,$C36)/1000 -> 3.907 | M36: =SUMIFS('P&L'!L:L,'P&L'!$A:$A,$C36)/1000 -> 1.738 | N36: =SUMIFS('P&L'!M:M,'P&L'!$A:$A,$C36)/1000 -> 7.5 | O36: =SUMIFS('P&L'!N:N,'P&L'!$A:$A,$C36)/1000 -> 1.892 | P36: =SUMIFS('P&L'!O:O,'P&L'!$A:$A,$C36)/1000 -> 2.625 | Q36: =SUMIFS('P&L'!P:P,'P&L'!$A:$A,$C36)/1000 -> 2.633 | R36: =SUMIFS('P&L'!Q:Q,'P&L'!$A:$A,$C36)/1000 -> 2.521 | S36: =SUMIFS('P&L'!R:R,'P&L'!$A:$A,$C36)/1000 -> 3.129 | T36: =SUMIFS('P&L'!S:S,'P&L'!$A:$A,$C36)/1000 -> 6.24116 | U36: =SUMIFS('P&L'!T:T,'P&L'!$A:$A,$C36)/1000 -> 15.96192 | V36: =SUMIFS('P&L'!U:U,'P&L'!$A:$A,$C36)/1000 -> 0.175 | W36: =SUMIFS('P&L'!V:V,'P&L'!$A:$A,$C36)/1000 -> 0 | X36: =SUMIFS('P&L'!W:W,'P&L'!$A:$A,$C36)/1000 -> 0 | Y36: =SUMIFS('P&L'!X:X,'P&L'!$A:$A,$C36)/1000 -> 0 | Z36: =SUMIFS('P&L'!Y:Y,'P&L'!$A:$A,$C36)/1000 -> 1.334 | AA36: =SUMIFS('P&L'!Z:Z,'P&L'!$A:$A,$C36)/1000 -> 0 | AB36: =SUMIFS('P&L'!AA:AA,'P&L'!$A:$A,$C36)/1000 -> 0 | AC36: =SUMIFS('P&L'!AB:AB,'P&L'!$A:$A,$C36)/1000 -> 0 | AD36: =SUMIFS('P&L'!AC:AC,'P&L'!$A:$A,$C36)/1000 -> 0 | AE36: =SUMIFS('P&L'!AD:AD,'P&L'!$A:$A,$C36)/1000 -> 0.15 | AF36: =SUMIFS('P&L'!AE:AE,'P&L'!$A:$A,$C36)/1000 -> 0 | AG36: =SUMIFS('P&L'!AF:AF,'P&L'!$A:$A,$C36)/1000 -> 11.17399 | AH36: =SUMIFS('P&L'!AG:AG,'P&L'!$A:$A,$C36)/1000 -> 2.38166 | AK36: =SUMIFS($CC36:$CE36,$CC$1:$CE$1,AK$3)*AK$24 -> 2.2559475 | AL36: =SUMIFS($CC36:$CE36,$CC$1:$CE$1,AL$3)*AL$24 -> 2.2559475 | AM36: =SUMIFS($CC36:$CE36,$CC$1:$CE$1,AM$3)*AM$24 -> 0.7519825 | AN36: =SUMIFS($CC36:$CE36,$CC$1:$CE$1,AN$3)*AN$24 -> 0.7519825 | AO36: =SUMIFS($CC36:$CE36,$CC$1:$CE$1,AO$3)*AO$24 -> 0 | AP36: =SUMIFS($CC36:$CE36,$CC$1:$CE$1,AP$3)*AP$24 -> 0 | AQ36: =SUMIFS($CC36:$CE36,$CC$1:$CE$1,AQ$3)*AQ$24 -> 0.37599125 | AR36: =SUMIFS($CC36:$CE36,$CC$1:$CE$1,AR$3)*AR$24 -> 1.503965 | ... BT36: =SUMIFS($CC36:$CE36,$CC$1:$CE$1,BT$3)*BT$24 -> 1.1279737 | BU36: =BI36 -> 1.503965 | BV36: =BJ36 -> 1.6919606 | BW36: =BK36 -> 1.503965 | BX36: =BL36 -> 1.1279737 | BZ36: =SUMIFS($D36:$AJ36,$D$1:$AJ$1,BZ$9) -> 61.18604 | CA36: =SUMIFS($D36:$AJ36,$D$1:$AJ$1,CA$9) -> 34.62008 | CB36: =SUMIFS($D36:$AJ36,$D$3:$AJ$3,"LTM") -> 15.03965 | CC36: =CB36 -> 15.03965 | CD36: =CC36 -> 15.03965 | CE36: =CD36 -> 15.03965 | CG36: =$CN36 -> 0 | CH36: =$CN36 -> 0 | CI36: =$CN36 -> 0 | CK36: =IFERROR(CB36/CB7,0) -> 0 | CM36: =SUMIFS('FY25 By Venue Financials'!$N:$N,'FY25 By Venue Financials'!$A:$A,$C36) -> 0 | CN36: =CM36/SUM($CM$27:$CM$32) -> 0 | CP36: % Total Rev | CQ36: % of Total Events | CR36: Blueberries, Pop Up events, merch
C38: Total Revenue | D38: =SUM(D27:D37) -> 0.38245 | E38: =SUM(E27:E37) -> 17.92665 | F38: =SUM(F27:F37) -> 50.2 | G38: =SUM(G27:G37) -> 76.5906 | H38: =SUM(H27:H37) -> 72.8818 | I38: =SUM(I27:I37) -> 110.44619 | J38: =SUM(J27:J37) -> 23.27067 | K38: =SUM(K27:K37) -> 0.836 | ... AH38: =SUM(AH27:AH37) -> 25.58166 | AK38: =SUM(AK27:AK37) -> 135.9567 | AL38: =SUM(AL27:AL37) -> 135.9567 | AM38: =SUM(AM27:AM37) -> 45.318899 | AN38: =SUM(AN27:AN37) -> 45.318899 | AO38: =SUM(AO27:AO37) -> 0 | AP38: =SUM(AP27:AP37) -> 0 | AQ38: =SUM(AQ27:AQ37) -> 22.65945 | AR38: =SUM(AR27:AR37) -> 90.637798 | ... BX38: =SUM(BX27:BX37) -> 195.15572 | BZ38: =SUM(BZ27:BZ37) -> 466.46436 | CA38: =SUM(CA27:CA37) -> 437.68522 | CB38: =SUM(CB27:CB37) -> 560.84978 | CC38: =SUM(CC27:CC37) -> 906.37798 | CD38: =SUM(CD27:CD37) -> 1749.6478 | CE38: =SUM(CE27:CE37) -> 2602.0763 | CM38: =SUM(CM27:CM37) -> 7053.435
C40: COGS
C41: Food COGS | D41: =-SUMIFS('P&L'!C:C,'P&L'!$A:$A,$C41)/1000 -> 0 | E41: =-SUMIFS('P&L'!D:D,'P&L'!$A:$A,$C41)/1000 -> 0 | F41: =-SUMIFS('P&L'!E:E,'P&L'!$A:$A,$C41)/1000 -> 0 | G41: =-SUMIFS('P&L'!F:F,'P&L'!$A:$A,$C41)/1000 -> 0 | H41: =-SUMIFS('P&L'!G:G,'P&L'!$A:$A,$C41)/1000 -> 0 | I41: =-SUMIFS('P&L'!H:H,'P&L'!$A:$A,$C41)/1000 -> 0 | J41: =-SUMIFS('P&L'!I:I,'P&L'!$A:$A,$C41)/1000 -> 0 | K41: =-SUMIFS('P&L'!J:J,'P&L'!$A:$A,$C41)/1000 -> 0 | L41: =-SUMIFS('P&L'!K:K,'P&L'!$A:$A,$C41)/1000 -> 0 | M41: =-SUMIFS('P&L'!L:L,'P&L'!$A:$A,$C41)/1000 -> 0 | N41: =-SUMIFS('P&L'!M:M,'P&L'!$A:$A,$C41)/1000 -> 0 | O41: =-SUMIFS('P&L'!N:N,'P&L'!$A:$A,$C41)/1000 -> 0 | P41: =-SUMIFS('P&L'!O:O,'P&L'!$A:$A,$C41)/1000 -> 0 | Q41: =-SUMIFS('P&L'!P:P,'P&L'!$A:$A,$C41)/1000 -> 0 | R41: =-SUMIFS('P&L'!Q:Q,'P&L'!$A:$A,$C41)/1000 -> 0 | S41: =-SUMIFS('P&L'!R:R,'P&L'!$A:$A,$C41)/1000 -> 0 | T41: =-SUMIFS('P&L'!S:S,'P&L'!$A:$A,$C41)/1000 -> 0 | U41: =-SUMIFS('P&L'!T:T,'P&L'!$A:$A,$C41)/1000 -> 0 | V41: =-SUMIFS('P&L'!U:U,'P&L'!$A:$A,$C41)/1000 -> 0 | W41: =-SUMIFS('P&L'!V:V,'P&L'!$A:$A,$C41)/1000 -> 0 | X41: =-SUMIFS('P&L'!W:W,'P&L'!$A:$A,$C41)/1000 -> 0 | Y41: =-SUMIFS('P&L'!X:X,'P&L'!$A:$A,$C41)/1000 -> 0 | Z41: =-SUMIFS('P&L'!Y:Y,'P&L'!$A:$A,$C41)/1000 -> 0 | AA41: =-SUMIFS('P&L'!Z:Z,'P&L'!$A:$A,$C41)/1000 -> 0 | AB41: =-SUMIFS('P&L'!AA:AA,'P&L'!$A:$A,$C41)/1000 -> 0 | AC41: =-SUMIFS('P&L'!AB:AB,'P&L'!$A:$A,$C41)/1000 -> 0 | AD41: =-SUMIFS('P&L'!AC:AC,'P&L'!$A:$A,$C41)/1000 -> 0 | AE41: =-SUMIFS('P&L'!AD:AD,'P&L'!$A:$A,$C41)/1000 -> 0 | AF41: =-SUMIFS('P&L'!AE:AE,'P&L'!$A:$A,$C41)/1000 -> 0 | AG41: =-SUMIFS('P&L'!AF:AF,'P&L'!$A:$A,$C41)/1000 -> 0 | AH41: =-SUMIFS('P&L'!AG:AG,'P&L'!$A:$A,$C41)/1000 -> 0 | AK41: =SUMIFS($CC41:$CE41,$CC$1:$CE$1,AK$3)*AK$24 -> 0 | AL41: =SUMIFS($CC41:$CE41,$CC$1:$CE$1,AL$3)*AL$24 -> 0 | AM41: =SUMIFS($CC41:$CE41,$CC$1:$CE$1,AM$3)*AM$24 -> 0 | AN41: =SUMIFS($CC41:$CE41,$CC$1:$CE$1,AN$3)*AN$24 -> 0 | AO41: =SUMIFS($CC41:$CE41,$CC$1:$CE$1,AO$3)*AO$24 -> 0 | AP41: =SUMIFS($CC41:$CE41,$CC$1:$CE$1,AP$3)*AP$24 -> 0 | AQ41: =SUMIFS($CC41:$CE41,$CC$1:$CE$1,AQ$3)*AQ$24 -> 0 | AR41: =SUMIFS($CC41:$CE41,$CC$1:$CE$1,AR$3)*AR$24 -> 0 | ... BT41: =SUMIFS($CC41:$CE41,$CC$1:$CE$1,BT$3)*BT$24 -> -5.018836 | BU41: =BI41 -> -6.6917813 | BV41: =BJ41 -> -7.528254 | BW41: =BK41 -> -6.6917813 | BX41: =BL41 -> -5.018836 | BZ41: =SUMIFS($D41:$AJ41,$D$1:$AJ$1,BZ$9) -> 0 | CA41: =SUMIFS($D41:$AJ41,$D$1:$AJ$1,CA$9) -> 0 | CB41: =SUMIFS($D41:$AJ41,$D$3:$AJ$3,"LTM") -> 0 | CC41: =CC28*CG41 -> 0 | CD41: =CD28*CH41 -> -26.767125 | CE41: =CE28*CI41 -> -66.917813 | CG41: =$CN41 -> -0.16556167 | CH41: =$CN41 -> -0.16556167 | CI41: =$CN41 -> -0.16556167 | CK41: =IFERROR(CB41/CB28,0) -> 0 | CM41: =-SUMIFS('FY25 By Venue Financials'!$N:$N,'FY25 By Venue Financials'!$A:$A,$C41) -> -286.71546 | CN41: =IFERROR(CM41/CM28,0) -> -0.16556167 | CP41: % Food Rev | CQ41: % of Total Events
C42: Ancillary COGS | D42: =-SUMIFS('P&L'!C:C,'P&L'!$A:$A,$C42)/1000 -> 0 | E42: =-SUMIFS('P&L'!D:D,'P&L'!$A:$A,$C42)/1000 -> 0 | F42: =-SUMIFS('P&L'!E:E,'P&L'!$A:$A,$C42)/1000 -> 0 | G42: =-SUMIFS('P&L'!F:F,'P&L'!$A:$A,$C42)/1000 -> 0 | H42: =-SUMIFS('P&L'!G:G,'P&L'!$A:$A,$C42)/1000 -> 0 | I42: =-SUMIFS('P&L'!H:H,'P&L'!$A:$A,$C42)/1000 -> 0 | J42: =-SUMIFS('P&L'!I:I,'P&L'!$A:$A,$C42)/1000 -> 0 | K42: =-SUMIFS('P&L'!J:J,'P&L'!$A:$A,$C42)/1000 -> 0 | L42: =-SUMIFS('P&L'!K:K,'P&L'!$A:$A,$C42)/1000 -> 0 | M42: =-SUMIFS('P&L'!L:L,'P&L'!$A:$A,$C42)/1000 -> 0 | N42: =-SUMIFS('P&L'!M:M,'P&L'!$A:$A,$C42)/1000 -> 0 | O42: =-SUMIFS('P&L'!N:N,'P&L'!$A:$A,$C42)/1000 -> 0 | P42: =-SUMIFS('P&L'!O:O,'P&L'!$A:$A,$C42)/1000 -> 0 | Q42: =-SUMIFS('P&L'!P:P,'P&L'!$A:$A,$C42)/1000 -> 0 | R42: =-SUMIFS('P&L'!Q:Q,'P&L'!$A:$A,$C42)/1000 -> 0 | S42: =-SUMIFS('P&L'!R:R,'P&L'!$A:$A,$C42)/1000 -> 0 | T42: =-SUMIFS('P&L'!S:S,'P&L'!$A:$A,$C42)/1000 -> 0 | U42: =-SUMIFS('P&L'!T:T,'P&L'!$A:$A,$C42)/1000 -> 0 | V42: =-SUMIFS('P&L'!U:U,'P&L'!$A:$A,$C42)/1000 -> 0 | W42: =-SUMIFS('P&L'!V:V,'P&L'!$A:$A,$C42)/1000 -> 0 | X42: =-SUMIFS('P&L'!W:W,'P&L'!$A:$A,$C42)/1000 -> 0 | Y42: =-SUMIFS('P&L'!X:X,'P&L'!$A:$A,$C42)/1000 -> 0 | Z42: =-SUMIFS('P&L'!Y:Y,'P&L'!$A:$A,$C42)/1000 -> 0 | AA42: =-SUMIFS('P&L'!Z:Z,'P&L'!$A:$A,$C42)/1000 -> 0 | AB42: =-SUMIFS('P&L'!AA:AA,'P&L'!$A:$A,$C42)/1000 -> 0 | AC42: =-SUMIFS('P&L'!AB:AB,'P&L'!$A:$A,$C42)/1000 -> 0 | AD42: =-SUMIFS('P&L'!AC:AC,'P&L'!$A:$A,$C42)/1000 -> 0 | AE42: =-SUMIFS('P&L'!AD:AD,'P&L'!$A:$A,$C42)/1000 -> 0 | AF42: =-SUMIFS('P&L'!AE:AE,'P&L'!$A:$A,$C42)/1000 -> 0 | AG42: =-SUMIFS('P&L'!AF:AF,'P&L'!$A:$A,$C42)/1000 -> 0 | AH42: =-SUMIFS('P&L'!AG:AG,'P&L'!$A:$A,$C42)/1000 -> 0 | AK42: =SUMIFS($CC42:$CE42,$CC$1:$CE$1,AK$3)*AK$24 -> -0.61162324 | AL42: =SUMIFS($CC42:$CE42,$CC$1:$CE$1,AL$3)*AL$24 -> -0.61162324 | AM42: =SUMIFS($CC42:$CE42,$CC$1:$CE$1,AM$3)*AM$24 -> -0.20387441 | AN42: =SUMIFS($CC42:$CE42,$CC$1:$CE$1,AN$3)*AN$24 -> -0.20387441 | AO42: =SUMIFS($CC42:$CE42,$CC$1:$CE$1,AO$3)*AO$24 -> 0 | AP42: =SUMIFS($CC42:$CE42,$CC$1:$CE$1,AP$3)*AP$24 -> 0 | AQ42: =SUMIFS($CC42:$CE42,$CC$1:$CE$1,AQ$3)*AQ$24 -> -0.10193721 | AR42: =SUMIFS($CC42:$CE42,$CC$1:$CE$1,AR$3)*AR$24 -> -0.40774883 | ... BT42: =SUMIFS($CC42:$CE42,$CC$1:$CE$1,BT$3)*BT$24 -> -5.1906047 | BU42: =BI42 -> -6.9208063 | BV42: =BJ42 -> -7.7859071 | BW42: =BK42 -> -6.9208063 | BX42: =BL42 -> -5.1906047 | BZ42: =SUMIFS($D42:$AJ42,$D$1:$AJ$1,BZ$9) -> 0 | CA42: =SUMIFS($D42:$AJ42,$D$1:$AJ$1,CA$9) -> 0 | CB42: =SUMIFS($D42:$AJ42,$D$3:$AJ$3,"LTM") -> 0 | CC42: =CC$31*CG42 -> -4.0774883 | CD42: =CD$31*CH42 -> -30.80201 | CE42: =CE$31*CI42 -> -69.208063 | CG42: =$CN42 -> -0.20786193 | CH42: =$CN42 -> -0.20786193 | CI42: =$CN42 -> -0.20786193 | CK42: =IFERROR(CB42/CB31,0) -> 0 | CM42: =-SUMIFS('FY25 By Venue Financials'!$N:$N,'FY25 By Venue Financials'!$A:$A,$C42) -> -315.48199 | CN42: =IFERROR(CM42/CM$31,0) -> -0.20786193 | CP42: % Ancillary Rev | CQ42: % of Total Events
C43: Alcohol COGS | D43: =-SUMIFS('P&L'!C:C,'P&L'!$A:$A,$C43)/1000 -> 0 | E43: =-SUMIFS('P&L'!D:D,'P&L'!$A:$A,$C43)/1000 -> 0 | F43: =-SUMIFS('P&L'!E:E,'P&L'!$A:$A,$C43)/1000 -> 0 | G43: =-SUMIFS('P&L'!F:F,'P&L'!$A:$A,$C43)/1000 -> 0 | H43: =-SUMIFS('P&L'!G:G,'P&L'!$A:$A,$C43)/1000 -> 0 | I43: =-SUMIFS('P&L'!H:H,'P&L'!$A:$A,$C43)/1000 -> 0 | J43: =-SUMIFS('P&L'!I:I,'P&L'!$A:$A,$C43)/1000 -> 0 | K43: =-SUMIFS('P&L'!J:J,'P&L'!$A:$A,$C43)/1000 -> 0 | L43: =-SUMIFS('P&L'!K:K,'P&L'!$A:$A,$C43)/1000 -> 0 | M43: =-SUMIFS('P&L'!L:L,'P&L'!$A:$A,$C43)/1000 -> 0 | N43: =-SUMIFS('P&L'!M:M,'P&L'!$A:$A,$C43)/1000 -> 0 | O43: =-SUMIFS('P&L'!N:N,'P&L'!$A:$A,$C43)/1000 -> 0 | P43: =-SUMIFS('P&L'!O:O,'P&L'!$A:$A,$C43)/1000 -> 0 | Q43: =-SUMIFS('P&L'!P:P,'P&L'!$A:$A,$C43)/1000 -> 0 | R43: =-SUMIFS('P&L'!Q:Q,'P&L'!$A:$A,$C43)/1000 -> 0 | S43: =-SUMIFS('P&L'!R:R,'P&L'!$A:$A,$C43)/1000 -> 0 | T43: =-SUMIFS('P&L'!S:S,'P&L'!$A:$A,$C43)/1000 -> 0 | U43: =-SUMIFS('P&L'!T:T,'P&L'!$A:$A,$C43)/1000 -> 0 | V43: =-SUMIFS('P&L'!U:U,'P&L'!$A:$A,$C43)/1000 -> 0 | W43: =-SUMIFS('P&L'!V:V,'P&L'!$A:$A,$C43)/1000 -> 0 | X43: =-SUMIFS('P&L'!W:W,'P&L'!$A:$A,$C43)/1000 -> 0 | Y43: =-SUMIFS('P&L'!X:X,'P&L'!$A:$A,$C43)/1000 -> 0 | Z43: =-SUMIFS('P&L'!Y:Y,'P&L'!$A:$A,$C43)/1000 -> 0 | AA43: =-SUMIFS('P&L'!Z:Z,'P&L'!$A:$A,$C43)/1000 -> 0 | AB43: =-SUMIFS('P&L'!AA:AA,'P&L'!$A:$A,$C43)/1000 -> 0 | AC43: =-SUMIFS('P&L'!AB:AB,'P&L'!$A:$A,$C43)/1000 -> 0 | AD43: =-SUMIFS('P&L'!AC:AC,'P&L'!$A:$A,$C43)/1000 -> 0 | AE43: =-SUMIFS('P&L'!AD:AD,'P&L'!$A:$A,$C43)/1000 -> 0 | AF43: =-SUMIFS('P&L'!AE:AE,'P&L'!$A:$A,$C43)/1000 -> 0 | AG43: =-SUMIFS('P&L'!AF:AF,'P&L'!$A:$A,$C43)/1000 -> 0 | AH43: =-SUMIFS('P&L'!AG:AG,'P&L'!$A:$A,$C43)/1000 -> 0 | AK43: =SUMIFS($CC43:$CE43,$CC$1:$CE$1,AK$3)*AK$24 -> -0.062654706 | AL43: =SUMIFS($CC43:$CE43,$CC$1:$CE$1,AL$3)*AL$24 -> -0.062654706 | AM43: =SUMIFS($CC43:$CE43,$CC$1:$CE$1,AM$3)*AM$24 -> -0.020884902 | AN43: =SUMIFS($CC43:$CE43,$CC$1:$CE$1,AN$3)*AN$24 -> -0.020884902 | AO43: =SUMIFS($CC43:$CE43,$CC$1:$CE$1,AO$3)*AO$24 -> 0 | AP43: =SUMIFS($CC43:$CE43,$CC$1:$CE$1,AP$3)*AP$24 -> 0 | AQ43: =SUMIFS($CC43:$CE43,$CC$1:$CE$1,AQ$3)*AQ$24 -> -0.010442451 | AR43: =SUMIFS($CC43:$CE43,$CC$1:$CE$1,AR$3)*AR$24 -> -0.041769804 | ... BT43: =SUMIFS($CC43:$CE43,$CC$1:$CE$1,BT$3)*BT$24 -> -0.31327353 | BU43: =BI43 -> -0.41769804 | BV43: =BJ43 -> -0.46991029 | BW43: =BK43 -> -0.41769804 | BX43: =BL43 -> -0.31327353 | BZ43: =SUMIFS($D43:$AJ43,$D$1:$AJ$1,BZ$9) -> 0 | CA43: =SUMIFS($D43:$AJ43,$D$1:$AJ$1,CA$9) -> 0 | CB43: =SUMIFS($D43:$AJ43,$D$3:$AJ$3,"LTM") -> 0 | CC43: =CC29*CG43 -> -0.41769804 | CD43: =CD29*CH43 -> -2.5061882 | CE43: =CE29*CI43 -> -4.1769804 | CG43: =$CN43 -> -0.06961634 | CH43: =$CN43 -> -0.06961634 | CI43: =$CN43 -> -0.06961634 | CK43: =IFERROR(CB43/CB29,0) -> 0 | CM43: =-SUMIFS('FY25 By Venue Financials'!$N:$N,'FY25 By Venue Financials'!$A:$A,$C43) -> -68.25809 | CN43: =IFERROR(CM43/CM29,0) -> -0.06961634 | CP43: % Alcohol Rev | CQ43: % of Total Events
C44: Other COGS | D44: =-SUMIFS('P&L'!C:C,'P&L'!$A:$A,$C44)/1000 -> -13.22447 | E44: =-SUMIFS('P&L'!D:D,'P&L'!$A:$A,$C44)/1000 -> -16.90425 | F44: =-SUMIFS('P&L'!E:E,'P&L'!$A:$A,$C44)/1000 -> -6.92204 | G44: =-SUMIFS('P&L'!F:F,'P&L'!$A:$A,$C44)/1000 -> -5.68561 | H44: =-SUMIFS('P&L'!G:G,'P&L'!$A:$A,$C44)/1000 -> -20.64956 | I44: =-SUMIFS('P&L'!H:H,'P&L'!$A:$A,$C44)/1000 -> -15.13228 | J44: =-SUMIFS('P&L'!I:I,'P&L'!$A:$A,$C44)/1000 -> -6.60258 | K44: =-SUMIFS('P&L'!J:J,'P&L'!$A:$A,$C44)/1000 -> -1.70385 | L44: =-SUMIFS('P&L'!K:K,'P&L'!$A:$A,$C44)/1000 -> -1.65507 | M44: =-SUMIFS('P&L'!L:L,'P&L'!$A:$A,$C44)/1000 -> -0.78576 | N44: =-SUMIFS('P&L'!M:M,'P&L'!$A:$A,$C44)/1000 -> -4.49531 | O44: =-SUMIFS('P&L'!N:N,'P&L'!$A:$A,$C44)/1000 -> 7.33563 | P44: =-SUMIFS('P&L'!O:O,'P&L'!$A:$A,$C44)/1000 -> -5.91342 | Q44: =-SUMIFS('P&L'!P:P,'P&L'!$A:$A,$C44)/1000 -> -4.23246 | R44: =-SUMIFS('P&L'!Q:Q,'P&L'!$A:$A,$C44)/1000 -> -2.91899 | S44: =-SUMIFS('P&L'!R:R,'P&L'!$A:$A,$C44)/1000 -> -5.85358 | T44: =-SUMIFS('P&L'!S:S,'P&L'!$A:$A,$C44)/1000 -> -5.04119 | U44: =-SUMIFS('P&L'!T:T,'P&L'!$A:$A,$C44)/1000 -> -6.14997 | V44: =-SUMIFS('P&L'!U:U,'P&L'!$A:$A,$C44)/1000 -> -0.93362 | W44: =-SUMIFS('P&L'!V:V,'P&L'!$A:$A,$C44)/1000 -> -1.76676 | X44: =-SUMIFS('P&L'!W:W,'P&L'!$A:$A,$C44)/1000 -> -0.90708 | Y44: =-SUMIFS('P&L'!X:X,'P&L'!$A:$A,$C44)/1000 -> -1.77226 | Z44: =-SUMIFS('P&L'!Y:Y,'P&L'!$A:$A,$C44)/1000 -> -6.35034 | AA44: =-SUMIFS('P&L'!Z:Z,'P&L'!$A:$A,$C44)/1000 -> -0.65108 | AB44: =-SUMIFS('P&L'!AA:AA,'P&L'!$A:$A,$C44)/1000 -> -11.74306 | AC44: =-SUMIFS('P&L'!AB:AB,'P&L'!$A:$A,$C44)/1000 -> 0 | AD44: =-SUMIFS('P&L'!AC:AC,'P&L'!$A:$A,$C44)/1000 -> -3.6575 | AE44: =-SUMIFS('P&L'!AD:AD,'P&L'!$A:$A,$C44)/1000 -> -4.13734 | AF44: =-SUMIFS('P&L'!AE:AE,'P&L'!$A:$A,$C44)/1000 -> -13.55008 | AG44: =-SUMIFS('P&L'!AF:AF,'P&L'!$A:$A,$C44)/1000 -> -3.93788 | AH44: =-SUMIFS('P&L'!AG:AG,'P&L'!$A:$A,$C44)/1000 -> -0.56763 | AK44: =SUMIFS($CC44:$CE44,$CC$1:$CE$1,AK$3)*AK$24 -> -1.6722018 | AL44: =SUMIFS($CC44:$CE44,$CC$1:$CE$1,AL$3)*AL$24 -> -1.6722018 | AM44: =SUMIFS($CC44:$CE44,$CC$1:$CE$1,AM$3)*AM$24 -> -0.55740061 | AN44: =SUMIFS($CC44:$CE44,$CC$1:$CE$1,AN$3)*AN$24 -> -0.55740061 | AO44: =SUMIFS($CC44:$CE44,$CC$1:$CE$1,AO$3)*AO$24 -> 0 | AP44: =SUMIFS($CC44:$CE44,$CC$1:$CE$1,AP$3)*AP$24 -> 0 | AQ44: =SUMIFS($CC44:$CE44,$CC$1:$CE$1,AQ$3)*AQ$24 -> -0.27870031 | AR44: =SUMIFS($CC44:$CE44,$CC$1:$CE$1,AR$3)*AR$24 -> -1.1148012 | ... BT44: =SUMIFS($CC44:$CE44,$CC$1:$CE$1,BT$3)*BT$24 -> -2.4003213 | BU44: =BI44 -> -3.2004284 | BV44: =BJ44 -> -3.6004819 | BW44: =BK44 -> -3.2004284 | BX44: =BL44 -> -2.4003213 | BZ44: =SUMIFS($D44:$AJ44,$D$1:$AJ$1,BZ$9) -> -86.42515 | CA44: =SUMIFS($D44:$AJ44,$D$1:$AJ$1,CA$9) -> -42.49075 | CB44: =SUMIFS($D44:$AJ44,$D$3:$AJ$3,"LTM") -> -49.04101 | CC44: =CC$38*CG44 -> -11.148012 | CD44: =CD$38*CH44 -> -21.519824 | CE44: =CE$38*CI44 -> -32.004284 | CG44: =$CN44 -> -0.012299518 | CH44: =$CN44 -> -0.012299518 | CI44: =$CN44 -> -0.012299518 | CK44: =IFERROR(CB44/CB$38,0) -> -0.087440544 | CM44: =-SUMIFS('FY25 By Venue Financials'!$N:$N,'FY25 By Venue Financials'!$A:$A,$C44) -> -86.75385 | CN44: =IFERROR(CM44/CM$38,0) -> -0.012299518 | CP44: % Total Rev | CQ44: % of Total Events
C45: Room COGS | D45: =-SUMIFS('P&L'!C:C,'P&L'!$A:$A,$C45)/1000 -> 0 | E45: =-SUMIFS('P&L'!D:D,'P&L'!$A:$A,$C45)/1000 -> 0 | F45: =-SUMIFS('P&L'!E:E,'P&L'!$A:$A,$C45)/1000 -> 0 | G45: =-SUMIFS('P&L'!F:F,'P&L'!$A:$A,$C45)/1000 -> 0 | H45: =-SUMIFS('P&L'!G:G,'P&L'!$A:$A,$C45)/1000 -> 0 | I45: =-SUMIFS('P&L'!H:H,'P&L'!$A:$A,$C45)/1000 -> 0 | J45: =-SUMIFS('P&L'!I:I,'P&L'!$A:$A,$C45)/1000 -> 0 | K45: =-SUMIFS('P&L'!J:J,'P&L'!$A:$A,$C45)/1000 -> 0 | L45: =-SUMIFS('P&L'!K:K,'P&L'!$A:$A,$C45)/1000 -> 0 | M45: =-SUMIFS('P&L'!L:L,'P&L'!$A:$A,$C45)/1000 -> 0 | N45: =-SUMIFS('P&L'!M:M,'P&L'!$A:$A,$C45)/1000 -> 0 | O45: =-SUMIFS('P&L'!N:N,'P&L'!$A:$A,$C45)/1000 -> 0 | P45: =-SUMIFS('P&L'!O:O,'P&L'!$A:$A,$C45)/1000 -> 0 | Q45: =-SUMIFS('P&L'!P:P,'P&L'!$A:$A,$C45)/1000 -> 0 | R45: =-SUMIFS('P&L'!Q:Q,'P&L'!$A:$A,$C45)/1000 -> 0 | S45: =-SUMIFS('P&L'!R:R,'P&L'!$A:$A,$C45)/1000 -> 0 | T45: =-SUMIFS('P&L'!S:S,'P&L'!$A:$A,$C45)/1000 -> 0 | U45: =-SUMIFS('P&L'!T:T,'P&L'!$A:$A,$C45)/1000 -> 0 | V45: =-SUMIFS('P&L'!U:U,'P&L'!$A:$A,$C45)/1000 -> 0 | W45: =-SUMIFS('P&L'!V:V,'P&L'!$A:$A,$C45)/1000 -> 0 | X45: =-SUMIFS('P&L'!W:W,'P&L'!$A:$A,$C45)/1000 -> 0 | Y45: =-SUMIFS('P&L'!X:X,'P&L'!$A:$A,$C45)/1000 -> 0 | Z45: =-SUMIFS('P&L'!Y:Y,'P&L'!$A:$A,$C45)/1000 -> 0 | AA45: =-SUMIFS('P&L'!Z:Z,'P&L'!$A:$A,$C45)/1000 -> 0 | AB45: =-SUMIFS('P&L'!AA:AA,'P&L'!$A:$A,$C45)/1000 -> 0 | AC45: =-SUMIFS('P&L'!AB:AB,'P&L'!$A:$A,$C45)/1000 -> 0 | AD45: =-SUMIFS('P&L'!AC:AC,'P&L'!$A:$A,$C45)/1000 -> 0 | AE45: =-SUMIFS('P&L'!AD:AD,'P&L'!$A:$A,$C45)/1000 -> 0 | AF45: =-SUMIFS('P&L'!AE:AE,'P&L'!$A:$A,$C45)/1000 -> 0 | AG45: =-SUMIFS('P&L'!AF:AF,'P&L'!$A:$A,$C45)/1000 -> 0 | AH45: =-SUMIFS('P&L'!AG:AG,'P&L'!$A:$A,$C45)/1000 -> 0 | AK45: =SUMIFS($CC45:$CE45,$CC$1:$CE$1,AK$3)*AK$24 -> 0 | AL45: =SUMIFS($CC45:$CE45,$CC$1:$CE$1,AL$3)*AL$24 -> 0 | AM45: =SUMIFS($CC45:$CE45,$CC$1:$CE$1,AM$3)*AM$24 -> 0 | AN45: =SUMIFS($CC45:$CE45,$CC$1:$CE$1,AN$3)*AN$24 -> 0 | AO45: =SUMIFS($CC45:$CE45,$CC$1:$CE$1,AO$3)*AO$24 -> 0 | AP45: =SUMIFS($CC45:$CE45,$CC$1:$CE$1,AP$3)*AP$24 -> 0 | AQ45: =SUMIFS($CC45:$CE45,$CC$1:$CE$1,AQ$3)*AQ$24 -> 0 | AR45: =SUMIFS($CC45:$CE45,$CC$1:$CE$1,AR$3)*AR$24 -> 0 | ... BT45: =SUMIFS($CC45:$CE45,$CC$1:$CE$1,BT$3)*BT$24 -> 0 | BU45: =BI45 -> 0 | BV45: =BJ45 -> 0 | BW45: =BK45 -> 0 | BX45: =BL45 -> 0 | BZ45: =SUMIFS($D45:$AJ45,$D$1:$AJ$1,BZ$9) -> 0 | CA45: =SUMIFS($D45:$AJ45,$D$1:$AJ$1,CA$9) -> 0 | CB45: =SUMIFS($D45:$AJ45,$D$3:$AJ$3,"LTM") -> 0 | CC45: =CC30*CG45 -> 0 | CD45: =CD30*CH45 -> 0 | CE45: =CE30*CI45 -> 0 | CG45: =$CN45 -> 0 | CH45: =$CN45 -> 0 | CI45: =$CN45 -> 0 | CK45: =IFERROR(CB45/CB27,0) -> 0 | CM45: =-SUMIFS('FY25 By Venue Financials'!$N:$N,'FY25 By Venue Financials'!$A:$A,$C45) -> 0 | CN45: =IFERROR(CM45/CM30,0) -> 0 | CP45: % Lodging Rev | CQ45: % of Total Events
C47: Total COGS | D47: =SUM(D41:D46) -> -13.22447 | E47: =SUM(E41:E46) -> -16.90425 | F47: =SUM(F41:F46) -> -6.92204 | G47: =SUM(G41:G46) -> -5.68561 | H47: =SUM(H41:H46) -> -20.64956 | I47: =SUM(I41:I46) -> -15.13228 | J47: =SUM(J41:J46) -> -6.60258 | K47: =SUM(K41:K46) -> -1.70385 | ... AH47: =SUM(AH41:AH46) -> -0.56763 | AK47: =SUM(AK41:AK46) -> -2.3464798 | AL47: =SUM(AL41:AL46) -> -2.3464798 | AM47: =SUM(AM41:AM46) -> -0.78215993 | AN47: =SUM(AN41:AN46) -> -0.78215993 | AO47: =SUM(AO41:AO46) -> 0 | AP47: =SUM(AP41:AP46) -> 0 | AQ47: =SUM(AQ41:AQ46) -> -0.39107996 | AR47: =SUM(AR41:AR46) -> -1.5643199 | ... BX47: =SUM(BX41:BX46) -> -12.923036 | BZ47: =SUM(BZ41:BZ46) -> -86.42515 | CA47: =SUM(CA41:CA46) -> -42.49075 | CB47: =SUM(CB41:CB46) -> -49.04101 | CC47: =SUM(CC41:CC46) -> -15.643199 | CD47: =SUM(CD41:CD46) -> -81.595148 | CE47: =SUM(CE41:CE46) -> -172.30714 | CG47: =IFERROR(CC47/CC$38,0) -> -0.017259023 | CH47: =IFERROR(CD47/CD$38,0) -> -0.046635185 | CI47: =IFERROR(CE47/CE$38,0) -> -0.066219097 | CK47: =IFERROR(CB47/CB$38,0) -> -0.087440544 | CM47: =SUM(CM41:CM46) -> -757.20939 | CN47: =IFERROR(CM47/CM$38,0) -> -0.10735328 | CP47: % Total Rev
C49: Gross Margin | D49: =D38+D47 -> -12.84202 | E49: =E38+E47 -> 1.0224 | F49: =F38+F47 -> 43.27796 | G49: =G38+G47 -> 70.90499 | H49: =H38+H47 -> 52.23224 | I49: =I38+I47 -> 95.31391 | J49: =J38+J47 -> 16.66809 | K49: =K38+K47 -> -0.86785 | ... AH49: =AH38+AH47 -> 25.01403 | AK49: =AK38+AK47 -> 133.61022 | AL49: =AL38+AL47 -> 133.61022 | AM49: =AM38+AM47 -> 44.536739 | AN49: =AN38+AN47 -> 44.536739 | AO49: =AO38+AO47 -> 0 | AP49: =AP38+AP47 -> 0 | AQ49: =AQ38+AQ47 -> 22.26837 | AR49: =AR38+AR47 -> 89.073478 | ... BX49: =BX38+BX47 -> 182.23268 | BZ49: =BZ38+BZ47 -> 380.03921 | CA49: =CA38+CA47 -> 395.19447 | CB49: =CB38+CB47 -> 511.80877 | CC49: =CC38+CC47 -> 890.73478 | CD49: =CD38+CD47 -> 1668.0526 | CE49: =CE38+CE47 -> 2429.7691 | CG49: =IFERROR(CC49/CC$38,0) -> 0.98274098 | CH49: =IFERROR(CD49/CD$38,0) -> 0.95336482 | CI49: =IFERROR(CE49/CE$38,0) -> 0.9337809 | CK49: =IFERROR(CB49/CB$38,0) -> 0.91255946 | CM49: =CM38+CM47 -> 6296.2256 | CN49: =IFERROR(CM49/CM$38,0) -> 0.89264672 | CP49: % Total Rev
C51: Payroll
C52: Sales Team Payroll | D52: =-SUMIFS('P&L'!C:C,'P&L'!$A:$A,$C52)/1000 -> 0 | E52: =-SUMIFS('P&L'!D:D,'P&L'!$A:$A,$C52)/1000 -> 0 | F52: =-SUMIFS('P&L'!E:E,'P&L'!$A:$A,$C52)/1000 -> 0 | G52: =-SUMIFS('P&L'!F:F,'P&L'!$A:$A,$C52)/1000 -> 0 | H52: =-SUMIFS('P&L'!G:G,'P&L'!$A:$A,$C52)/1000 -> 0 | I52: =-SUMIFS('P&L'!H:H,'P&L'!$A:$A,$C52)/1000 -> 0 | J52: =-SUMIFS('P&L'!I:I,'P&L'!$A:$A,$C52)/1000 -> 0 | K52: =-SUMIFS('P&L'!J:J,'P&L'!$A:$A,$C52)/1000 -> 0 | L52: =-SUMIFS('P&L'!K:K,'P&L'!$A:$A,$C52)/1000 -> 0 | M52: =-SUMIFS('P&L'!L:L,'P&L'!$A:$A,$C52)/1000 -> 0 | N52: =-SUMIFS('P&L'!M:M,'P&L'!$A:$A,$C52)/1000 -> 0 | O52: =-SUMIFS('P&L'!N:N,'P&L'!$A:$A,$C52)/1000 -> 0 | P52: =-SUMIFS('P&L'!O:O,'P&L'!$A:$A,$C52)/1000 -> 0 | Q52: =-SUMIFS('P&L'!P:P,'P&L'!$A:$A,$C52)/1000 -> 0 | R52: =-SUMIFS('P&L'!Q:Q,'P&L'!$A:$A,$C52)/1000 -> 0 | S52: =-SUMIFS('P&L'!R:R,'P&L'!$A:$A,$C52)/1000 -> 0 | T52: =-SUMIFS('P&L'!S:S,'P&L'!$A:$A,$C52)/1000 -> 0 | U52: =-SUMIFS('P&L'!T:T,'P&L'!$A:$A,$C52)/1000 -> 0 | V52: =-SUMIFS('P&L'!U:U,'P&L'!$A:$A,$C52)/1000 -> 0 | W52: =-SUMIFS('P&L'!V:V,'P&L'!$A:$A,$C52)/1000 -> 0 | X52: =-SUMIFS('P&L'!W:W,'P&L'!$A:$A,$C52)/1000 -> 0 | Y52: =-SUMIFS('P&L'!X:X,'P&L'!$A:$A,$C52)/1000 -> 0 | Z52: =-SUMIFS('P&L'!Y:Y,'P&L'!$A:$A,$C52)/1000 -> 0 | AA52: =-SUMIFS('P&L'!Z:Z,'P&L'!$A:$A,$C52)/1000 -> 0 | AB52: =-SUMIFS('P&L'!AA:AA,'P&L'!$A:$A,$C52)/1000 -> 0 | AC52: =-SUMIFS('P&L'!AB:AB,'P&L'!$A:$A,$C52)/1000 -> 0 | AD52: =-SUMIFS('P&L'!AC:AC,'P&L'!$A:$A,$C52)/1000 -> 0 | AE52: =-SUMIFS('P&L'!AD:AD,'P&L'!$A:$A,$C52)/1000 -> 0 | AF52: =-SUMIFS('P&L'!AE:AE,'P&L'!$A:$A,$C52)/1000 -> 0 | AG52: =-SUMIFS('P&L'!AF:AF,'P&L'!$A:$A,$C52)/1000 -> 0 | AH52: =-SUMIFS('P&L'!AG:AG,'P&L'!$A:$A,$C52)/1000 -> 0 | AK52: =SUMIFS($CC52:$CE52,$CC$1:$CE$1,AK$3)/12 -> -6.25 | AL52: =SUMIFS($CC52:$CE52,$CC$1:$CE$1,AL$3)/12 -> -6.25 | AM52: =SUMIFS($CC52:$CE52,$CC$1:$CE$1,AM$3)/12 -> -6.25 | AN52: =SUMIFS($CC52:$CE52,$CC$1:$CE$1,AN$3)/12 -> -6.25 | AO52: =SUMIFS($CC52:$CE52,$CC$1:$CE$1,AO$3)/12 -> -6.25 | AP52: =SUMIFS($CC52:$CE52,$CC$1:$CE$1,AP$3)/12 -> -6.25 | AQ52: =SUMIFS($CC52:$CE52,$CC$1:$CE$1,AQ$3)/12 -> -6.25 | AR52: =SUMIFS($CC52:$CE52,$CC$1:$CE$1,AR$3)/12 -> -6.25 | ... BT52: =SUMIFS($CC52:$CE52,$CC$1:$CE$1,BT$3)/12 -> -6.630625 | BU52: =BI52 -> -6.630625 | BV52: =BJ52 -> -6.630625 | BW52: =BK52 -> -6.630625 | BX52: =BL52 -> -6.630625 | BZ52: =SUMIFS($D52:$AJ52,$D$1:$AJ$1,BZ$9) -> 0 | CA52: =SUMIFS($D52:$AJ52,$D$1:$AJ$1,CA$9) -> 0 | CB52: =SUMIFS($D52:$AJ52,$D$3:$AJ$3,"LTM") -> 0 | CC52: =CG52*1 -> -75 | CD52: =CH52*1 -> -77.25 | CE52: =CI52*1 -> -79.5675 | CG52: =-Payroll!$E$11/1000 -> -75 | CH52: =CG52*1.03 -> -77.25 | CI52: =CH52*1.03 -> -79.5675 | CK52: =IFERROR(CB52/CB$38,0) -> 0 | CM52: =-SUMIFS('FY25 By Venue Financials'!$N:$N,'FY25 By Venue Financials'!$A:$A,$C52) -> -210.42054 | CP52: $/team member | CQ52: Split evently | CR52: Kathy (5% YoY)
